Workbook

Sheet ACCUEIL
B2: ANNEXE 7 - PRÉVISIONNEL FINANCIER
B3: Cabinet d'Expertise Comptable 100% Numérique
B5: Guide de création d'un prévisionnel financier sur 3 ans
B8: OBJECTIF DE L'OUTIL
B9: Cet outil permet de créer rapidement un prévisionnel financier complet pour la création d'un cabinet d'expertise comptable.
B10: Il génère automatiquement : Bilan, Plan de Financement, Compte de Résultat, Plan de Trésorerie et Synthèse.
B13: MODE D'EMPLOI
B15: 1. Allez dans l'onglet SAISIE
B16: 2. Remplissez UNIQUEMENT les cellules jaunes avec vos données annuelles
B17: 3. Les montants sont automatiquement répartis mensuellement (÷12)
B18: 4. Consultez les onglets de synthèse pour voir vos résultats
B21: STRUCTURE DES ONGLETS
B23: • SAISIE | C23: Saisie simplifiée des données annuelles (POINT D'ENTRÉE)
B24: • Synthèse | C24: Indicateurs clés agrégés
B25: • Bilan | C25: Bilan prévisionnel sur 3 ans
B26: • Plan de Financement | C26: Sources et emplois des fonds
B27: • Compte de Résultat | C27: Performances prévisionnelles
B28: • Plan de trésorerie | C28: Flux de trésorerie mensuels
B29: • Prévisions mensuelles | C29: Détail mensuel généré automatiquement
B30: • Personnel | C30: Détail de la masse salariale
B34: POINTS D'ATTENTION
B36: ⚠ Les valeurs par défaut sont des exemples - adaptez-les à votre projet
B37: ⚠ La répartition mensuelle est linéaire (÷12) - ajustez si nécessaire dans les prévisions mensuelles
B38: ⚠ Le taux de charges sociales par défaut est de 42% - vérifiez selon votre statut
B39: ⚠ Le taux d'IS par défaut est de 25% - appliquez le taux réduit PME si éligible (15%)
B40: ⚠ Les durées d'amortissement doivent respecter les usages comptables
B43: CONFORMITÉ PROFESSIONNELLE
B45: Cet outil respecte les principes comptables français (PCG) et les normes professionnelles.
B46: Il est destiné à servir de base de travail pour l'expert-comptable souhaitant créer son cabinet.
B47: Les projections doivent être validées par un professionnel avant utilisation auprès des banques ou investisseurs.
B50: Outil développé dans le cadre du mémoire d'expertise comptable
B53: ⚠ HYPOTHÈSE DE RÉPARTITION
B54: Le CA et les charges sont répartis linéairement (÷12) par simplification. L'activité réelle d'un cabinet d'EC est saisonnière (bilans jan-avr, creux estival). Le plan de trésorerie mensuel est donc indicatif. Pour une analyse fine, appliquer des coefficients mensuels de saisonnalité.

Sheet SAISIE
B1: ANNEXE 7 - PRÉVISIONNEL CRÉATION CABINET D'EXPERTISE COMPTABLE
B2: Guide de saisie: Remplissez uniquement les cellules jaunes avec vos données annuelles
B3: Les montants mensuels seront calculés automatiquement (répartition linéaire sur 12 mois)
B5: PARAMÈTRES | C5: Année N | D5: Année N+1 | E5: Année N+2 | F5: Commentaires / Instructions
B7: 1) BUDGET DES VENTES (Chiffre d'affaires HT)
B8: a) Mission Expertise-Comptable | C8: =+D8/2 -> 80000 | D8: 160000 | E8: 240000 | F8: Mission principale - Tenue comptabilité, révision, bilan
B9: b) Mission CAC (Commissariat aux comptes) | C9: 0 | D9: 36000 | E9: 72000 | F9: Audit légal et missions de certification
B10: c) Mission Social (Paie) | C10: 5000 | D10: 10000 | E10: 15000 | F10: Établissement des bulletins de paie et DSN
B11: d) Mission Juridique | C11: =+D11/2 -> 3000 | D11: 6000 | E11: 18000 | F11: Secrétariat juridique, AG, cessions...
B12: e) DAF externalisé / Conseil | C12: 25000 | D12: 36000 | E12: 72000 | F12: Direction financière externalisée, conseil stratégique
B13: TOTAL CHIFFRE D'AFFAIRES | C13: =SUM(C8:C12) -> 113000 | D13: =SUM(D8:D12) -> 248000 | E13: =SUM(E8:E12) -> 417000
B15: 2) CHARGES DIRECTES (Coûts production)
B16: Logiciels métier (Prod. comptable) | C16: 6000 | D16: 6000 | E16: 6000 | F16: Cegid, ACD, Sage, Pennylane, FULLL …
B17: Marketing / Publicité | C17: 1200 | D17: 1200 | E17: 1200 | F17: Campagnes, sponsoring, événements
B18: TOTAL CHARGES DIRECTES | C18: =SUM(C16:C17) -> 7200 | D18: =SUM(D16:D17) -> 7200 | E18: =SUM(E16:E17) -> 7200
B20: 3) CHARGES EXTERNES
B21: Cotisations Ordre des Experts-Comptables | C21: 500 | D21: 500 | E21: 500 | F21: Cotisation annuelle obligatoire
B22: Assurances (RCP + autres) | C22: 2000 | D22: 3000 | E22: 5000 | F22: Responsabilité civile professionnelle obligatoire
B23: Loyers crédit-bail (véhicules...) | C23: 0 | D23: 0 | E23: 0 | F23: Leasing voiture, matériel
B24: Location bureaux / Coworking | C24: 1200 | D24: 1200 | E24: 1200 | F24: Loyer mensuel bureau ou espace coworking
B25: Frais de production | C25: 600 | D25: 600 | E25: 600 | F25: Fournitures bureau, consommables
B26: Honoraires (avocat, expert...) | C26: 2400 | D26: 2400 | E26: 2400 | F26: Conseils externes ponctuels
B27: Publicité | C27: 600 | D27: 600 | E27: 600 | F27: Annonces, Google Ads, réseaux sociaux
B28: Frais de déplacement | C28: 1200 | D28: 1200 | E28: 1200 | F28: Carburant, transports, parking
B29: Frais de missions/réceptions | C29: 1800 | D29: 1800 | E29: 1800 | F29: Repas clients, séminaires
B30: Divers | C30: 1200 | D30: 1200 | E30: 1200 | F30: Autres charges non listées
B31: TOTAL CHARGES EXTERNES | C31: =SUM(C21:C30) -> 11500 | D31: =SUM(D21:D30) -> 12500 | E31: =SUM(E21:E30) -> 14500
B33: 4) PERSONNEL & RÉMUNÉRATION
B34: Rémunération de l'EC (annuelle) | C34: 25000 | D34: 45000 | E34: 80000 | F34: Salaire annuel brut du dirigeant TNS ou assimilé salarié
B35: Masse salariale collaborateurs (brut) | C35: 30000 | D35: 74400 | E35: 128400 | F35: Total brut annuel de tous les salariés
B36: Charges sociales estimées (%) | C36: 0.42 | D36: 0.42 | E36: 0.42 | F36: En % des salaires bruts (environ 42% si salarié, 45% si TNS)
B37: Charges sociales calculées | C37: =C35*C36 -> 12600 | D37: =D35*D36 -> 31248 | E37: =E35*E36 -> 53928
B38: TOTAL CHARGES DE PERSONNEL | C38: =C34+C35+C37+C62 -> 78850 | D38: =D34+D35+D37+D62 -> 170898 | E38: =E34+E35+E37+E62 -> 298328
B40: 5) INVESTISSEMENTS (Immobilisations)
B41: R&D / Logiciels immobilisés | C41: 0 | D41: 0 | E41: 0 | F41: Développement interne, logiciels > 500€
B42: Matériel de transport | C42: 0 | D42: 0 | E42: 0 | F42: Véhicules achetés (non en crédit-bail)
B43: Mobilier et matériel de bureau | C43: 1500 | D43: 500 | E43: 500 | F43: Bureau, chaises, armoires, écrans...
B44: Matériel informatique | C44: 4000 | D44: 1500 | E44: 2000 | F44: Serveurs, ordinateurs, imprimantes > 500€
B45: Durée d'amortissement moyenne (années) | C45: 3 | D45: 3 | E45: 3 | F45: 3 ans = logiciels, 5 ans = mobilier, 5-7 ans = véhicules
B46: TOTAL INVESTISSEMENTS | C46: =SUM(C41:C44) -> 5500 | D46: =SUM(D41:D44) -> 2000 | E46: =SUM(E41:E44) -> 2500
...

Sheet Tableau de bord KPI
B1: TABLEAU DE BORD — INDICATEURS DE PILOTAGE
B2: Cabinet d'expertise comptable 100% numérique — Prévisionnel sur 3 ans
B4: INDICATEUR | C4: Année N (2026) | D4: Année N+1 (2027) | E4: Année N+2 (2028)
B5: 1. PERFORMANCE ÉCONOMIQUE
B6: Chiffre d'affaires | C6: =SAISIE!C13 -> 113000 | D6: =SAISIE!D13 -> 248000 | E6: =SAISIE!E13 -> 417000
B7: Marge brute | C7: =Synthèse!C8 -> 62000 | D7: =Synthèse!D8 -> 133952 | E7: =Synthèse!E8 -> 226272
B8: Taux de marge brute (%) | C8: =Synthèse!C9 -> 0.54867257 | D8: =Synthèse!D9 -> 0.54012903 | E8: =Synthèse!E9 -> 0.54261871
B9: EBITDA | C9: =Synthèse!C10 -> 14850 | D9: =Synthèse!D10 -> 56802 | E9: =Synthèse!E10 -> 96372
B10: Taux EBITDA (%) | C10: =Synthèse!C11 -> 0.13141593 | D10: =Synthèse!D11 -> 0.22904032 | E10: =Synthèse!E11 -> 0.23110791
B11: Résultat net | C11: ='Compte de Résultat'!D31 -> 10434.592 | D11: ='Compte de Résultat'!E31 -> 45895.585 | E11: ='Compte de Résultat'!F31 -> 75551.735
B12: Taux de marge nette (%) | C12: ='Compte de Résultat'!D32 -> 0.092341518 | D12: ='Compte de Résultat'!E32 -> 0.18506284 | E12: ='Compte de Résultat'!F32 -> 0.18117922
B14: 2. SEUIL DE RENTABILITÉ (POINT MORT)
B15: Charges fixes annuelles | C15: =SAISIE!C34+SAISIE!C62+SAISIE!C21+SAISIE!C22+SAISIE!C23+SAISIE!C24+SAISIE!C26+SAISIE!C57 -> 42950 | D15: =SAISIE!D34+SAISIE!D62+SAISIE!D21+SAISIE!D22+SAISIE!D23+SAISIE!D24+SAISIE!D26+SAISIE!D57 -> 72950 | E15: =SAISIE!E34+SAISIE!E62+SAISIE!E21+SAISIE!E22+SAISIE!E23+SAISIE!E24+SAISIE!E26+SAISIE!E57 -> 125700
B16: Charges variables (personnel + production) | C16: =SAISIE!C35+SAISIE!C37+SAISIE!C16+SAISIE!C17 -> 49800 | D16: =SAISIE!D35+SAISIE!D37+SAISIE!D16+SAISIE!D17 -> 112848 | E16: =SAISIE!E35+SAISIE!E37+SAISIE!E16+SAISIE!E17 -> 189528
B17: Taux de marge sur coûts variables (%) | C17: =IF(C6=0,0,(C6-C16)/C6) -> 0.55929204 | D17: =IF(D6=0,0,(D6-D16)/D6) -> 0.54496774 | E17: =IF(E6=0,0,(E6-E16)/E6) -> 0.5454964
B18: Point mort (CA seuil de rentabilité) | C18: =IF(C17=0,0,C15/C17) -> 76793.513 | D18: =IF(D17=0,0,D15/D17) -> 133861.13 | E18: =IF(E17=0,0,E15/E17) -> 230432.32
B19: Point mort atteint en mois | C19: =IF(C6=0,0,ROUND(C18/C6*12,1)) -> 8.2 | D19: =IF(D6=0,0,ROUND(D18/D6*12,1)) -> 6.5 | E19: =IF(E6=0,0,ROUND(E18/E6*12,1)) -> 6.6
B21: 3. TRÉSORERIE ET SOLIDITÉ FINANCIÈRE
B22: Trésorerie fin d'année | C22: =Synthèse!C14 -> 31630.157 | D22: =Synthèse!D14 -> 72051.14 | E22: =Synthèse!E14 -> 137165.29
B23: Plus bas de trésorerie dans l'année | C23: =Synthèse!C15 -> 25516.667 | D23: =Synthèse!D15 -> 27467.521 | E23: =Synthèse!E15 -> 69813.478
B24: Mois de charges couvertes par la trésorerie | C24: =IF(C6=0,0,ROUND(Synthèse!C14/((SAISIE!C38+SAISIE!C18+SAISIE!C31+SAISIE!C62)/12),1)) -> 3.5 | D24: =IF(D6=0,0,ROUND(Synthèse!D14/((SAISIE!D38+SAISIE!D18+SAISIE!D31+SAISIE!D62)/12),1)) -> 4.1 | E24: =IF(E6=0,0,ROUND(Synthèse!E14/((SAISIE!E38+SAISIE!E18+SAISIE!E31+SAISIE!E62)/12),1)) -> 4.6
B25: Fonds propres | C25: =Synthèse!C16 -> 20434.592 | D25: =Synthèse!D16 -> 66330.177 | E25: =Synthèse!E16 -> 141881.91
B26: Ratio d'autonomie financière (%) | C26: =IF(Bilan!D39=0,0,Synthèse!C16/Bilan!D39) -> 0.43854044 | D26: =IF(Bilan!E39=0,0,Synthèse!D16/Bilan!E39) -> 0.65124629 | E26: =IF(Bilan!F39=0,0,Synthèse!E16/Bilan!F39) -> 0.76473029
B27: BFR | C27: =Synthèse!C17 -> 1137.7682 | D27: =Synthèse!D17 -> 1279.0369 | E27: =Synthèse!E17 -> 6049.95
B29: 4. ACTIVITÉ ET CROISSANCE
B30: Effectif moyen (ETP) | C30: =Synthèse!C13 -> 1 | D30: =Synthèse!D13 -> 2 | E30: =Synthèse!E13 -> 3
B31: CA moyen par collaborateur | C31: =IF(C30=0,0,C6/(C30+1)) -> 56500 | D31: =IF(D30=0,0,D6/(D30+1)) -> 82666.667 | E31: =IF(E30=0,0,E6/(E30+1)) -> 104250
B32: Taux de croissance CA (%) | C32: ="N/A" -> N/A | D32: =IF(C6=0,0,(D6-C6)/C6) -> 1.1946903 | E32: =IF(D6=0,0,(E6-D6)/D6) -> 0.68145161
B33: CA moyen mensuel | C33: =C6/12 -> 9416.6667 | D33: =D6/12 -> 20666.667 | E33: =E6/12 -> 34750
B35: 5. KPI MÉTIER — CABINET D'EXPERTISE COMPTABLE
B36: Objectif clients signés (cumulé) | C36: =25 -> 25 | D36: =60 -> 60 | E36: =100 -> 100
B37: Panier moyen par client (CA / nb clients) | C37: =IF(C36=0,0,C6/C36) -> 4520 | D37: =IF(D36=0,0,D6/D36) -> 4133.3333 | E37: =IF(E36=0,0,E6/E36) -> 4170
B38: Part EC dans CA total (%) | C38: =IF(C6=0,0,SAISIE!C8/C6) -> 0.7079646 | D38: =IF(D6=0,0,SAISIE!D8/D6) -> 0.64516129 | E38: =IF(E6=0,0,SAISIE!E8/E6) -> 0.57553957
B39: Indice de diversification (nb missions >5% CA) | C39: =COUNTIF(SAISIE!C8:C12,">"&C6*5%) -> 2 | D39: =COUNTIF(SAISIE!D8:D12,">"&D6*5%) -> 3 | E39: =COUNTIF(SAISIE!E8:E12,">"&E6*5%) -> 3
B41: SEUILS D'ALERTE (repères)
B42: ⚠ Trésorerie < 15 000 € → risque de cessation de paiement
B43: ⚠ Mois charges couvertes < 2 → tension critique
B44: ⚠ Marge EBITDA < 10% → modèle non viable à terme
B45: ⚠ Point mort > 10 mois → croissance trop lente
B46: ⚠ Autonomie financière < 30% → dépendance bancaire élevée
...

Sheet Synthèse
B2: Synthèse agrégats
B3: en k€ | C3: 46387 | D3: 46752 | E3: 47118
C4: 12m | D4: 12m | E4: 12m
B6: Chiffre d'affaires | C6: ='Compte de Résultat'!D7 -> 113000 | D6: ='Compte de Résultat'!E7 -> 248000 | E6: ='Compte de Résultat'!F7 -> 417000
B7: Coût direct | C7: =+SAISIE!C18+SAISIE!C30+SAISIE!C35+SAISIE!C37 -> 51000 | D7: =+SAISIE!D18+SAISIE!D30+SAISIE!D35+SAISIE!D37 -> 114048 | E7: =+SAISIE!E18+SAISIE!E30+SAISIE!E35+SAISIE!E37 -> 190728
B8: Marge brute | C8: =+C6-C7 -> 62000 | D8: =+D6-D7 -> 133952 | E8: =+E6-E7 -> 226272
B9: % marge brute | C9: =+C8/C6 -> 0.54867257 | D9: =+D8/D6 -> 0.54012903 | E9: =+E8/E6 -> 0.54261871
B10: EBITDA | C10: ='Compte de Résultat'!D22-'Compte de Résultat'!D21 -> 14850 | D10: ='Compte de Résultat'!E22-'Compte de Résultat'!E21 -> 56802 | E10: ='Compte de Résultat'!F22-'Compte de Résultat'!F21 -> 96372
B11: % marge EBITDA | C11: =C10/C6 -> 0.13141593 | D11: =D10/D6 -> 0.22904032 | E11: =E10/E6 -> 0.23110791
B12: EBIT | C12: ='Compte de Résultat'!D22 -> 13016.667 | D12: ='Compte de Résultat'!E22 -> 56135.333 | E12: ='Compte de Résultat'!F22 -> 95538.667
B13: Effectif moyen | C13: =+Personnel!Q19 -> 1 | D13: =+Personnel!AF19 -> 2 | E13: =+Personnel!AU19 -> 3
B14: Trésorerie fin d'année | C14: ='Prévisions mensuelles'!O129 -> 31630.157 | D14: ='Prévisions mensuelles'!AB129 -> 72051.14 | E14: ='Prévisions mensuelles'!AO129 -> 137165.29
B15: Plus bas de trésorerie | C15: =MIN('Prévisions mensuelles'!D129:O129) -> 25516.667 | D15: =MIN('Prévisions mensuelles'!Q129:AB129) -> 27467.521 | E15: =MIN('Prévisions mensuelles'!AD129:AO129) -> 69813.478
B16: Fonds propres | C16: =Bilan!D24 -> 20434.592 | D16: =Bilan!E24 -> 66330.177 | E16: =Bilan!F24 -> 141881.91
B17: BFR | C17: =+Bilan!D43 -> 1137.7682 | D17: =+Bilan!E43 -> 1279.0369 | E17: =+Bilan!F43 -> 6049.95
B18: Variation du BFR (N/N-1) | C18: =+'Plan de Financement'!D8 -> 1137.7682 | D18: =+'Plan de Financement'!E8 -> 141.26871 | E18: =+'Plan de Financement'!F8 -> 4770.9132

Sheet Bilan
B2: Bilan
B3: en € | C3: 46022 | D3: =EOMONTH(C3,12) -> 46387 | E3: =EOMONTH(D3,12) -> 46752 | F3: =EOMONTH(E3,12) -> 47118
C4: 12m | D4: 12m | E4: 12m | F4: 12m
B6: Immobilisations incorporelles | D6: =C6+'Prévisions mensuelles'!C79 -> 0 | E6: =D6+'Prévisions mensuelles'!P79 -> 0 | F6: =E6+'Prévisions mensuelles'!AC79 -> 0
B7: Immobilisations corporelles | D7: =+C7+SUM('Prévisions mensuelles'!C80:C83) -> 5500 | E7: =+D7+SUM('Prévisions mensuelles'!P80:P83) -> 7500 | F7: =+E7+SUM('Prévisions mensuelles'!AC80:AC83) -> 10000
B8: Amortissements cumulés | D8: =C8+'Compte de Résultat'!D21 -> -1833.3333 | E8: =D8+'Compte de Résultat'!E21 -> -2500 | F8: =E8+'Compte de Résultat'!F21 -> -3333.3333
B9: Autres immobilisations financières | D9: =C9+'Prévisions mensuelles'!C84 -> 0 | E9: =D9+'Prévisions mensuelles'!P84 -> 0 | F9: =E9+'Prévisions mensuelles'!AC84 -> 0
B10: Actif immobilisé | C10: =SUM(C6:C9) -> 0 | D10: =SUM(D6:D9) -> 3666.6667 | E10: =SUM(E6:E9) -> 5000 | F10: =SUM(F6:F9) -> 6666.6667
B12: Clients | D12: =$C12+SUMIFS('Prévisions mensuelles'!36:36,'Prévisions mensuelles'!$1:$1,"<="&D$3)*1.2-SUMIFS('Prévisions mensuelles'!$113:$113,'Prévisions mensuelles'!$1:$1,"<="&D$3) -> 11300 | E12: =$C12+SUMIFS('Prévisions mensuelles'!36:36,'Prévisions mensuelles'!$1:$1,"<="&E$3)*1.2-SUMIFS('Prévisions mensuelles'!$113:$113,'Prévisions mensuelles'!$1:$1,"<="&E$3) -> 24800 | F12: =$C12+SUMIFS('Prévisions mensuelles'!36:36,'Prévisions mensuelles'!$1:$1,"<="&F$3)*1.2-SUMIFS('Prévisions mensuelles'!$113:$113,'Prévisions mensuelles'!$1:$1,"<="&F$3) -> 41700
B13: Impôt sur les sociétés | D13: =C13+IF(SUMIFS('Prévisions mensuelles'!$70:$70,'Prévisions mensuelles'!$1:$1,"<="&D$3)-SUMIFS('Prévisions mensuelles'!$125:$125,'Prévisions mensuelles'!$1:$1,"<="&D$3)>0,0,SUMIFS('Prévisions mensuelles'!$70:$70,'Prévisions mensuelles'!$1:$1,"<="&D$3)-SUMIFS('Prévisions mensuelles'!$125:$125,'Prévisions mensuelles'!$1:$1,"<="&D$3)) -> 0 | E13: =$C13+IF(SUMIFS('Prévisions mensuelles'!$70:$70,'Prévisions mensuelles'!$1:$1,"<="&E$3)-SUMIFS('Prévisions mensuelles'!$125:$125,'Prévisions mensuelles'!$1:$1,"<="&E$3)>0,0,SUMIFS('Prévisions mensuelles'!$70:$70,'Prévisions mensuelles'!$1:$1,"<="&E$3)-SUMIFS('Prévisions mensuelles'!$125:$125,'Prévisions mensuelles'!$1:$1,"<="&E$3)) -> 0 | F13: =$C13+IF(SUMIFS('Prévisions mensuelles'!$70:$70,'Prévisions mensuelles'!$1:$1,"<="&F$3)-SUMIFS('Prévisions mensuelles'!$125:$125,'Prévisions mensuelles'!$1:$1,"<="&F$3)>0,0,SUMIFS('Prévisions mensuelles'!$70:$70,'Prévisions mensuelles'!$1:$1,"<="&F$3)-SUMIFS('Prévisions mensuelles'!$125:$125,'Prévisions mensuelles'!$1:$1,"<="&F$3)) -> 0
B14: TVA | D14: =-SUMIFS('Prévisions mensuelles'!140:140,'Prévisions mensuelles'!1:1,D$3) -> 0 | E14: =-SUMIFS('Prévisions mensuelles'!140:140,'Prévisions mensuelles'!1:1,E$3) -> 0 | F14: =-SUMIFS('Prévisions mensuelles'!140:140,'Prévisions mensuelles'!1:1,F$3) -> 0
B15: Trésorerie | D15: =IF('Prévisions mensuelles'!C129>0,'Prévisions mensuelles'!C129,0) -> 31630.157 | E15: =IF('Prévisions mensuelles'!P129>0,'Prévisions mensuelles'!P129,0) -> 72051.14 | F15: =IF('Prévisions mensuelles'!AC129>0,'Prévisions mensuelles'!AC129,0) -> 137165.29
B16: Charges constatées d'avance | D16: =C16+0 -> 0 | E16: =D16+0 -> 0 | F16: =E16+0 -> 0
B17: Actif circulant | C17: =SUM(C12:C16) -> 0 | D17: =SUM(D12:D16) -> 42930.157 | E17: =SUM(E12:E16) -> 96851.14 | F17: =SUM(F12:F16) -> 178865.29
B18: TOTAL ACTIF | C18: =C10+C17 -> 0 | D18: =D10+D17 -> 46596.823 | E18: =E10+E17 -> 101851.14 | F18: =F10+F17 -> 185531.96
B20: Capital | D20: =C20+'Prévisions mensuelles'!C112 -> 10000 | E20: =D20+'Prévisions mensuelles'!P112 -> 10000 | F20: =E20+'Prévisions mensuelles'!E112 -> 10000
B21: Réserves | D21: =C21+C22 -> 0 | E21: =D21+D22 -> 10434.592 | F21: =E21+E22 -> 56330.177
B22: Résultat de l'exercice | D22: ='Compte de Résultat'!D31 -> 10434.592 | E22: ='Compte de Résultat'!E31 -> 45895.585 | F22: ='Compte de Résultat'!F31 -> 75551.735
B23: Provisions réglementées | D23: =C23-'Compte de Résultat'!D29 -> 0 | E23: =D23-'Compte de Résultat'!E29 -> 0 | F23: =E23-'Compte de Résultat'!F29 -> 0
B24: Capitaux propres | C24: =SUM(C20:C23) -> 0 | D24: =SUM(D20:D23) -> 20434.592 | E24: =SUM(E20:E23) -> 66330.177 | F24: =SUM(F20:F23) -> 141881.91
B26: Emprunts auprès des banques | D26: =C26+SUMIFS('Prévisions mensuelles'!$115:$115,'Prévisions mensuelles'!$1:$1,"<="&D$3)-SUMIFS('Prévisions mensuelles'!$118:$118,'Prévisions mensuelles'!$1:$1,"<="&D$3) -> 16000 | E26: =$C26+SUMIFS('Prévisions mensuelles'!$115:$115,'Prévisions mensuelles'!$1:$1,"<="&E$3)-SUMIFS('Prévisions mensuelles'!$118:$118,'Prévisions mensuelles'!$1:$1,"<="&E$3) -> 12000 | F26: =$C26+SUMIFS('Prévisions mensuelles'!$115:$115,'Prévisions mensuelles'!$1:$1,"<="&F$3)-SUMIFS('Prévisions mensuelles'!$118:$118,'Prévisions mensuelles'!$1:$1,"<="&F$3) -> 8000
B27: Concours bancaires courants | D27: =C27+IF('Prévisions mensuelles'!C129<0,-'Prévisions mensuelles'!C129,0) -> 0 | E27: =D27+IF('Prévisions mensuelles'!P129<0,-'Prévisions mensuelles'!P129,0) -> 0 | F27: =E27+IF('Prévisions mensuelles'!Q129<0,-'Prévisions mensuelles'!Q129,0) -> 0
B28: Comptes courants | D28: =C28 -> 0 | E28: =D28 -> 0 | F28: =E28 -> 0
B29: Fournisseurs | D29: =C29+SUMIFS('Prévisions mensuelles'!$42:$42,'Prévisions mensuelles'!$1:$1,"<="&D$3)*1.2+SUMIFS('Prévisions mensuelles'!$53:$53,'Prévisions mensuelles'!$1:$1,"<="&D$3)*1.2+SUMIFS('Prévisions mensuelles'!$54:$54,'Prévisions mensuelles'!$1:$1,"<="&D$3)*1.2-SUMIFS('Prévisions mensuelles'!$120:$120,'Prévisions mensuelles'!$1:$1,"<="&D$3) -> 1870 | E29: =$C29+SUMIFS('Prévisions mensuelles'!$42:$42,'Prévisions mensuelles'!$1:$1,"<="&E$3)*1.2+SUMIFS('Prévisions mensuelles'!$53:$53,'Prévisions mensuelles'!$1:$1,"<="&E$3)*1.2+SUMIFS('Prévisions mensuelles'!$54:$54,'Prévisions mensuelles'!$1:$1,"<="&E$3)*1.2-SUMIFS('Prévisions mensuelles'!$120:$120,'Prévisions mensuelles'!$1:$1,"<="&E$3) -> 1970 | F29: =$C29+SUMIFS('Prévisions mensuelles'!$42:$42,'Prévisions mensuelles'!$1:$1,"<="&F$3)*1.2+SUMIFS('Prévisions mensuelles'!$53:$53,'Prévisions mensuelles'!$1:$1,"<="&F$3)*1.2+SUMIFS('Prévisions mensuelles'!$54:$54,'Prévisions mensuelles'!$1:$1,"<="&F$3)*1.2-SUMIFS('Prévisions mensuelles'!$120:$120,'Prévisions mensuelles'!$1:$1,"<="&F$3) -> 2170
B30: Fournisseurs immos | D30: =SUMIFS('Prévisions mensuelles'!$85:$85,'Prévisions mensuelles'!$1:$1,"<="&D$3)*1.2-SUMIFS('Prévisions mensuelles'!$119:$119,'Prévisions mensuelles'!$1:$1,"<="&D$3) -> 550 | E30: =SUMIFS('Prévisions mensuelles'!$85:$85,'Prévisions mensuelles'!$1:$1,"<="&E$3)*1.2-SUMIFS('Prévisions mensuelles'!$119:$119,'Prévisions mensuelles'!$1:$1,"<="&E$3) -> 200 | F30: =SUMIFS('Prévisions mensuelles'!$85:$85,'Prévisions mensuelles'!$1:$1,"<="&F$3)*1.2-SUMIFS('Prévisions mensuelles'!$119:$119,'Prévisions mensuelles'!$1:$1,"<="&F$3) -> 250
B31: Dettes sociales | D31: =C31+'Prévisions mensuelles'!Q123 -> 2537.5 | E31: =$C31+'Prévisions mensuelles'!AD123 -> 5655.5 | F31: =$C31+'Prévisions mensuelles'!AE123 -> 9848
B32: Impôt sur les sociétés | D32: =C32+IF(SUMIFS('Prévisions mensuelles'!$70:$70,'Prévisions mensuelles'!$1:$1,"<="&D$3)-SUMIFS('Prévisions mensuelles'!$125:$125,'Prévisions mensuelles'!$1:$1,"<="&D$3)<0,0,SUMIFS('Prévisions mensuelles'!$70:$70,'Prévisions mensuelles'!$1:$1,"<="&D$3)-SUMIFS('Prévisions mensuelles'!$125:$125,'Prévisions mensuelles'!$1:$1,"<="&D$3)) -> 1841.3985 | E32: =$C32+IF(SUMIFS('Prévisions mensuelles'!$70:$70,'Prévisions mensuelles'!$1:$1,"<="&E$3)-SUMIFS('Prévisions mensuelles'!$125:$125,'Prévisions mensuelles'!$1:$1,"<="&E$3)<0,0,SUMIFS('Prévisions mensuelles'!$70:$70,'Prévisions mensuelles'!$1:$1,"<="&E$3)-SUMIFS('Prévisions mensuelles'!$125:$125,'Prévisions mensuelles'!$1:$1,"<="&E$3)) -> 7790.4631 | F32: =$C32+IF(SUMIFS('Prévisions mensuelles'!$70:$70,'Prévisions mensuelles'!$1:$1,"<="&F$3)-SUMIFS('Prévisions mensuelles'!$125:$125,'Prévisions mensuelles'!$1:$1,"<="&F$3)<0,0,SUMIFS('Prévisions mensuelles'!$70:$70,'Prévisions mensuelles'!$1:$1,"<="&F$3)-SUMIFS('Prévisions mensuelles'!$125:$125,'Prévisions mensuelles'!$1:$1,"<="&F$3)) -> 9885.3833
B33: TVA | D33: =C33+SUMIFS('Prévisions mensuelles'!$141:$141,'Prévisions mensuelles'!$1:$1,D$3)+SUMIFS('Prévisions mensuelles'!$143:$143,'Prévisions mensuelles'!$1:$1,D$3)+'Prévisions mensuelles'!C143 -> 3363.3333 | E33: =$D33+SUMIFS('Prévisions mensuelles'!$141:$141,'Prévisions mensuelles'!$1:$1,E$3)+SUMIFS('Prévisions mensuelles'!$143:$143,'Prévisions mensuelles'!$1:$1,E$3)+'Prévisions mensuelles'!P143-'Prévisions mensuelles'!O126 -> 7905 | F33: =$E33+SUMIFS('Prévisions mensuelles'!$141:$141,'Prévisions mensuelles'!$1:$1,F$3)+SUMIFS('Prévisions mensuelles'!$143:$143,'Prévisions mensuelles'!$1:$1,F$3)+'Prévisions mensuelles'!AC143-'Prévisions mensuelles'!AB141 -> 13496.667
B34: Autres dettes sociales et fiscales | D34: 0 | E34: =$C34+0 -> 0 | F34: =$C34+0 -> 0
B35: Autres dettes (avoirs) | D35: =C35 -> 0 | E35: =D35 -> 0 | F35: =E35 -> 0
B36: Produits constatés d'avance | D36: =C36+'Prévisions mensuelles'!D37 -> 0 | E36: =D36+'Prévisions mensuelles'!E37 -> 0 | F36: =E36+'Prévisions mensuelles'!F37 -> 0
B37: Ecart
B38: Total des dettes | C38: =SUM(C26:C37) -> 0 | D38: =SUM(D26:D37) -> 26162.232 | E38: =SUM(E26:E37) -> 35520.963 | F38: =SUM(F26:F37) -> 43650.05
B39: TOTAL PASSIF | C39: =C24+C38 -> 0 | D39: =D24+D38 -> 46596.823 | E39: =E24+E38 -> 101851.14 | F39: =F24+F38 -> 185531.96
B41: Ctrl | C41: =C18-C39 -> 0 | D41: =D18-D39 -> 0 | E41: =E18-E39 -> 0 | F41: =F18-F39 -> 0
B43: BFR | C43: =SUM(C12:C14,C16)-SUM(C29:C36) -> 0 | D43: =SUM(D12:D14,D16)-SUM(D29:D36) -> 1137.7682 | E43: =SUM(E12:E14,E16)-SUM(E29:E36) -> 1279.0369 | F43: =SUM(F12:F14,F16)-SUM(F29:F36) -> 6049.95
B44: Var. BFR | D44: =D43-C43 -> 1137.7682 | E44: =E43-D43 -> 141.26871 | F44: =F43-E43 -> 4770.9132

Sheet Plan de Financement
B2: Plan de financement
B3: en k€ | C3: =Bilan!C3 -> 46022 | D3: =Bilan!D3 -> 46387 | E3: =Bilan!E3 -> 46752 | F3: =Bilan!F3 -> 47118
C4: =Bilan!C4 -> 12m | D4: =Bilan!D4 -> 12m | E4: =Bilan!E4 -> 12m | F4: =Bilan!F4 -> 12m
B6: Distribution de dividendes
B7: Investissements | D7: =+'Prévisions mensuelles'!C85 -> 5500 | E7: =+'Prévisions mensuelles'!P85 -> 2000 | F7: ='Prévisions mensuelles'!AC85 -> 2500
B8: Var. BFR d'exploitation | D8: =IF(Bilan!D44<0,0,Bilan!D44) -> 1137.7682 | E8: =IF(Bilan!E44<0,0,Bilan!E44) -> 141.26871 | F8: =IF(Bilan!F44<0,0,Bilan!F44) -> 4770.9132
B9: Remboursement d'emprunts | D9: ='Prévisions mensuelles'!C118 -> 4000 | E9: ='Prévisions mensuelles'!P118 -> 4000 | F9: ='Prévisions mensuelles'!AC118 -> 4000
B10: Total des besoins | D10: =SUM(D7:D9) -> 10637.768 | E10: =SUM(E7:E9) -> 6141.2687 | F10: =SUM(F7:F9) -> 11270.913
B12: Capacité d'autofinancement | D12: ='Compte de Résultat'!D31-'Compte de Résultat'!D21-'Compte de Résultat'!D29 -> 12267.925 | E12: ='Compte de Résultat'!E31-'Compte de Résultat'!E21-'Compte de Résultat'!E29 -> 46562.252 | F12: ='Compte de Résultat'!F31-'Compte de Résultat'!F21-'Compte de Résultat'!F29 -> 76385.068
B13: Var. BFR d'exploitation | D13: =IF(Bilan!D44<0,-Bilan!D44,0) -> 0 | E13: =IF(Bilan!E44<0,-Bilan!E44,0) -> 0 | F13: =IF(Bilan!F44<0,-Bilan!F44,0) -> 0
B14: Augmentation de capital | D14: ='Prévisions mensuelles'!C112 -> 10000 | E14: ='Prévisions mensuelles'!P112 -> 0 | F14: ='Prévisions mensuelles'!AC112 -> 0
B15: Nouveaux emprunts | D15: ='Prévisions mensuelles'!C115 -> 20000 | E15: 0 | F15: ='Prévisions mensuelles'!AC115 -> 0
B16: Autres | D16: =Bilan!D37 -> 0 | E16: =Bilan!E37 -> 0 | F16: =Bilan!F37-E16 -> 0
B17: Total des ressources | D17: =SUM(D12:D15) -> 42267.925 | E17: =SUM(E12:E16) -> 46562.252 | F17: =SUM(F12:F16) -> 76385.068
B18: Variation de trésorerie | D18: =D17-D10 -> 31630.157 | E18: =E17-E10 -> 40420.983 | F18: =F17-F10 -> 65114.155
B19: Trésorerie fin de période | C19: 0 | D19: =D18+C19 -> 31630.157 | E19: =E18+D19 -> 72051.14 | F19: =F18+E19 -> 137165.29
B21: Ctrl | C21: =C19-Bilan!C15 -> 0 | D21: =D19-Bilan!D15 -> -5.4569682e-11 | E21: =E19-Bilan!E15 -> 0 | F21: =F19-Bilan!F15 -> 0

Sheet Compte de Résultat
B2: Compte de résultat
B3: en k€ | C3: =Bilan!C3 -> 46022 | D3: =Bilan!D3 -> 46387 | E3: =Bilan!E3 -> 46752 | F3: =Bilan!F3 -> 47118
C4: =Bilan!C4 -> 12m | D4: =Bilan!D4 -> 12m | E4: =Bilan!E4 -> 12m | F4: =Bilan!F4 -> 12m
B6: Revenus | D6: =+'Prévisions mensuelles'!C36 -> 113000 | E6: =+'Prévisions mensuelles'!P36 -> 248000 | F6: =+'Prévisions mensuelles'!AC36 -> 417000
B7: Chiffre d'affaires | D7: =SUM(D6:D6) -> 113000 | E7: =SUM(E6:E6) -> 248000 | F7: =SUM(F6:F6) -> 417000
B9: Subventions
B11: Charges directes | D11: =-('Prévisions mensuelles'!C42) -> -7200 | E11: =-('Prévisions mensuelles'!P42) -> -7200 | F11: =-('Prévisions mensuelles'!AC42) -> -7200
B12: Charges externes | D12: =-'Prévisions mensuelles'!C53-D13 -> -11500 | E12: =-'Prévisions mensuelles'!P53-E13 -> -12500 | F12: =-'Prévisions mensuelles'!AC53-F13 -> -14500
B13: Soldes de crédit-bail | D13: 0 | E13: 0 | F13: 0
B14: Impôts & taxes | D14: =-'Prévisions mensuelles'!C56 -> -600 | E14: =-'Prévisions mensuelles'!P56 -> -600 | F14: =-'Prévisions mensuelles'!AC56 -> -600
B15: Charges de personnel | D15: =-'Prévisions mensuelles'!C57-'Prévisions mensuelles'!C58 -> -53850 | E15: =-'Prévisions mensuelles'!P57-'Prévisions mensuelles'!P58 -> -125898 | F15: =-'Prévisions mensuelles'!AC57-'Prévisions mensuelles'!AC58 -> -218328
B16: Rémunération gérant | D16: =-'Prévisions mensuelles'!C55 -> -25000 | E16: =-'Prévisions mensuelles'!P55 -> -45000 | F16: =-'Prévisions mensuelles'!AC55 -> -80000
B17: Redevances | D17: =-'Prévisions mensuelles'!C54 -> 0 | E17: =-'Prévisions mensuelles'!P54 -> 0 | F17: =-'Prévisions mensuelles'!AC54 -> 0
B18: EBITDA | C18: =C7+C9+SUM(C11:C16) -> 0 | D18: =D7+D9+SUM(D11:D16) -> 14850 | E18: =E7+E9+SUM(E11:E16) -> 56802 | F18: =F7+F9+SUM(F11:F16) -> 96372
B19: EBITDA en % | D19: =D18/D$7 -> 0.13141593 | E19: =E18/E$7 -> 0.22904032 | F19: =F18/F$7 -> 0.23110791
B21: Dotations aux amortissements | D21: =-'Prévisions mensuelles'!C59 -> -1833.3333 | E21: =-'Prévisions mensuelles'!P59 -> -666.66667 | F21: =-'Prévisions mensuelles'!AC59 -> -833.33333
B22: Résultat d'exploitation (EBIT) | C22: =C18+C21 -> 0 | D22: =D18+D21 -> 13016.667 | E22: =E18+E21 -> 56135.333 | F22: =F18+F21 -> 95538.667
B23: EBIT en % | D23: =D22/D$7 -> 0.11519174 | E23: =E22/E$7 -> 0.22635215 | F23: =F22/F$7 -> 0.22910951
B25: Résultat financier | D25: =-'Prévisions mensuelles'!C64 -> -740.67657 | E25: =-'Prévisions mensuelles'!P64 -> -607.8867 | F25: =-'Prévisions mensuelles'!AC64 -> -469.68677
B26: Résultat courant | C26: =C22+C25 -> 0 | D26: =D22+D25 -> 12275.99 | E26: =E22+E25 -> 55527.447 | F26: =F22+F25 -> 95068.98
B27: Résultat courant en % | D27: =D26/D$7 -> 0.10863708 | E27: =E26/E$7 -> 0.22390099 | F27: =F26/F$7 -> 0.22798317
B29: Résultat exceptionnel | D29: =-'Prévisions mensuelles'!C69 -> 0 | E29: =-'Prévisions mensuelles'!P69 -> 0 | F29: =-'Prévisions mensuelles'!AC69 -> 0
B30: Impôt sur les bénéfices | D30: =-'Prévisions mensuelles'!C70 -> -1841.3985 | E30: =-'Prévisions mensuelles'!P70 -> -9631.8617 | F30: =-'Prévisions mensuelles'!AC70 -> -19517.245
B31: Résultat net | C31: =C26+SUM(C29:C30) -> 0 | D31: =D26+SUM(D29:D30) -> 10434.592 | E31: =E26+SUM(E29:E30) -> 45895.585 | F31: =F26+SUM(F29:F30) -> 75551.735
B32: Résultat net en % | D32: =D31/D7 -> 0.092341518 | E32: =E31/E7 -> 0.18506284 | F32: =F31/F7 -> 0.18117922
B36: Ctrl | D36: =D31-'Prévisions mensuelles'!C72 -> 0 | E36: =E31-'Prévisions mensuelles'!P72 -> 0 | F36: =F31-'Prévisions mensuelles'!AC72 -> 0

Sheet Plan de trésorerie
B1: Plan de trésorerie
B3: Date | D3: 46053 | E3: 46081 | F3: 46112 | G3: 46142 | H3: 46173 | I3: 46203 | J3: 46234 | K3: 46265 | L3: 46295 | M3: 46326 | N3: 46356 | O3: 46387 | Q3: 46418 | R3: 46446 | S3: 46477 | T3: 46507 | U3: 46538 | V3: 46568 | W3: 46599 | X3: 46630 | Y3: 46660 | Z3: 46691 | AA3: 46721 | AB3: 46752 | AD3: 46783 | AE3: 46812 | AF3: 46843 | AG3: 46873 | AH3: 46904 | AI3: 46934 | AJ3: 46965 | AK3: 46996 | AL3: 47026 | AM3: 47057 | AN3: 47087 | AO3: 47118
B5: I - Trésorerie initiale | D5: =+'Prévisions mensuelles'!D109 -> 0 | E5: =+'Prévisions mensuelles'!E109 -> 25516.667 | F5: =+'Prévisions mensuelles'!F109 -> 27376.722 | G5: =+'Prévisions mensuelles'!G109 -> 28161.003 | H5: =+'Prévisions mensuelles'!H109 -> 28542.845 | I5: =+'Prévisions mensuelles'!I109 -> 28925.585 | J5: =+'Prévisions mensuelles'!J109 -> 29309.226 | K5: =+'Prévisions mensuelles'!K109 -> 29693.771 | ... AO5: =+'Prévisions mensuelles'!AO109 -> 132117.65
B7: II - Recettes | C7: =+'Prévisions mensuelles'!C111 -> 154300 | D7: =+'Prévisions mensuelles'!D111 -> 30000 | E7: =+'Prévisions mensuelles'!E111 -> 11300 | F7: =+'Prévisions mensuelles'!F111 -> 11300 | G7: =+'Prévisions mensuelles'!G111 -> 11300 | H7: =+'Prévisions mensuelles'!H111 -> 11300 | I7: =+'Prévisions mensuelles'!I111 -> 11300 | J7: =+'Prévisions mensuelles'!J111 -> 11300 | ... AO7: =+'Prévisions mensuelles'!AO111 -> 41700
B8: Apport en capital | C8: =+'Prévisions mensuelles'!C112 -> 10000 | D8: =+'Prévisions mensuelles'!D112 -> 10000 | E8: =+'Prévisions mensuelles'!E112 -> 0 | F8: =+'Prévisions mensuelles'!F112 -> 0 | G8: =+'Prévisions mensuelles'!G112 -> 0 | H8: =+'Prévisions mensuelles'!H112 -> 0 | I8: =+'Prévisions mensuelles'!I112 -> 0 | J8: =+'Prévisions mensuelles'!J112 -> 0 | ... AO8: =+'Prévisions mensuelles'!AO112 -> 0
B9: Encaissement clients TTC | C9: =+'Prévisions mensuelles'!C113 -> 124300 | D9: =+'Prévisions mensuelles'!D113 -> 0 | E9: =+'Prévisions mensuelles'!E113 -> 11300 | F9: =+'Prévisions mensuelles'!F113 -> 11300 | G9: =+'Prévisions mensuelles'!G113 -> 11300 | H9: =+'Prévisions mensuelles'!H113 -> 11300 | I9: =+'Prévisions mensuelles'!I113 -> 11300 | J9: =+'Prévisions mensuelles'!J113 -> 11300 | ... AO9: =+'Prévisions mensuelles'!AO113 -> 41700
B10: Remboursement crédit TVA | C10: =+'Prévisions mensuelles'!C114 -> 0 | D10: =+'Prévisions mensuelles'!D114 -> 0 | E10: =+'Prévisions mensuelles'!E114 -> 0 | F10: =+'Prévisions mensuelles'!F114 -> 0 | G10: =+'Prévisions mensuelles'!G114 -> 0 | H10: =+'Prévisions mensuelles'!H114 -> 0 | I10: =+'Prévisions mensuelles'!I114 -> 0 | J10: =+'Prévisions mensuelles'!J114 -> 0 | ... AO10: =+'Prévisions mensuelles'!AO114 -> 0
B11: Nouveaux crédits bancaires | C11: =+'Prévisions mensuelles'!C115 -> 20000 | D11: =+'Prévisions mensuelles'!D115 -> 20000 | E11: =+'Prévisions mensuelles'!E115 -> 0 | F11: =+'Prévisions mensuelles'!F115 -> 0 | G11: =+'Prévisions mensuelles'!G115 -> 0 | H11: =+'Prévisions mensuelles'!H115 -> 0 | I11: =+'Prévisions mensuelles'!I115 -> 0 | J11: =+'Prévisions mensuelles'!J115 -> 0 | ... AO11: =+'Prévisions mensuelles'!AO115 -> 0
B13: III - Dépenses | C13: =+'Prévisions mensuelles'!C117 -> 122669.84 | D13: =+'Prévisions mensuelles'!D117 -> 4483.3333 | E13: =+'Prévisions mensuelles'!E117 -> 9439.9444 | F13: =+'Prévisions mensuelles'!F117 -> 10515.719 | G13: =+'Prévisions mensuelles'!G117 -> 10918.158 | H13: =+'Prévisions mensuelles'!H117 -> 10917.26 | I13: =+'Prévisions mensuelles'!I117 -> 10916.359 | J13: =+'Prévisions mensuelles'!J117 -> 10915.455 | ... AO13: =+'Prévisions mensuelles'!AO117 -> 36652.358
B14: Remboursement de crédit | C14: =+'Prévisions mensuelles'!C118 -> 4000 | D14: =+'Prévisions mensuelles'!D118 -> 333.33333 | E14: =+'Prévisions mensuelles'!E118 -> 333.33333 | F14: =+'Prévisions mensuelles'!F118 -> 333.33333 | G14: =+'Prévisions mensuelles'!G118 -> 333.33333 | H14: =+'Prévisions mensuelles'!H118 -> 333.33333 | I14: =+'Prévisions mensuelles'!I118 -> 333.33333 | J14: =+'Prévisions mensuelles'!J118 -> 333.33333 | ... AO14: =+'Prévisions mensuelles'!AO118 -> 333.33333
B15: Investissements | C15: =+'Prévisions mensuelles'!C119 -> 6050 | D15: =+'Prévisions mensuelles'!D119 -> 0 | E15: =+'Prévisions mensuelles'!E119 -> 550 | F15: =+'Prévisions mensuelles'!F119 -> 550 | G15: =+'Prévisions mensuelles'!G119 -> 550 | H15: =+'Prévisions mensuelles'!H119 -> 550 | I15: =+'Prévisions mensuelles'!I119 -> 550 | J15: =+'Prévisions mensuelles'!J119 -> 550 | ... AO15: =+'Prévisions mensuelles'!AO119 -> 250
B16: Charges directes et externes TTC | C16: =+'Prévisions mensuelles'!C120 -> 20570 | D16: =+'Prévisions mensuelles'!D120 -> 0 | E16: =+'Prévisions mensuelles'!E120 -> 1870 | F16: =+'Prévisions mensuelles'!F120 -> 1870 | G16: =+'Prévisions mensuelles'!G120 -> 1870 | H16: =+'Prévisions mensuelles'!H120 -> 1870 | I16: =+'Prévisions mensuelles'!I120 -> 1870 | J16: =+'Prévisions mensuelles'!J120 -> 1870 | ... AO16: =+'Prévisions mensuelles'!AO120 -> 2170
B17: Impôts & taxes | C17: =+'Prévisions mensuelles'!C121 -> 600 | D17: =+'Prévisions mensuelles'!D121 -> 50 | E17: =+'Prévisions mensuelles'!E121 -> 50 | F17: =+'Prévisions mensuelles'!F121 -> 50 | G17: =+'Prévisions mensuelles'!G121 -> 50 | H17: =+'Prévisions mensuelles'!H121 -> 50 | I17: =+'Prévisions mensuelles'!I121 -> 50 | J17: =+'Prévisions mensuelles'!J121 -> 50 | ... AO17: =+'Prévisions mensuelles'!AO121 -> 50
B18: Salaires | C18: =+'Prévisions mensuelles'!C122 -> 48400 | D18: =+'Prévisions mensuelles'!D122 -> 4033.3333 | E18: =+'Prévisions mensuelles'!E122 -> 4033.3333 | F18: =+'Prévisions mensuelles'!F122 -> 4033.3333 | G18: =+'Prévisions mensuelles'!G122 -> 4033.3333 | H18: =+'Prévisions mensuelles'!H122 -> 4033.3333 | I18: =+'Prévisions mensuelles'!I122 -> 4033.3333 | J18: =+'Prévisions mensuelles'!J122 -> 4033.3333 | ... AO18: =+'Prévisions mensuelles'!AO122 -> 15012.667
B19: Charges sociales | C19: =+'Prévisions mensuelles'!C123 -> 27912.5 | D19: =+'Prévisions mensuelles'!D123 -> 0 | E19: =+'Prévisions mensuelles'!E123 -> 2537.5 | F19: =+'Prévisions mensuelles'!F123 -> 2537.5 | G19: =+'Prévisions mensuelles'!G123 -> 2537.5 | H19: =+'Prévisions mensuelles'!H123 -> 2537.5 | I19: =+'Prévisions mensuelles'!I123 -> 2537.5 | J19: =+'Prévisions mensuelles'!J123 -> 2537.5 | ... AO19: =+'Prévisions mensuelles'!AO123 -> 9848
... B25: IV - Trésorerie finale | C25: =+'Prévisions mensuelles'!C129 -> 31630.157 | D25: =+'Prévisions mensuelles'!D129 -> 25516.667 | E25: =+'Prévisions mensuelles'!E129 -> 27376.722 | F25: =+'Prévisions mensuelles'!F129 -> 28161.003 | G25: =+'Prévisions mensuelles'!G129 -> 28542.845 | H25: =+'Prévisions mensuelles'!H129 -> 28925.585 | I25: =+'Prévisions mensuelles'!I129 -> 29309.226 | J25: =+'Prévisions mensuelles'!J129 -> 29693.771 | ... AO25: =+'Prévisions mensuelles'!AO129 -> 137165.29

Sheet Prévisions mensuelles
D1: =EOMONTH(D3,0) -> 46053 | E1: =EOMONTH(E3,0) -> 46081 | F1: =EOMONTH(F3,0) -> 46112 | G1: =EOMONTH(G3,0) -> 46142 | H1: =EOMONTH(H3,0) -> 46173 | I1: =EOMONTH(I3,0) -> 46203 | J1: =EOMONTH(J3,0) -> 46234 | K1: =EOMONTH(K3,0) -> 46265 | ... O1: =EOMONTH(O3,0) -> 46387 | Q1: =EOMONTH(Q3,0) -> 46418 | R1: =EOMONTH(R3,0) -> 46446 | S1: =EOMONTH(S3,0) -> 46477 | T1: =EOMONTH(T3,0) -> 46507 | U1: =EOMONTH(U3,0) -> 46538 | V1: =EOMONTH(V3,0) -> 46568 | W1: =EOMONTH(W3,0) -> 46599 | X1: =EOMONTH(X3,0) -> 46630 | ... AB1: =EOMONTH(AB3,0) -> 46752 | AD1: =EOMONTH(AD3,0) -> 46783 | AE1: =EOMONTH(AE3,0) -> 46812 | AF1: =EOMONTH(AF3,0) -> 46843 | AG1: =EOMONTH(AG3,0) -> 46873 | AH1: =EOMONTH(AH3,0) -> 46904 | AI1: =EOMONTH(AI3,0) -> 46934 | AJ1: =EOMONTH(AJ3,0) -> 46965 | AK1: =EOMONTH(AK3,0) -> 46996 | ... AO1: =EOMONTH(AO3,0) -> 47118
B2: 1) Budget des ventes
D3: 46053 | E3: 46081 | F3: 46112 | G3: 46142 | H3: 46173 | I3: 46203 | J3: 46234 | K3: 46265 | L3: 46295 | M3: 46326 | N3: 46356 | O3: 46387 | Q3: 46418 | R3: 46446 | S3: 46477 | T3: 46507 | U3: 46538 | V3: 46568 | W3: 46599 | X3: 46630 | Y3: 46660 | Z3: 46691 | AA3: 46721 | AB3: 46752 | AD3: 46783 | AE3: 46811 | AF3: 46843 | AG3: 46873 | AH3: 46904 | AI3: 46934 | AJ3: 46965 | AK3: 46996 | AL3: 47026 | AM3: 47057 | AN3: 47087 | AO3: 47118
B5: a) Expertise-comptable
B7: Chiffre d'affaires | C7: =SAISIE!C8 -> 80000 | D7: =SAISIE!$C$8/12 -> 6666.6667 | E7: =SAISIE!$C$8/12 -> 6666.6667 | F7: =SAISIE!$C$8/12 -> 6666.6667 | G7: =SAISIE!$C$8/12 -> 6666.6667 | H7: =SAISIE!$C$8/12 -> 6666.6667 | I7: =SAISIE!$C$8/12 -> 6666.6667 | J7: =SAISIE!$C$8/12 -> 6666.6667 | K7: =SAISIE!$C$8/12 -> 6666.6667 | ... O7: =SAISIE!$C$8/12 -> 6666.6667 | P7: =SAISIE!D8 -> 160000 | Q7: =SAISIE!$D$8/12 -> 13333.333 | R7: =SAISIE!$D$8/12 -> 13333.333 | S7: =SAISIE!$D$8/12 -> 13333.333 | T7: =SAISIE!$D$8/12 -> 13333.333 | U7: =SAISIE!$D$8/12 -> 13333.333 | V7: =SAISIE!$D$8/12 -> 13333.333 | W7: =SAISIE!$D$8/12 -> 13333.333 | X7: =SAISIE!$D$8/12 -> 13333.333 | ... AB7: =SAISIE!$D$8/12 -> 13333.333 | AC7: =SAISIE!E8 -> 240000 | AD7: =SAISIE!$E$8/12 -> 20000 | AE7: =SAISIE!$E$8/12 -> 20000 | AF7: =SAISIE!$E$8/12 -> 20000 | AG7: =SAISIE!$E$8/12 -> 20000 | AH7: =SAISIE!$E$8/12 -> 20000 | AI7: =SAISIE!$E$8/12 -> 20000 | AJ7: =SAISIE!$E$8/12 -> 20000 | AK7: =SAISIE!$E$8/12 -> 20000 | ... AO7: =SAISIE!$E$8/12 -> 20000
C8: 0.5
B9: b) CAC
B11: Chiffre d'affaires | C11: =SAISIE!C9 -> 0 | D11: =SAISIE!$C$9/12 -> 0 | E11: =SAISIE!$C$9/12 -> 0 | F11: =SAISIE!$C$9/12 -> 0 | G11: =SAISIE!$C$9/12 -> 0 | H11: =SAISIE!$C$9/12 -> 0 | I11: =SAISIE!$C$9/12 -> 0 | J11: =SAISIE!$C$9/12 -> 0 | K11: =SAISIE!$C$9/12 -> 0 | ... O11: =SAISIE!$C$9/12 -> 0 | P11: =SAISIE!D9 -> 36000 | Q11: =SAISIE!$D$9/12 -> 3000 | R11: =SAISIE!$D$9/12 -> 3000 | S11: =SAISIE!$D$9/12 -> 3000 | T11: =SAISIE!$D$9/12 -> 3000 | U11: =SAISIE!$D$9/12 -> 3000 | V11: =SAISIE!$D$9/12 -> 3000 | W11: =SAISIE!$D$9/12 -> 3000 | X11: =SAISIE!$D$9/12 -> 3000 | ... AB11: =SAISIE!$D$9/12 -> 3000 | AC11: =SAISIE!E9 -> 72000 | AD11: =SAISIE!$E$9/12 -> 6000 | AE11: =SAISIE!$E$9/12 -> 6000 | AF11: =SAISIE!$E$9/12 -> 6000 | AG11: =SAISIE!$E$9/12 -> 6000 | AH11: =SAISIE!$E$9/12 -> 6000 | AI11: =SAISIE!$E$9/12 -> 6000 | AJ11: =SAISIE!$E$9/12 -> 6000 | AK11: =SAISIE!$E$9/12 -> 6000 | ... AO11: =SAISIE!$E$9/12 -> 6000
C12: 0.11666667
B13: c) Social
B15: Chiffre d'affaires | C15: =SAISIE!C10 -> 5000 | D15: =SAISIE!$C$10/12 -> 416.66667 | E15: =SAISIE!$C$10/12 -> 416.66667 | F15: =SAISIE!$C$10/12 -> 416.66667 | G15: =SAISIE!$C$10/12 -> 416.66667 | H15: =SAISIE!$C$10/12 -> 416.66667 | I15: =SAISIE!$C$10/12 -> 416.66667 | J15: =SAISIE!$C$10/12 -> 416.66667 | K15: =SAISIE!$C$10/12 -> 416.66667 | ... O15: =SAISIE!$C$10/12 -> 416.66667 | P15: =SAISIE!D10 -> 10000 | Q15: =SAISIE!$D$10/12 -> 833.33333 | R15: =SAISIE!$D$10/12 -> 833.33333 | S15: =SAISIE!$D$10/12 -> 833.33333 | T15: =SAISIE!$D$10/12 -> 833.33333 | U15: =SAISIE!$D$10/12 -> 833.33333 | V15: =SAISIE!$D$10/12 -> 833.33333 | W15: =SAISIE!$D$10/12 -> 833.33333 | X15: =SAISIE!$D$10/12 -> 833.33333 | ... AB15: =SAISIE!$D$10/12 -> 833.33333 | AC15: =SAISIE!E10 -> 15000 | AD15: =SAISIE!$E$10/12 -> 1250 | AE15: =SAISIE!$E$10/12 -> 1250 | AF15: =SAISIE!$E$10/12 -> 1250 | AG15: =SAISIE!$E$10/12 -> 1250 | AH15: =SAISIE!$E$10/12 -> 1250 | AI15: =SAISIE!$E$10/12 -> 1250 | AJ15: =SAISIE!$E$10/12 -> 1250 | AK15: =SAISIE!$E$10/12 -> 1250 | ... AO15: =SAISIE!$E$10/12 -> 1250
C16: 0.11666667
B17: d) Juridique
B19: Chiffre d'affaires | C19: =SAISIE!C11 -> 3000 | D19: =SAISIE!$C$11/12 -> 250 | E19: =SAISIE!$C$11/12 -> 250 | F19: =SAISIE!$C$11/12 -> 250 | G19: =SAISIE!$C$11/12 -> 250 | H19: =SAISIE!$C$11/12 -> 250 | I19: =SAISIE!$C$11/12 -> 250 | J19: =SAISIE!$C$11/12 -> 250 | K19: =SAISIE!$C$11/12 -> 250 | ... O19: =SAISIE!$C$11/12 -> 250 | P19: =SAISIE!D11 -> 6000 | Q19: =SAISIE!$D$11/12 -> 500 | R19: =SAISIE!$D$11/12 -> 500 | S19: =SAISIE!$D$11/12 -> 500 | T19: =SAISIE!$D$11/12 -> 500 | U19: =SAISIE!$D$11/12 -> 500 | V19: =SAISIE!$D$11/12 -> 500 | W19: =SAISIE!$D$11/12 -> 500 | X19: =SAISIE!$D$11/12 -> 500 | ... AB19: =SAISIE!$D$11/12 -> 500 | AC19: =SAISIE!E11 -> 18000 | AD19: =SAISIE!$E$11/12 -> 1500 | AE19: =SAISIE!$E$11/12 -> 1500 | AF19: =SAISIE!$E$11/12 -> 1500 | AG19: =SAISIE!$E$11/12 -> 1500 | AH19: =SAISIE!$E$11/12 -> 1500 | AI19: =SAISIE!$E$11/12 -> 1500 | AJ19: =SAISIE!$E$11/12 -> 1500 | AK19: =SAISIE!$E$11/12 -> 1500 | ... AO19: =SAISIE!$E$11/12 -> 1500
C20: 0.16666667
B21: e) DAF externalisé
B23: Chiffre d'affaires | C23: =SAISIE!C12 -> 25000 | D23: =SAISIE!$C$12/12 -> 2083.3333 | E23: =SAISIE!$C$12/12 -> 2083.3333 | F23: =SAISIE!$C$12/12 -> 2083.3333 | G23: =SAISIE!$C$12/12 -> 2083.3333 | H23: =SAISIE!$C$12/12 -> 2083.3333 | I23: =SAISIE!$C$12/12 -> 2083.3333 | J23: =SAISIE!$C$12/12 -> 2083.3333 | K23: =SAISIE!$C$12/12 -> 2083.3333 | ... O23: =SAISIE!$C$12/12 -> 2083.3333 | P23: =SAISIE!D12 -> 36000 | Q23: =SAISIE!$D$12/12 -> 3000 | R23: =SAISIE!$D$12/12 -> 3000 | S23: =SAISIE!$D$12/12 -> 3000 | T23: =SAISIE!$D$12/12 -> 3000 | U23: =SAISIE!$D$12/12 -> 3000 | V23: =SAISIE!$D$12/12 -> 3000 | W23: =SAISIE!$D$12/12 -> 3000 | X23: =SAISIE!$D$12/12 -> 3000 | ... AB23: =SAISIE!$D$12/12 -> 3000 | AC23: =SAISIE!E12 -> 72000 | AD23: =SAISIE!$E$12/12 -> 6000 | AE23: =SAISIE!$E$12/12 -> 6000 | AF23: =SAISIE!$E$12/12 -> 6000 | AG23: =SAISIE!$E$12/12 -> 6000 | AH23: =SAISIE!$E$12/12 -> 6000 | AI23: =SAISIE!$E$12/12 -> 6000 | AJ23: =SAISIE!$E$12/12 -> 6000 | AK23: =SAISIE!$E$12/12 -> 6000 | ... AO23: =SAISIE!$E$12/12 -> 6000
B26: 2) Budget d'exploitation
D28: 46053 | E28: 46081 | F28: 46112 | G28: 46142 | H28: 46173 | I28: 46203 | J28: 46234 | K28: 46265 | L28: 46295 | M28: 46326 | N28: 46356 | O28: 46387 | Q28: 46418 | R28: 46446 | S28: 46477 | T28: 46507 | U28: 46538 | V28: 46568 | W28: 46599 | X28: 46630 | Y28: 46660 | Z28: 46691 | AA28: 46721 | AB28: 46752 | AD28: 46783 | AE28: 46811 | AF28: 46839 | AG28: 46867 | AH28: 46895 | AI28: 46923 | AJ28: 46951 | AK28: 46979 | AL28: 47007 | AM28: 47035 | AN28: 47063 | AO28: 47091
B30: =+B5 -> a) Expertise-comptable | C30: =+C7 -> 80000 | D30: =+D7 -> 6666.6667 | E30: =+E7 -> 6666.6667 | F30: =+F7 -> 6666.6667 | G30: =+G7 -> 6666.6667 | H30: =+H7 -> 6666.6667 | I30: =+I7 -> 6666.6667 | J30: =+J7 -> 6666.6667 | ... AO30: =+AO7 -> 20000
B31: =+B9 -> b) CAC | C31: =+C11 -> 0 | D31: =+D11 -> 0 | E31: =+E11 -> 0 | F31: =+F11 -> 0 | G31: =+G11 -> 0 | H31: =+H11 -> 0 | I31: =+I11 -> 0 | J31: =+J11 -> 0 | ... AO31: =+AO11 -> 6000
B32: =+B13 -> c) Social | C32: =+C15 -> 5000 | D32: =+D15 -> 416.66667 | E32: =+E15 -> 416.66667 | F32: =+F15 -> 416.66667 | G32: =+G15 -> 416.66667 | H32: =+H15 -> 416.66667 | I32: =+I15 -> 416.66667 | J32: =+J15 -> 416.66667 | ... AO32: =+AO15 -> 1250
B33: =+B17 -> d) Juridique | C33: =+C19 -> 3000 | D33: =+D19 -> 250 | E33: =+E19 -> 250 | F33: =+F19 -> 250 | G33: =+G19 -> 250 | H33: =+H19 -> 250 | I33: =+I19 -> 250 | J33: =+J19 -> 250 | ... AO33: =+AO19 -> 1500
B34: =+B21 -> e) DAF externalisé | C34: =+C23 -> 25000 | D34: =+D23 -> 2083.3333 | E34: =+E23 -> 2083.3333 | F34: =+F23 -> 2083.3333 | G34: =+G23 -> 2083.3333 | H34: =+H23 -> 2083.3333 | I34: =+I23 -> 2083.3333 | J34: =+J23 -> 2083.3333 | ... AO34: =+AO23 -> 6000
B36: Chiffre d'affaires | C36: =SUM(C30:C35) -> 113000 | D36: =SUM(D30:D35) -> 9416.6667 | E36: =SUM(E30:E35) -> 9416.6667 | F36: =SUM(F30:F35) -> 9416.6667 | G36: =SUM(G30:G35) -> 9416.6667 | H36: =SUM(H30:H35) -> 9416.6667 | I36: =SUM(I30:I35) -> 9416.6667 | J36: =SUM(J30:J35) -> 9416.6667 | ... AO36: =SUM(AO30:AO35) -> 34750
B37: *PCA n-1 | C37: =SUM(D37:O37) -> 0 | D37: =Bilan!C36 -> 0
B39: Marge directe | D39: =+(D36-D42)/D36 -> 0.93628319 | E39: =+(E36-E42)/E36 -> 0.93628319 | F39: =+(F36-F42)/F36 -> 0.93628319 | G39: =+(G36-G42)/G36 -> 0.93628319 | H39: =+(H36-H42)/H36 -> 0.93628319 | I39: =+(I36-I42)/I36 -> 0.93628319 | J39: =+(J36-J42)/J36 -> 0.93628319 | K39: =+(K36-K42)/K36 -> 0.93628319 | ... O39: =+(O36-O42)/O36 -> 0.93628319 | Q39: =+(Q36-Q42)/Q36 -> 0.97096774 | R39: =+(R36-R42)/R36 -> 0.97096774 | S39: =+(S36-S42)/S36 -> 0.97096774 | T39: =+(T36-T42)/T36 -> 0.97096774 | U39: =+(U36-U42)/U36 -> 0.97096774 | V39: =+(V36-V42)/V36 -> 0.97096774 | W39: =+(W36-W42)/W36 -> 0.97096774 | X39: =+(X36-X42)/X36 -> 0.97096774 | ... AB39: =+(AB36-AB42)/AB36 -> 0.97096774 | AD39: =+(AD36-AD42)/AD36 -> 0.98273381 | AE39: =+(AE36-AE42)/AE36 -> 0.98273381 | AF39: =+(AF36-AF42)/AF36 -> 0.98273381 | AG39: =+(AG36-AG42)/AG36 -> 0.98273381 | AH39: =+(AH36-AH42)/AH36 -> 0.98273381 | AI39: =+(AI36-AI42)/AI36 -> 0.98273381 | AJ39: =+(AJ36-AJ42)/AJ36 -> 0.98273381 | AK39: =+(AK36-AK42)/AK36 -> 0.98273381 | ... AO39: =+(AO36-AO42)/AO36 -> 0.98273381
B40: Logiciels | C40: =SAISIE!C16 -> 6000 | D40: =SAISIE!$C$16/12 -> 500 | E40: =SAISIE!$C$16/12 -> 500 | F40: =SAISIE!$C$16/12 -> 500 | G40: =SAISIE!$C$16/12 -> 500 | H40: =SAISIE!$C$16/12 -> 500 | I40: =SAISIE!$C$16/12 -> 500 | J40: =SAISIE!$C$16/12 -> 500 | K40: =SAISIE!$C$16/12 -> 500 | ... O40: =SAISIE!$C$16/12 -> 500 | P40: =SAISIE!D16 -> 6000 | Q40: =SAISIE!$D$16/12 -> 500 | R40: =SAISIE!$D$16/12 -> 500 | S40: =SAISIE!$D$16/12 -> 500 | T40: =SAISIE!$D$16/12 -> 500 | U40: =SAISIE!$D$16/12 -> 500 | V40: =SAISIE!$D$16/12 -> 500 | W40: =SAISIE!$D$16/12 -> 500 | X40: =SAISIE!$D$16/12 -> 500 | ... AB40: =SAISIE!$D$16/12 -> 500 | AC40: =SAISIE!E16 -> 6000 | AD40: =SAISIE!$E$16/12 -> 500 | AE40: =SAISIE!$E$16/12 -> 500 | AF40: =SAISIE!$E$16/12 -> 500 | AG40: =SAISIE!$E$16/12 -> 500 | AH40: =SAISIE!$E$16/12 -> 500 | AI40: =SAISIE!$E$16/12 -> 500 | AJ40: =SAISIE!$E$16/12 -> 500 | AK40: =SAISIE!$E$16/12 -> 500 | ... AO40: =SAISIE!$E$16/12 -> 500
B41: Marketing / PUB / investissement | C41: =SAISIE!C17 -> 1200 | D41: =SAISIE!$C$17/12 -> 100 | E41: =SAISIE!$C$17/12 -> 100 | F41: =SAISIE!$C$17/12 -> 100 | G41: =SAISIE!$C$17/12 -> 100 | H41: =SAISIE!$C$17/12 -> 100 | I41: =SAISIE!$C$17/12 -> 100 | J41: =SAISIE!$C$17/12 -> 100 | K41: =SAISIE!$C$17/12 -> 100 | ... O41: =SAISIE!$C$17/12 -> 100 | P41: =SAISIE!D17 -> 1200 | Q41: =SAISIE!$D$17/12 -> 100 | R41: =SAISIE!$D$17/12 -> 100 | S41: =SAISIE!$D$17/12 -> 100 | T41: =SAISIE!$D$17/12 -> 100 | U41: =SAISIE!$D$17/12 -> 100 | V41: =SAISIE!$D$17/12 -> 100 | W41: =SAISIE!$D$17/12 -> 100 | X41: =SAISIE!$D$17/12 -> 100 | ... AB41: =SAISIE!$D$17/12 -> 100 | AC41: =SAISIE!E17 -> 1200 | AD41: =SAISIE!$E$17/12 -> 100 | AE41: =SAISIE!$E$17/12 -> 100 | AF41: =SAISIE!$E$17/12 -> 100 | AG41: =SAISIE!$E$17/12 -> 100 | AH41: =SAISIE!$E$17/12 -> 100 | AI41: =SAISIE!$E$17/12 -> 100 | AJ41: =SAISIE!$E$17/12 -> 100 | AK41: =SAISIE!$E$17/12 -> 100 | ... AO41: =SAISIE!$E$17/12 -> 100
B42: Charges directes | C42: =SUM(C40:C41) -> 7200 | D42: =SUM(D40:D41) -> 600 | E42: =SUM(E40:E41) -> 600 | F42: =SUM(F40:F41) -> 600 | G42: =SUM(G40:G41) -> 600 | H42: =SUM(H40:H41) -> 600 | I42: =SUM(I40:I41) -> 600 | J42: =SUM(J40:J41) -> 600 | ... O42: =SUM(O40:O41) -> 600 | P42: =SUM(Q42:AB42) -> 7200 | Q42: =SUM(Q40:Q41) -> 600 | R42: =SUM(R40:R41) -> 600 | S42: =SUM(S40:S41) -> 600 | T42: =SUM(T40:T41) -> 600 | U42: =SUM(U40:U41) -> 600 | V42: =SUM(V40:V41) -> 600 | W42: =SUM(W40:W41) -> 600 | X42: =SUM(X40:X41) -> 600 | ... AB42: =SUM(AB40:AB41) -> 600 | AC42: =SUM(AD42:AO42) -> 7200 | AD42: =SUM(AD40:AD41) -> 600 | AE42: =SUM(AE40:AE41) -> 600 | AF42: =SUM(AF40:AF41) -> 600 | AG42: =SUM(AG40:AG41) -> 600 | AH42: =SUM(AH40:AH41) -> 600 | AI42: =SUM(AI40:AI41) -> 600 | AJ42: =SUM(AJ40:AJ41) -> 600 | AK42: =SUM(AK40:AK41) -> 600 | ... AO42: =SUM(AO40:AO41) -> 600
B43: Ordre | C43: =SAISIE!C21 -> 500 | D43: =SAISIE!$C$21/12 -> 41.666667 | E43: =SAISIE!$C$21/12 -> 41.666667 | F43: =SAISIE!$C$21/12 -> 41.666667 | G43: =SAISIE!$C$21/12 -> 41.666667 | H43: =SAISIE!$C$21/12 -> 41.666667 | I43: =SAISIE!$C$21/12 -> 41.666667 | J43: =SAISIE!$C$21/12 -> 41.666667 | K43: =SAISIE!$C$21/12 -> 41.666667 | ... O43: =SAISIE!$C$21/12 -> 41.666667 | P43: =SAISIE!D21 -> 500 | Q43: =SAISIE!$D$21/12 -> 41.666667 | R43: =SAISIE!$D$21/12 -> 41.666667 | S43: =SAISIE!$D$21/12 -> 41.666667 | T43: =SAISIE!$D$21/12 -> 41.666667 | U43: =SAISIE!$D$21/12 -> 41.666667 | V43: =SAISIE!$D$21/12 -> 41.666667 | W43: =SAISIE!$D$21/12 -> 41.666667 | X43: =SAISIE!$D$21/12 -> 41.666667 | ... AB43: =SAISIE!$D$21/12 -> 41.666667 | AC43: =SAISIE!E21 -> 500 | AD43: =SAISIE!$E$21/12 -> 41.666667 | AE43: =SAISIE!$E$21/12 -> 41.666667 | AF43: =SAISIE!$E$21/12 -> 41.666667 | AG43: =SAISIE!$E$21/12 -> 41.666667 | AH43: =SAISIE!$E$21/12 -> 41.666667 | AI43: =SAISIE!$E$21/12 -> 41.666667 | AJ43: =SAISIE!$E$21/12 -> 41.666667 | AK43: =SAISIE!$E$21/12 -> 41.666667 | ... AO43: =SAISIE!$E$21/12 -> 41.666667
B44: Assurances | C44: =SAISIE!C22 -> 2000 | D44: =SAISIE!$C$22/12 -> 166.66667 | E44: =SAISIE!$C$22/12 -> 166.66667 | F44: =SAISIE!$C$22/12 -> 166.66667 | G44: =SAISIE!$C$22/12 -> 166.66667 | H44: =SAISIE!$C$22/12 -> 166.66667 | I44: =SAISIE!$C$22/12 -> 166.66667 | J44: =SAISIE!$C$22/12 -> 166.66667 | K44: =SAISIE!$C$22/12 -> 166.66667 | ... O44: =SAISIE!$C$22/12 -> 166.66667 | P44: =SAISIE!D22 -> 3000 | Q44: =SAISIE!$D$22/12 -> 250 | R44: =SAISIE!$D$22/12 -> 250 | S44: =SAISIE!$D$22/12 -> 250 | T44: =SAISIE!$D$22/12 -> 250 | U44: =SAISIE!$D$22/12 -> 250 | V44: =SAISIE!$D$22/12 -> 250 | W44: =SAISIE!$D$22/12 -> 250 | X44: =SAISIE!$D$22/12 -> 250 | ... AB44: =SAISIE!$D$22/12 -> 250 | AC44: =SAISIE!E22 -> 5000 | AD44: =SAISIE!$E$22/12 -> 416.66667 | AE44: =SAISIE!$E$22/12 -> 416.66667 | AF44: =SAISIE!$E$22/12 -> 416.66667 | AG44: =SAISIE!$E$22/12 -> 416.66667 | AH44: =SAISIE!$E$22/12 -> 416.66667 | AI44: =SAISIE!$E$22/12 -> 416.66667 | AJ44: =SAISIE!$E$22/12 -> 416.66667 | AK44: =SAISIE!$E$22/12 -> 416.66667 | ... AO44: =SAISIE!$E$22/12 -> 416.66667
B45: Loyers crédit-bail | C45: =SAISIE!C23 -> 0 | D45: =SAISIE!$C$23/12 -> 0 | E45: =SAISIE!$C$23/12 -> 0 | F45: =SAISIE!$C$23/12 -> 0 | G45: =SAISIE!$C$23/12 -> 0 | H45: =SAISIE!$C$23/12 -> 0 | I45: =SAISIE!$C$23/12 -> 0 | J45: =SAISIE!$C$23/12 -> 0 | K45: =SAISIE!$C$23/12 -> 0 | ... O45: =SAISIE!$C$23/12 -> 0 | P45: =SAISIE!D23 -> 0 | Q45: =SAISIE!$D$23/12 -> 0 | R45: =SAISIE!$D$23/12 -> 0 | S45: =SAISIE!$D$23/12 -> 0 | T45: =SAISIE!$D$23/12 -> 0 | U45: =SAISIE!$D$23/12 -> 0 | V45: =SAISIE!$D$23/12 -> 0 | W45: =SAISIE!$D$23/12 -> 0 | X45: =SAISIE!$D$23/12 -> 0 | ... AB45: =SAISIE!$D$23/12 -> 0 | AC45: =SAISIE!E23 -> 0 | AD45: =SAISIE!$E$23/12 -> 0 | AE45: =SAISIE!$E$23/12 -> 0 | AF45: =SAISIE!$E$23/12 -> 0 | AG45: =SAISIE!$E$23/12 -> 0 | AH45: =SAISIE!$E$23/12 -> 0 | AI45: =SAISIE!$E$23/12 -> 0 | AJ45: =SAISIE!$E$23/12 -> 0 | AK45: =SAISIE!$E$23/12 -> 0 | ... AO45: =SAISIE!$E$23/12 -> 0
B46: Location bureaux coworking | C46: =SAISIE!C24 -> 1200 | D46: =SAISIE!$C$24/12 -> 100 | E46: =SAISIE!$C$24/12 -> 100 | F46: =SAISIE!$C$24/12 -> 100 | G46: =SAISIE!$C$24/12 -> 100 | H46: =SAISIE!$C$24/12 -> 100 | I46: =SAISIE!$C$24/12 -> 100 | J46: =SAISIE!$C$24/12 -> 100 | K46: =SAISIE!$C$24/12 -> 100 | ... O46: =SAISIE!$C$24/12 -> 100 | P46: =SAISIE!D24 -> 1200 | Q46: =SAISIE!$D$24/12 -> 100 | R46: =SAISIE!$D$24/12 -> 100 | S46: =SAISIE!$D$24/12 -> 100 | T46: =SAISIE!$D$24/12 -> 100 | U46: =SAISIE!$D$24/12 -> 100 | V46: =SAISIE!$D$24/12 -> 100 | W46: =SAISIE!$D$24/12 -> 100 | X46: =SAISIE!$D$24/12 -> 100 | ... AB46: =SAISIE!$D$24/12 -> 100 | AC46: =SAISIE!E24 -> 1200 | AD46: =SAISIE!$E$24/12 -> 100 | AE46: =SAISIE!$E$24/12 -> 100 | AF46: =SAISIE!$E$24/12 -> 100 | AG46: =SAISIE!$E$24/12 -> 100 | AH46: =SAISIE!$E$24/12 -> 100 | AI46: =SAISIE!$E$24/12 -> 100 | AJ46: =SAISIE!$E$24/12 -> 100 | AK46: =SAISIE!$E$24/12 -> 100 | ... AO46: =SAISIE!$E$24/12 -> 100
B47: Frais de production | C47: =SAISIE!C25 -> 600 | D47: =SAISIE!$C$25/12 -> 50 | E47: =SAISIE!$C$25/12 -> 50 | F47: =SAISIE!$C$25/12 -> 50 | G47: =SAISIE!$C$25/12 -> 50 | H47: =SAISIE!$C$25/12 -> 50 | I47: =SAISIE!$C$25/12 -> 50 | J47: =SAISIE!$C$25/12 -> 50 | K47: =SAISIE!$C$25/12 -> 50 | ... O47: =SAISIE!$C$25/12 -> 50 | P47: =SAISIE!D25 -> 600 | Q47: =SAISIE!$D$25/12 -> 50 | R47: =SAISIE!$D$25/12 -> 50 | S47: =SAISIE!$D$25/12 -> 50 | T47: =SAISIE!$D$25/12 -> 50 | U47: =SAISIE!$D$25/12 -> 50 | V47: =SAISIE!$D$25/12 -> 50 | W47: =SAISIE!$D$25/12 -> 50 | X47: =SAISIE!$D$25/12 -> 50 | ... AB47: =SAISIE!$D$25/12 -> 50 | AC47: =SAISIE!E25 -> 600 | AD47: =SAISIE!$E$25/12 -> 50 | AE47: =SAISIE!$E$25/12 -> 50 | AF47: =SAISIE!$E$25/12 -> 50 | AG47: =SAISIE!$E$25/12 -> 50 | AH47: =SAISIE!$E$25/12 -> 50 | AI47: =SAISIE!$E$25/12 -> 50 | AJ47: =SAISIE!$E$25/12 -> 50 | AK47: =SAISIE!$E$25/12 -> 50 | ... AO47: =SAISIE!$E$25/12 -> 50
B48: Honoraires | C48: =SAISIE!C26 -> 2400 | D48: =SAISIE!$C$26/12 -> 200 | E48: =SAISIE!$C$26/12 -> 200 | F48: =SAISIE!$C$26/12 -> 200 | G48: =SAISIE!$C$26/12 -> 200 | H48: =SAISIE!$C$26/12 -> 200 | I48: =SAISIE!$C$26/12 -> 200 | J48: =SAISIE!$C$26/12 -> 200 | K48: =SAISIE!$C$26/12 -> 200 | ... O48: =SAISIE!$C$26/12 -> 200 | P48: =SAISIE!D26 -> 2400 | Q48: =SAISIE!$D$26/12 -> 200 | R48: =SAISIE!$D$26/12 -> 200 | S48: =SAISIE!$D$26/12 -> 200 | T48: =SAISIE!$D$26/12 -> 200 | U48: =SAISIE!$D$26/12 -> 200 | V48: =SAISIE!$D$26/12 -> 200 | W48: =SAISIE!$D$26/12 -> 200 | X48: =SAISIE!$D$26/12 -> 200 | ... AB48: =SAISIE!$D$26/12 -> 200 | AC48: =SAISIE!E26 -> 2400 | AD48: =SAISIE!$E$26/12 -> 200 | AE48: =SAISIE!$E$26/12 -> 200 | AF48: =SAISIE!$E$26/12 -> 200 | AG48: =SAISIE!$E$26/12 -> 200 | AH48: =SAISIE!$E$26/12 -> 200 | AI48: =SAISIE!$E$26/12 -> 200 | AJ48: =SAISIE!$E$26/12 -> 200 | AK48: =SAISIE!$E$26/12 -> 200 | ... AO48: =SAISIE!$E$26/12 -> 200
B49: Publicité | C49: =SAISIE!C27 -> 600 | D49: =SAISIE!$C$27/12 -> 50 | E49: =SAISIE!$C$27/12 -> 50 | F49: =SAISIE!$C$27/12 -> 50 | G49: =SAISIE!$C$27/12 -> 50 | H49: =SAISIE!$C$27/12 -> 50 | I49: =SAISIE!$C$27/12 -> 50 | J49: =SAISIE!$C$27/12 -> 50 | K49: =SAISIE!$C$27/12 -> 50 | ... O49: =SAISIE!$C$27/12 -> 50 | P49: =SAISIE!D27 -> 600 | Q49: =SAISIE!$D$27/12 -> 50 | R49: =SAISIE!$D$27/12 -> 50 | S49: =SAISIE!$D$27/12 -> 50 | T49: =SAISIE!$D$27/12 -> 50 | U49: =SAISIE!$D$27/12 -> 50 | V49: =SAISIE!$D$27/12 -> 50 | W49: =SAISIE!$D$27/12 -> 50 | X49: =SAISIE!$D$27/12 -> 50 | ... AB49: =SAISIE!$D$27/12 -> 50 | AC49: =SAISIE!E27 -> 600 | AD49: =SAISIE!$E$27/12 -> 50 | AE49: =SAISIE!$E$27/12 -> 50 | AF49: =SAISIE!$E$27/12 -> 50 | AG49: =SAISIE!$E$27/12 -> 50 | AH49: =SAISIE!$E$27/12 -> 50 | AI49: =SAISIE!$E$27/12 -> 50 | AJ49: =SAISIE!$E$27/12 -> 50 | AK49: =SAISIE!$E$27/12 -> 50 | ... AO49: =SAISIE!$E$27/12 -> 50
B50: Frais de déplacement | C50: =SAISIE!C28 -> 1200 | D50: =SAISIE!$C$28/12 -> 100 | E50: =SAISIE!$C$28/12 -> 100 | F50: =SAISIE!$C$28/12 -> 100 | G50: =SAISIE!$C$28/12 -> 100 | H50: =SAISIE!$C$28/12 -> 100 | I50: =SAISIE!$C$28/12 -> 100 | J50: =SAISIE!$C$28/12 -> 100 | K50: =SAISIE!$C$28/12 -> 100 | ... O50: =SAISIE!$C$28/12 -> 100 | P50: =SAISIE!D28 -> 1200 | Q50: =SAISIE!$D$28/12 -> 100 | R50: =SAISIE!$D$28/12 -> 100 | S50: =SAISIE!$D$28/12 -> 100 | T50: =SAISIE!$D$28/12 -> 100 | U50: =SAISIE!$D$28/12 -> 100 | V50: =SAISIE!$D$28/12 -> 100 | W50: =SAISIE!$D$28/12 -> 100 | X50: =SAISIE!$D$28/12 -> 100 | ... AB50: =SAISIE!$D$28/12 -> 100 | AC50: =SAISIE!E28 -> 1200 | AD50: =SAISIE!$E$28/12 -> 100 | AE50: =SAISIE!$E$28/12 -> 100 | AF50: =SAISIE!$E$28/12 -> 100 | AG50: =SAISIE!$E$28/12 -> 100 | AH50: =SAISIE!$E$28/12 -> 100 | AI50: =SAISIE!$E$28/12 -> 100 | AJ50: =SAISIE!$E$28/12 -> 100 | AK50: =SAISIE!$E$28/12 -> 100 | ... AO50: =SAISIE!$E$28/12 -> 100
B51: Frais missions | C51: =SAISIE!C29 -> 1800 | D51: =SAISIE!$C$29/12 -> 150 | E51: =SAISIE!$C$29/12 -> 150 | F51: =SAISIE!$C$29/12 -> 150 | G51: =SAISIE!$C$29/12 -> 150 | H51: =SAISIE!$C$29/12 -> 150 | I51: =SAISIE!$C$29/12 -> 150 | J51: =SAISIE!$C$29/12 -> 150 | K51: =SAISIE!$C$29/12 -> 150 | ... O51: =SAISIE!$C$29/12 -> 150 | P51: =SAISIE!D29 -> 1800 | Q51: =SAISIE!$D$29/12 -> 150 | R51: =SAISIE!$D$29/12 -> 150 | S51: =SAISIE!$D$29/12 -> 150 | T51: =SAISIE!$D$29/12 -> 150 | U51: =SAISIE!$D$29/12 -> 150 | V51: =SAISIE!$D$29/12 -> 150 | W51: =SAISIE!$D$29/12 -> 150 | X51: =SAISIE!$D$29/12 -> 150 | ... AB51: =SAISIE!$D$29/12 -> 150 | AC51: =SAISIE!E29 -> 1800 | AD51: =SAISIE!$E$29/12 -> 150 | AE51: =SAISIE!$E$29/12 -> 150 | AF51: =SAISIE!$E$29/12 -> 150 | AG51: =SAISIE!$E$29/12 -> 150 | AH51: =SAISIE!$E$29/12 -> 150 | AI51: =SAISIE!$E$29/12 -> 150 | AJ51: =SAISIE!$E$29/12 -> 150 | AK51: =SAISIE!$E$29/12 -> 150 | ... AO51: =SAISIE!$E$29/12 -> 150
B52: Divers | C52: =SAISIE!C30 -> 1200 | D52: =SAISIE!$C$30/12 -> 100 | E52: =SAISIE!$C$30/12 -> 100 | F52: =SAISIE!$C$30/12 -> 100 | G52: =SAISIE!$C$30/12 -> 100 | H52: =SAISIE!$C$30/12 -> 100 | I52: =SAISIE!$C$30/12 -> 100 | J52: =SAISIE!$C$30/12 -> 100 | K52: =SAISIE!$C$30/12 -> 100 | ... O52: =SAISIE!$C$30/12 -> 100 | P52: =SAISIE!D30 -> 1200 | Q52: =SAISIE!$D$30/12 -> 100 | R52: =SAISIE!$D$30/12 -> 100 | S52: =SAISIE!$D$30/12 -> 100 | T52: =SAISIE!$D$30/12 -> 100 | U52: =SAISIE!$D$30/12 -> 100 | V52: =SAISIE!$D$30/12 -> 100 | W52: =SAISIE!$D$30/12 -> 100 | X52: =SAISIE!$D$30/12 -> 100 | ... AB52: =SAISIE!$D$30/12 -> 100 | AC52: =SAISIE!E30 -> 1200 | AD52: =SAISIE!$E$30/12 -> 100 | AE52: =SAISIE!$E$30/12 -> 100 | AF52: =SAISIE!$E$30/12 -> 100 | AG52: =SAISIE!$E$30/12 -> 100 | AH52: =SAISIE!$E$30/12 -> 100 | AI52: =SAISIE!$E$30/12 -> 100 | AJ52: =SAISIE!$E$30/12 -> 100 | AK52: =SAISIE!$E$30/12 -> 100 | ... AO52: =SAISIE!$E$30/12 -> 100
...

Sheet Personnel
B2: Catégorie | C2: Poste | D2: Date entrée | E2: 2025 | T2: 2026 | AI2: 2027
E3: Salaires bruts annuels | F3: Nombre de salariés | T3: Salaires bruts annuels | U3: Nombre de salariés | AI3: Salaires bruts annuels | AJ3: Nombre de salariés
F4: 46023 | G4: =EOMONTH(F4,1) -> 46081 | H4: =EOMONTH(G4,1) -> 46112 | I4: =EOMONTH(H4,1) -> 46142 | J4: =EOMONTH(I4,1) -> 46173 | K4: =EOMONTH(J4,1) -> 46203 | L4: =EOMONTH(K4,1) -> 46234 | M4: =EOMONTH(L4,1) -> 46265 | N4: =EOMONTH(M4,1) -> 46295 | ... Q4: =EOMONTH(P4,1) -> 46387 | R4: Total brut | U4: 46418 | V4: =EOMONTH(U4,1) -> 46446 | W4: =EOMONTH(V4,1) -> 46477 | X4: =EOMONTH(W4,1) -> 46507 | Y4: =EOMONTH(X4,1) -> 46538 | Z4: =EOMONTH(Y4,1) -> 46568 | AA4: =EOMONTH(Z4,1) -> 46599 | AB4: =EOMONTH(AA4,1) -> 46630 | AC4: =EOMONTH(AB4,1) -> 46660 | ... AF4: =EOMONTH(AE4,1) -> 46752 | AG4: TOTAL | AJ4: 46783 | AK4: =EOMONTH(AJ4,1) -> 46812 | AL4: =EOMONTH(AK4,1) -> 46843 | AM4: =EOMONTH(AL4,1) -> 46873 | AN4: =EOMONTH(AM4,1) -> 46904 | AO4: =EOMONTH(AN4,1) -> 46934 | AP4: =EOMONTH(AO4,1) -> 46965 | AQ4: =EOMONTH(AP4,1) -> 46996 | AR4: =EOMONTH(AQ4,1) -> 47026 | ... AU4: =EOMONTH(AT4,1) -> 47118 | AV4: TOTAL
B6: Cadre | C6: Junior | D6: 46023 | E6: 30000 | F6: =+$E6/12 -> 2500 | G6: =+$E6/12 -> 2500 | H6: =+$E6/12 -> 2500 | I6: =+$E6/12 -> 2500 | J6: =+$E6/12 -> 2500 | K6: =+$E6/12 -> 2500 | L6: =+$E6/12 -> 2500 | M6: =+$E6/12 -> 2500 | ... Q6: =+$E6/12 -> 2500 | R6: =SUM(F6:Q6) -> 30000 | U6: 2900 | V6: 2900 | W6: 2900 | X6: 2900 | Y6: 2900 | Z6: 2900 | AA6: 2900 | AB6: 2900 | AC6: 2900 | AD6: 2900 | AE6: 2900 | AF6: 2900 | AG6: =SUM(U6:AF6) -> 34800 | AJ6: 3300 | AK6: 3300 | AL6: 3300 | AM6: 3300 | AN6: 3300 | AO6: 3300 | AP6: 3300 | AQ6: 3300 | AR6: 3300 | AS6: 3300 | AT6: 3300 | AU6: 3300 | AV6: =SUM(AJ6:AU6) -> 39600
