Workbook

Sheet GUIDE
B1: 📋 GUIDE D'UTILISATION — ANNEXE 22
B2: Grille de suivi de la formation continue — Cabinet 100% numérique
B4: OBJECTIF DE L'OUTIL
B5: Cet outil permet à l'expert-comptable de piloter l'intégralité du processus de formation continue de son cabinet : diagnostic de conformité (Art. 22 Code de déontologie), cartographie des compétences, scoring des priorités, plan d'action budgété avec financement OPCO Atlas, et synthèse imprimable pour le dossier qualité NPMQ. Un seul onglet de saisie alimente automatiquement les 3 onglets suivants.
B9: ARCHITECTURE — FLUX DE DONNÉES
B11: ① SAISIE | D11: ② DIAGNOSTIC | F11: ③ PLAN D'ACTION | H11: ④ FICHE QUALITÉ | J11: ⑤ _REF
B12: Seul onglet modifiable ■ Jaune = saisie manuelle ■ Gris = calcul auto • Paramètres cabinet • Effectif & collaborateurs • Évaluation compétences • Formations réalisées • Formations planifiées • AFEST internes | D12: 100% automatisé — 🔒 Protégé • Conformité Art. 22 CD (120h / 3 ans glissants) • Cartographie compétences • Radar de compétences • TOP 5 priorités formation (scoring multicritère) | F12: 100% automatisé — 🔒 Protégé • Budget formations ext. • Financement OPCO Atlas (PDC + DEC/CAC) • Économies AFEST • Investissement net • Suivi comblement déficit | H12: 100% automatisé — 🔒 Protégé • Fiche cabinet • Conformité par collab. • Taux avant/après plan • Budget consolidé • Checklist pièces (NPMQ §44) • Conclusion dynamique | J12: Documentation technique • Fondement réglementaire • Méthodologie scoring • Sources OPCO Atlas • Taux horaire complet • Données OMECA • Articulation Annexe 23
C14: → | E14: → | G14: → | I14: →
B22: MARCHE À SUIVRE
B24: Étape 1 | D24: Ouvrir l'onglet SAISIE | F24: Renseigner les paramètres du cabinet (section A) : nom, N° OEC, masse salariale, OPCO.
B26: Étape 2 | D26: Saisir l'effectif | F26: Compléter la section B : prénom, nom, grade, contrat, ETP, objectif 3 ans, heures par période.
B28: Étape 3 | D28: Évaluer les compétences | F28: Section C : noter chaque collaborateur de 1 à 5 sur les 16 domaines. Fixer cible, criticité, urgence.
B30: Étape 4 | D30: Saisir les formations | F30: Section D (réalisées) + Section E (planifiées S2) + Section F (AFEST internes).
B32: Étape 5 | D32: Consulter le diagnostic | F32: Onglet DIAGNOSTIC : écarts conformité, cartographie compétences, radar, TOP 5 priorités.
B34: Étape 6 | D34: Lire le plan d'action | F34: Onglet PLAN D'ACTION : budget, OPCO Atlas, économies AFEST, investissement net, comblement.
B36: Étape 7 | D36: Imprimer la fiche qualité | F36: Onglet FICHE QUALITÉ : prêt pour le dossier qualité NPMQ. Signer et dater en bas de page.
B38: ⚠️ PREMIÈRE UTILISATION : avant de saisir vos propres données, effacer l'intégralité des cellules jaunes de l'onglet SAISIE (sections A à F). Les données pré-remplies (Cabinet Digit Expertise, collaborateurs Dupré / Martin / Lambert / Renaud, formations, évaluations) sont des exemples fictifs destinés à illustrer le fonctionnement de l'outil. Une fois les cellules jaunes vidées, les onglets DIAGNOSTIC, PLAN D'ACTION et FICHE QUALITÉ se réinitialiseront automatiquement.
B42: RÉFÉRENCES NORMATIVES CLÉS
B43: Art. 22 Code de déontologie | D43: Formation continue ≈ 120h / 3 ans glissants | H43: Décret 2012-432 mod. 2023-388 — éd. janv. 2026
B44: NPMQ 2025 §21-25 | D44: Compétences, plan formation, évaluation, ressources | H44: Arrêté du 30 mai 2024, applicable 01/01/2025
B45: Art. 148 Code de déontologie | D45: Responsabilité EC sur la compétence de l'équipe | H45: Éd. janv. 2026
B46: Art. L6313-2 Code du travail | D46: AFEST — Formation en situation de travail | H46: Loi n°2018-771 du 5 sept. 2018
B47: Art. L561-32 CMF | D47: Formation LCB-FT annuelle obligatoire | H47: Code monétaire et financier
B48: Règl. (UE) 2024/1689 art. 4 | D48: AI literacy — Obligation depuis février 2025 | H48: AI Act — Parlement européen
B49: Art. L6315-1 Code du travail | D49: Entretien professionnel biennal | H49: Évaluation compétences + besoins formation

Sheet SAISIE
B1: 📋 MODE D'EMPLOI : Saisir uniquement les cellules jaunes de cet onglet → Tout le reste se calcule automatiquement dans les 3 onglets suivants
B2: ANNEXE 22 — GRILLE DE SUIVI FORMATION CONTINUE
B3: Cabinet 100% numérique — ■ Cases jaunes = saisie manuelle • ■ Cases grises = calcul automatique
B4: Art. 22 Code de déontologie (Décret 2012-432 mod. 2023-388 — éd. janv. 2026) • NPMQ 2025 §21-25 • Règl. (UE) 2024/1689 art. 4 — AI literacy
B6: A. MON CABINET
B7: Paramètre | C7: Valeur | K7: Note / Source
B8: Nom du cabinet | C8: Cabinet X | K8: Raison sociale fictive
B9: N° inscription OEC | C9: IDF-XXXXX | K9: Région + numéro
B10: Expert-comptable titulaire | C10: M. Dupré | K10: Responsable qualité NPMQ §21
B11: Masse salariale brute (€/an) | C11: 185000 | K11: Tous contrats (comptes 641)
B12: OPCO de branche | C12: OPCO Atlas | K12: CCN 3020 IDCC 0787 — Accord n°48 du 05/12/2025 (minima +2,9% en 2026)
B13: Plafond PDC annuel OPCO (€ HT) | C13: 2800 | K13: OPCO Atlas 2026 : 2 800€ HT/an (<11 sal.) — opco-atlas.fr MAJ 05/01/2026
B14: Plafond stage DEC/CAC (€/sal/an) | C14: 1000 | K14: OPCO Atlas 2026 : 1 000€ HT/sal/an — opco-atlas.fr MAJ 05/01/2026
B16: EFFECTIF | C16: 4 | D16: ETP | E16: =SUM(F20:F29) -> 3.8 | F16: Taux hor. complet | G16: =IF(E16=0,0,ROUND(C11/(E16*1607)*1.45*1.18,0)) -> 52 | K16: Formule : Masse salariale brute / (ETP × 1 607h) × 1,45 × 1,18. Soit : 185 000€ / (3,8 × 1 607) × 1,45 × 1,18 ≈ 52€/h. Charges patronales 2026 : 43-45% (coef. 1,45 — URSSAF / LFSS 2026, hausse cotis. vieillesse déplaf. 2,02→2,11%). Frais structure : 18% (coef. 1,18 — benchmark OMECA S2 2025 cabinets <10 sal.).
B18: B. MES COLLABORATEURS
B19: Prénom | C19: Nom | D19: Grade | E19: Contrat | F19: ETP | G19: Obj. 3 ans (h) | H19: Heures 2024 | I19: Heures 2025 | J19: Heures S1 2026 | K19: Note
B20: M. | C20: Dupré | D20: Expert-comptable | E20: Gérant TNS | F20: 1 | G20: 120 | H20: 45 | I20: 34.5 | J20: 7 | K20: 120h/3 ans (art. 22 CD éd. janv. 2026). S1 2026 = 7h (LCB-FT 3,5h row 65 + webinaire CROEC-IDF 3,5h row 70). Déficit résiduel comblé après exécution intégrale du plan d'action S2 2026.
B21: Lucas | C21: Martin | D21: Apprenti | E21: Alternance | F21: 0.8 | G21: 40 | H21: 0 | I21: 14 | J21: 3.5 | K21: 40h/an proratisé (apprenti sept. 2025, 0,8 ETP). Non soumis au seuil 60h structurées. Totaux par période = heures homologuées OEC uniquement (17,5h). Les heures non homologuées (onboarding non structuré 7h row 60 + autoformation libre 3h row 69) figurent au registre (section D) mais sont exclues du décompte Art. 22 CD conformément à la règle _REF §8.
B22: Marie | C22: Lambert | D22: Confirmée (5 ans) | E22: CDI | F22: 1 | G22: 120 | H22: 42 | I22: 31.5 | J22: 3.5 | K22: 120h/3 ans. Heures homologuées OEC : 77h/77h = 100%.
B23: Thomas | C23: Renaud | D23: Junior (1 an) | E23: CDI | F23: 1 | G23: 120 | H23: 28 | I23: 17.5 | J23: 3.5 | K23: 120h/3 ans. Heures homologuées OEC : 49h/49h = 100%.
C30: Équipe | K30: Valeur fixe pour les formations collectives (ne pas supprimer)
B31: C. ÉVALUATIONS DES COMPÉTENCES (note 1 à 5) | K31: BARÈME : 1=Découverte (notions théoriques) | 2=Initiation (pratique supervisée) | 3=Pratique courante (autonomie avec contrôle) | 4=Maîtrise (autonomie complète) | 5=Expertise (forme les autres, référent). Évaluation croisée : auto-évaluation collaborateur + validation managériale lors de l'entretien professionnel biennal (art. L6315-1 CT). Méthode : NPMQ 2025 §23 — « évaluation des compétences et besoins en formation ».
B32: Domaine | C32: =IF(SAISIE!C20="","",LEFT(SAISIE!B20,1)&". "&SAISIE!C20) -> M. Dupré | D32: =IF(SAISIE!C21="","",LEFT(SAISIE!B21,1)&". "&SAISIE!C21) -> L. Martin | E32: =IF(SAISIE!C22="","",LEFT(SAISIE!B22,1)&". "&SAISIE!C22) -> M. Lambert | F32: =IF(SAISIE!C23="","",LEFT(SAISIE!B23,1)&". "&SAISIE!C23) -> T. Renaud | G32: Cible | H32: Criticité | I32: Coef. | J32: Urgence | K32: CRITICITÉ : Standard (coef.1) = compétence métier classique | Stratégique (coef.2) = différenciation numérique du cabinet | CRITIQUE (coef.3) = obligation réglementaire ou risque pénal/disciplinaire. URGENCE : 1=amélioration continue (>12 mois) | 2=risque opérationnel identifié (6-12 mois) | 3=échéance réglementaire <6 mois (ex: e-facture sept. 2026, AI literacy fév. 2025). Critères fixés lors de la revue annuelle qualité NPMQ §25.
B33: Comptabilité générale | C33: 4 | D33: 1 | E33: 4 | F33: 2 | G33: 4 | H33: Standard | I33: 1 | J33: 1
B34: TVA & Fiscalité | C34: 4 | D34: 1 | E34: 4 | F34: 2 | G34: 4 | H34: Standard | I34: 1 | J34: 1
B35: Paie & Social | C35: 4 | D35: 1 | E35: 3 | F35: 2 | G35: 3 | H35: Standard | I35: 1 | J35: 1
B36: Comptes annuels | C36: 4 | D36: 1 | E36: 4 | F36: 2 | G36: 4 | H36: Standard | I36: 1 | J36: 1
B37: Révision | C37: 4 | D37: 1 | E37: 4 | F37: 2 | G37: 3 | H37: Standard | I37: 1 | J37: 1
B38: Facture électronique (PA) | C38: 3 | D38: 2 | E38: 2 | F38: 2 | G38: 4 | H38: CRITIQUE | I38: 3 | J38: 3
B39: RGPD & Protection données | C39: 3 | D39: 2 | E39: 2 | F39: 2 | G39: 4 | H39: CRITIQUE | I39: 3 | J39: 2
B40: Cybersécurité | C40: 3 | D40: 2 | E40: 2 | F40: 2 | G40: 4 | H40: CRITIQUE | I40: 3 | J40: 2
B41: LCB-FT / Tracfin | C41: 3 | D41: 2 | E41: 3 | F41: 2 | G41: 4 | H41: CRITIQUE | I41: 3 | J41: 1
B42: Outils SaaS / Cloud | C42: 3 | D42: 3 | E42: 2 | F42: 3 | G42: 3 | H42: Stratégique | I42: 2 | J42: 2
B43: IA & Automatisation | C43: 3 | D43: 2 | E43: 1 | F43: 2 | G43: 4 | H43: CRITIQUE | I43: 3 | J43: 2
B44: Relation client digitale | C44: 4 | D44: 2 | E44: 3 | F44: 2 | G44: 3 | H44: Standard | I44: 1 | J44: 1
... B48: Communication digitale | C48: 3 | D48: 2 | E48: 2 | F48: 2 | G48: 3 | H48: Standard | I48: 1 | J48: 1
B51: D. FORMATIONS RÉALISÉES
B52: Date | C52: Collaborateur (Nom) | D52: Domaine | E52: Intitulé | F52: Organisme | G52: Durée (h) | H52: Coût HT € | I52: Homol. OEC | J52: Art. 22
B53: 2024 (récap.) | C53: Dupré | D53: Multi | E53: LF2024, LCB-FT, Congrès OEC, ANSSI, IFRS (5 formations) | F53: CFPC / CNOEC / Lefebvre Dalloz | G53: 45 | H53: 1490 | I53: Oui | J53: Oui | K53: Formations antérieures justifiées par : attestations OF transmises à l'embauche, historique CPF (moncompteformation.gouv.fr), certificats CFPC/CROEC. Pièces classées en GED cabinet (cf. checklist FICHE QUALITÉ — « Attestations de formation »).
B54: 2024 (récap.) | C54: Lambert | D54: Multi | E54: Compta, TVA intl, Paie, SaaS, LCB-FT, RGPD, Révision IA (7 form.) | F54: CFPC / Lefebvre Dalloz / ENOES | G54: 42 | H54: 2390 | I54: Oui | J54: Oui
...

Sheet DIAGNOSTIC
B2: DIAGNOSTIC AUTOMATIQUE — FORMATION CONTINUE
B3: ⚠️ Cet onglet est 100% automatisé depuis l'onglet SAISIE — Ne rien modifier ici
B5: INDICATEURS CLÉS
B6: Effectif ETP | D6: Conformes | F6: Heures manquantes | H6: Taux hor. complet
B7: =SAISIE!E16 -> 3.8 | D7: =COUNTIF(G13:G22,"✅*")&" / "&COUNTIF(B13:B22,"?*") -> 0 / 4 | F7: =ABS(SUMIF(F13:F22,"<0")) -> 170 | H7: ="≈ "&SAISIE!G16&" €/h" -> ≈ 52 €/h
B10: A. CONFORMITÉ FORMATION CONTINUE (Art. 22 Code de déontologie)
B11: Obligation : 120h/3 ans glissants (≈ 40h/an) — Contrôle qualité OEC
B12: Collaborateur | C12: Grade | D12: Total 3 ans (h) | E12: Objectif (h) | F12: Écart (h) | G12: Statut | H12: Action requise
B13: =IF(SAISIE!C20="","",LEFT(SAISIE!B20,1)&". "&SAISIE!C20) -> M. Dupré | C13: =IF(SAISIE!C20="","",SAISIE!D20) -> Expert-comptable | D13: =IF(SAISIE!C20="","",SAISIE!H20+SAISIE!I20+SAISIE!J20) -> 86.5 | E13: =IF(SAISIE!C20="","",SAISIE!G20) -> 120 | F13: =IF(SAISIE!C20="","",D13-E13) -> -33.5 | G13: =IF(SAISIE!C20="","",IF(F13>=0,"✅ Conforme",IF(F13>=-5,"🟠 Vigilance","🔴 Non conforme"))) -> 🔴 Non conforme | H13: =IF(SAISIE!C20="","",IF(F13>=0,"—","Planifier "&TEXT(ABS(F13),"0.#")&"h avant 31/12/2026")) -> Planifier 3.4h avant 31/12/2026
B14: =IF(SAISIE!C21="","",LEFT(SAISIE!B21,1)&". "&SAISIE!C21) -> L. Martin | C14: =IF(SAISIE!C21="","",SAISIE!D21) -> Apprenti | D14: =IF(SAISIE!C21="","",SAISIE!H21+SAISIE!I21+SAISIE!J21) -> 17.5 | E14: =IF(SAISIE!C21="","",SAISIE!G21) -> 40 | F14: =IF(SAISIE!C21="","",D14-E14) -> -22.5 | G14: =IF(SAISIE!C21="","",IF(F14>=0,"✅ Conforme",IF(F14>=-5,"🟠 Vigilance","🔴 Non conforme"))) -> 🔴 Non conforme | H14: =IF(SAISIE!C21="","",IF(F14>=0,"—","Planifier "&TEXT(ABS(F14),"0.#")&"h avant 31/12/2026")) -> Planifier 2.3h avant 31/12/2026
B15: =IF(SAISIE!C22="","",LEFT(SAISIE!B22,1)&". "&SAISIE!C22) -> M. Lambert | C15: =IF(SAISIE!C22="","",SAISIE!D22) -> Confirmée (5 ans) | D15: =IF(SAISIE!C22="","",SAISIE!H22+SAISIE!I22+SAISIE!J22) -> 77 | E15: =IF(SAISIE!C22="","",SAISIE!G22) -> 120 | F15: =IF(SAISIE!C22="","",D15-E15) -> -43 | G15: =IF(SAISIE!C22="","",IF(F15>=0,"✅ Conforme",IF(F15>=-5,"🟠 Vigilance","🔴 Non conforme"))) -> 🔴 Non conforme | H15: =IF(SAISIE!C22="","",IF(F15>=0,"—","Planifier "&TEXT(ABS(F15),"0.#")&"h avant 31/12/2026")) -> Planifier 4.3h avant 31/12/2026
B16: =IF(SAISIE!C23="","",LEFT(SAISIE!B23,1)&". "&SAISIE!C23) -> T. Renaud | C16: =IF(SAISIE!C23="","",SAISIE!D23) -> Junior (1 an) | D16: =IF(SAISIE!C23="","",SAISIE!H23+SAISIE!I23+SAISIE!J23) -> 49 | E16: =IF(SAISIE!C23="","",SAISIE!G23) -> 120 | F16: =IF(SAISIE!C23="","",D16-E16) -> -71 | G16: =IF(SAISIE!C23="","",IF(F16>=0,"✅ Conforme",IF(F16>=-5,"🟠 Vigilance","🔴 Non conforme"))) -> 🔴 Non conforme | H16: =IF(SAISIE!C23="","",IF(F16>=0,"—","Planifier "&TEXT(ABS(F16),"0.#")&"h avant 31/12/2026")) -> Planifier 7.1h avant 31/12/2026
B17: =IF(SAISIE!C24="","",LEFT(SAISIE!B24,1)&". "&SAISIE!C24) | C17: =IF(SAISIE!C24="","",SAISIE!D24) | D17: =IF(SAISIE!C24="","",SAISIE!H24+SAISIE!I24+SAISIE!J24) | E17: =IF(SAISIE!C24="","",SAISIE!G24) | F17: =IF(SAISIE!C24="","",D17-E17) | G17: =IF(SAISIE!C24="","",IF(F17>=0,"✅ Conforme",IF(F17>=-5,"🟠 Vigilance","🔴 Non conforme"))) | H17: =IF(SAISIE!C24="","",IF(F17>=0,"—","Planifier "&TEXT(ABS(F17),"0.#")&"h avant 31/12/2026"))
B18: =IF(SAISIE!C25="","",LEFT(SAISIE!B25,1)&". "&SAISIE!C25) | C18: =IF(SAISIE!C25="","",SAISIE!D25) | D18: =IF(SAISIE!C25="","",SAISIE!H25+SAISIE!I25+SAISIE!J25) | E18: =IF(SAISIE!C25="","",SAISIE!G25) | F18: =IF(SAISIE!C25="","",D18-E18) | G18: =IF(SAISIE!C25="","",IF(F18>=0,"✅ Conforme",IF(F18>=-5,"🟠 Vigilance","🔴 Non conforme"))) | H18: =IF(SAISIE!C25="","",IF(F18>=0,"—","Planifier "&TEXT(ABS(F18),"0.#")&"h avant 31/12/2026"))
B19: =IF(SAISIE!C26="","",LEFT(SAISIE!B26,1)&". "&SAISIE!C26) | C19: =IF(SAISIE!C26="","",SAISIE!D26) | D19: =IF(SAISIE!C26="","",SAISIE!H26+SAISIE!I26+SAISIE!J26) | E19: =IF(SAISIE!C26="","",SAISIE!G26) | F19: =IF(SAISIE!C26="","",D19-E19) | G19: =IF(SAISIE!C26="","",IF(F19>=0,"✅ Conforme",IF(F19>=-5,"🟠 Vigilance","🔴 Non conforme"))) | H19: =IF(SAISIE!C26="","",IF(F19>=0,"—","Planifier "&TEXT(ABS(F19),"0.#")&"h avant 31/12/2026"))
B20: =IF(SAISIE!C27="","",LEFT(SAISIE!B27,1)&". "&SAISIE!C27) | C20: =IF(SAISIE!C27="","",SAISIE!D27) | D20: =IF(SAISIE!C27="","",SAISIE!H27+SAISIE!I27+SAISIE!J27) | E20: =IF(SAISIE!C27="","",SAISIE!G27) | F20: =IF(SAISIE!C27="","",D20-E20) | G20: =IF(SAISIE!C27="","",IF(F20>=0,"✅ Conforme",IF(F20>=-5,"🟠 Vigilance","🔴 Non conforme"))) | H20: =IF(SAISIE!C27="","",IF(F20>=0,"—","Planifier "&TEXT(ABS(F20),"0.#")&"h avant 31/12/2026"))
B21: =IF(SAISIE!C28="","",LEFT(SAISIE!B28,1)&". "&SAISIE!C28) | C21: =IF(SAISIE!C28="","",SAISIE!D28) | D21: =IF(SAISIE!C28="","",SAISIE!H28+SAISIE!I28+SAISIE!J28) | E21: =IF(SAISIE!C28="","",SAISIE!G28) | F21: =IF(SAISIE!C28="","",D21-E21) | G21: =IF(SAISIE!C28="","",IF(F21>=0,"✅ Conforme",IF(F21>=-5,"🟠 Vigilance","🔴 Non conforme"))) | H21: =IF(SAISIE!C28="","",IF(F21>=0,"—","Planifier "&TEXT(ABS(F21),"0.#")&"h avant 31/12/2026"))
B22: =IF(SAISIE!C29="","",LEFT(SAISIE!B29,1)&". "&SAISIE!C29) | C22: =IF(SAISIE!C29="","",SAISIE!D29) | D22: =IF(SAISIE!C29="","",SAISIE!H29+SAISIE!I29+SAISIE!J29) | E22: =IF(SAISIE!C29="","",SAISIE!G29) | F22: =IF(SAISIE!C29="","",D22-E22) | G22: =IF(SAISIE!C29="","",IF(F22>=0,"✅ Conforme",IF(F22>=-5,"🟠 Vigilance","🔴 Non conforme"))) | H22: =IF(SAISIE!C29="","",IF(F22>=0,"—","Planifier "&TEXT(ABS(F22),"0.#")&"h avant 31/12/2026"))
B23: ⚠️ Le taux de conformité est évalué au point d'arrêté (date de saisie). Le cycle triennal glissant (Art. 22 CD) s'achève au 31/12/2026. La conformité intégrale est conditionnée à l'exécution complète du plan d'action (cf. onglet PLAN D'ACTION, section F).
B25: B. CARTOGRAPHIE DES COMPÉTENCES — ÉCARTS vs CIBLE | J25: Moy. équipe | K25: Cible
B26: Domaine | C26: =IF(SAISIE!C20="","",LEFT(SAISIE!B20,1)&". "&SAISIE!C20) -> M. Dupré | D26: =IF(SAISIE!C21="","",LEFT(SAISIE!B21,1)&". "&SAISIE!C21) -> L. Martin | E26: =IF(SAISIE!C22="","",LEFT(SAISIE!B22,1)&". "&SAISIE!C22) -> M. Lambert | F26: =IF(SAISIE!C23="","",LEFT(SAISIE!B23,1)&". "&SAISIE!C23) -> T. Renaud | G26: Cible | H26: Écart moy. | I26: Score prio.
B27: =SAISIE!B33 -> Comptabilité générale | C27: =SAISIE!C33 -> 4 | D27: =SAISIE!D33 -> 1 | E27: =SAISIE!E33 -> 4 | F27: =SAISIE!F33 -> 2 | G27: =SAISIE!G33 -> 4 | H27: =AVERAGE(C27:F27)-G27 -> -1.25 | I27: =IF(H27>=0,0,SAISIE!I33*ABS(H27)*SAISIE!J33+(16-ROW()+27)/10000) -> 1.2516 | J27: =AVERAGE(C27:F27) -> 2.75 | K27: =G27 -> 4
B28: =SAISIE!B34 -> TVA & Fiscalité | C28: =SAISIE!C34 -> 4 | D28: =SAISIE!D34 -> 1 | E28: =SAISIE!E34 -> 4 | F28: =SAISIE!F34 -> 2 | G28: =SAISIE!G34 -> 4 | H28: =AVERAGE(C28:F28)-G28 -> -1.25 | I28: =IF(H28>=0,0,SAISIE!I34*ABS(H28)*SAISIE!J34+(16-ROW()+27)/10000) -> 1.2515 | J28: =AVERAGE(C28:F28) -> 2.75 | K28: =G28 -> 4
B29: =SAISIE!B35 -> Paie & Social | C29: =SAISIE!C35 -> 4 | D29: =SAISIE!D35 -> 1 | E29: =SAISIE!E35 -> 3 | F29: =SAISIE!F35 -> 2 | G29: =SAISIE!G35 -> 3 | H29: =AVERAGE(C29:F29)-G29 -> -0.5 | I29: =IF(H29>=0,0,SAISIE!I35*ABS(H29)*SAISIE!J35+(16-ROW()+27)/10000) -> 0.5014 | J29: =AVERAGE(C29:F29) -> 2.5 | K29: =G29 -> 3
B30: =SAISIE!B36 -> Comptes annuels | C30: =SAISIE!C36 -> 4 | D30: =SAISIE!D36 -> 1 | E30: =SAISIE!E36 -> 4 | F30: =SAISIE!F36 -> 2 | G30: =SAISIE!G36 -> 4 | H30: =AVERAGE(C30:F30)-G30 -> -1.25 | I30: =IF(H30>=0,0,SAISIE!I36*ABS(H30)*SAISIE!J36+(16-ROW()+27)/10000) -> 1.2513 | J30: =AVERAGE(C30:F30) -> 2.75 | K30: =G30 -> 4
B31: =SAISIE!B37 -> Révision | C31: =SAISIE!C37 -> 4 | D31: =SAISIE!D37 -> 1 | E31: =SAISIE!E37 -> 4 | F31: =SAISIE!F37 -> 2 | G31: =SAISIE!G37 -> 3 | H31: =AVERAGE(C31:F31)-G31 -> -0.25 | I31: =IF(H31>=0,0,SAISIE!I37*ABS(H31)*SAISIE!J37+(16-ROW()+27)/10000) -> 0.2512 | J31: =AVERAGE(C31:F31) -> 2.75 | K31: =G31 -> 3
B32: =SAISIE!B38 -> Facture électronique (PA) | C32: =SAISIE!C38 -> 3 | D32: =SAISIE!D38 -> 2 | E32: =SAISIE!E38 -> 2 | F32: =SAISIE!F38 -> 2 | G32: =SAISIE!G38 -> 4 | H32: =AVERAGE(C32:F32)-G32 -> -1.75 | I32: =IF(H32>=0,0,SAISIE!I38*ABS(H32)*SAISIE!J38+(16-ROW()+27)/10000) -> 15.7511 | J32: =AVERAGE(C32:F32) -> 2.25 | K32: =G32 -> 4
B33: =SAISIE!B39 -> RGPD & Protection données | C33: =SAISIE!C39 -> 3 | D33: =SAISIE!D39 -> 2 | E33: =SAISIE!E39 -> 2 | F33: =SAISIE!F39 -> 2 | G33: =SAISIE!G39 -> 4 | H33: =AVERAGE(C33:F33)-G33 -> -1.75 | I33: =IF(H33>=0,0,SAISIE!I39*ABS(H33)*SAISIE!J39+(16-ROW()+27)/10000) -> 10.501 | J33: =AVERAGE(C33:F33) -> 2.25 | K33: =G33 -> 4
B34: =SAISIE!B40 -> Cybersécurité | C34: =SAISIE!C40 -> 3 | D34: =SAISIE!D40 -> 2 | E34: =SAISIE!E40 -> 2 | F34: =SAISIE!F40 -> 2 | G34: =SAISIE!G40 -> 4 | H34: =AVERAGE(C34:F34)-G34 -> -1.75 | I34: =IF(H34>=0,0,SAISIE!I40*ABS(H34)*SAISIE!J40+(16-ROW()+27)/10000) -> 10.5009 | J34: =AVERAGE(C34:F34) -> 2.25 | K34: =G34 -> 4
B35: =SAISIE!B41 -> LCB-FT / Tracfin | C35: =SAISIE!C41 -> 3 | D35: =SAISIE!D41 -> 2 | E35: =SAISIE!E41 -> 3 | F35: =SAISIE!F41 -> 2 | G35: =SAISIE!G41 -> 4 | H35: =AVERAGE(C35:F35)-G35 -> -1.5 | I35: =IF(H35>=0,0,SAISIE!I41*ABS(H35)*SAISIE!J41+(16-ROW()+27)/10000) -> 4.5008 | J35: =AVERAGE(C35:F35) -> 2.5 | K35: =G35 -> 4
B36: =SAISIE!B42 -> Outils SaaS / Cloud | C36: =SAISIE!C42 -> 3 | D36: =SAISIE!D42 -> 3 | E36: =SAISIE!E42 -> 2 | F36: =SAISIE!F42 -> 3 | G36: =SAISIE!G42 -> 3 | H36: =AVERAGE(C36:F36)-G36 -> -0.25 | I36: =IF(H36>=0,0,SAISIE!I42*ABS(H36)*SAISIE!J42+(16-ROW()+27)/10000) -> 1.0007 | J36: =AVERAGE(C36:F36) -> 2.75 | K36: =G36 -> 3
B37: =SAISIE!B43 -> IA & Automatisation | C37: =SAISIE!C43 -> 3 | D37: =SAISIE!D43 -> 2 | E37: =SAISIE!E43 -> 1 | F37: =SAISIE!F43 -> 2 | G37: =SAISIE!G43 -> 4 | H37: =AVERAGE(C37:F37)-G37 -> -2 | I37: =IF(H37>=0,0,SAISIE!I43*ABS(H37)*SAISIE!J43+(16-ROW()+27)/10000) -> 12.0006 | J37: =AVERAGE(C37:F37) -> 2 | K37: =G37 -> 4
B38: =SAISIE!B44 -> Relation client digitale | C38: =SAISIE!C44 -> 4 | D38: =SAISIE!D44 -> 2 | E38: =SAISIE!E44 -> 3 | F38: =SAISIE!F44 -> 2 | G38: =SAISIE!G44 -> 3 | H38: =AVERAGE(C38:F38)-G38 -> -0.25 | I38: =IF(H38>=0,0,SAISIE!I44*ABS(H38)*SAISIE!J44+(16-ROW()+27)/10000) -> 0.2505 | J38: =AVERAGE(C38:F38) -> 2.75 | K38: =G38 -> 3
... B42: =SAISIE!B48 -> Communication digitale | C42: =SAISIE!C48 -> 3 | D42: =SAISIE!D48 -> 2 | E42: =SAISIE!E48 -> 2 | F42: =SAISIE!F48 -> 2 | G42: =SAISIE!G48 -> 3 | H42: =AVERAGE(C42:F42)-G42 -> -0.75 | I42: =IF(H42>=0,0,SAISIE!I48*ABS(H42)*SAISIE!J48+(16-ROW()+27)/10000) -> 0.7501 | J42: =AVERAGE(C42:F42) -> 2.25 | K42: =G42 -> 3
B45: C. TOP 5 PRIORITÉS FORMATION (scoring = Coef. × |Écart| × Urgence)
B46: Rang | C46: Domaine | D46: Score | E46: Écart moy. | F46: Criticité | G46: Urgence | H46: Niveau
B47: 1 | C47: =IFERROR(INDEX($B$27:$B$42,MATCH(LARGE($I$27:$I$42,1),$I$27:$I$42,0)),"—") -> Facture électronique (PA) | D47: =IFERROR(ROUND(LARGE($I$27:$I$42,1),1),0) -> 15.8 | E47: =IFERROR(INDEX($H$27:$H$42,MATCH(LARGE($I$27:$I$42,1),$I$27:$I$42,0)),0) -> -1.75 | F47: =IFERROR(INDEX(SAISIE!$H$33:$H$48,MATCH(LARGE($I$27:$I$42,1),$I$27:$I$42,0)),"—") -> CRITIQUE | G47: =IFERROR(INDEX(SAISIE!$J$33:$J$48,MATCH(LARGE($I$27:$I$42,1),$I$27:$I$42,0)),0) -> 3 | H47: =IF(D47>=8,"🔴 URGENT",IF(D47>=4,"🟠 HAUTE",IF(D47>0,"🟡 MOYENNE","—"))) -> 🔴 URGENT
B48: 2 | C48: =IFERROR(INDEX($B$27:$B$42,MATCH(LARGE($I$27:$I$42,2),$I$27:$I$42,0)),"—") -> IA & Automatisation | D48: =IFERROR(ROUND(LARGE($I$27:$I$42,2),1),0) -> 12 | E48: =IFERROR(INDEX($H$27:$H$42,MATCH(LARGE($I$27:$I$42,2),$I$27:$I$42,0)),0) -> -2 | F48: =IFERROR(INDEX(SAISIE!$H$33:$H$48,MATCH(LARGE($I$27:$I$42,2),$I$27:$I$42,0)),"—") -> CRITIQUE | G48: =IFERROR(INDEX(SAISIE!$J$33:$J$48,MATCH(LARGE($I$27:$I$42,2),$I$27:$I$42,0)),0) -> 2 | H48: =IF(D48>=8,"🔴 URGENT",IF(D48>=4,"🟠 HAUTE",IF(D48>0,"🟡 MOYENNE","—"))) -> 🔴 URGENT
B49: 3 | C49: =IFERROR(INDEX($B$27:$B$42,MATCH(LARGE($I$27:$I$42,3),$I$27:$I$42,0)),"—") -> RGPD & Protection données | D49: =IFERROR(ROUND(LARGE($I$27:$I$42,3),1),0) -> 10.5 | E49: =IFERROR(INDEX($H$27:$H$42,MATCH(LARGE($I$27:$I$42,3),$I$27:$I$42,0)),0) -> -1.75 | F49: =IFERROR(INDEX(SAISIE!$H$33:$H$48,MATCH(LARGE($I$27:$I$42,3),$I$27:$I$42,0)),"—") -> CRITIQUE | G49: =IFERROR(INDEX(SAISIE!$J$33:$J$48,MATCH(LARGE($I$27:$I$42,3),$I$27:$I$42,0)),0) -> 2 | H49: =IF(D49>=8,"🔴 URGENT",IF(D49>=4,"🟠 HAUTE",IF(D49>0,"🟡 MOYENNE","—"))) -> 🔴 URGENT
B50: 4 | C50: =IFERROR(INDEX($B$27:$B$42,MATCH(LARGE($I$27:$I$42,4),$I$27:$I$42,0)),"—") -> Cybersécurité | D50: =IFERROR(ROUND(LARGE($I$27:$I$42,4),1),0) -> 10.5 | E50: =IFERROR(INDEX($H$27:$H$42,MATCH(LARGE($I$27:$I$42,4),$I$27:$I$42,0)),0) -> -1.75 | F50: =IFERROR(INDEX(SAISIE!$H$33:$H$48,MATCH(LARGE($I$27:$I$42,4),$I$27:$I$42,0)),"—") -> CRITIQUE | G50: =IFERROR(INDEX(SAISIE!$J$33:$J$48,MATCH(LARGE($I$27:$I$42,4),$I$27:$I$42,0)),0) -> 2 | H50: =IF(D50>=8,"🔴 URGENT",IF(D50>=4,"🟠 HAUTE",IF(D50>0,"🟡 MOYENNE","—"))) -> 🔴 URGENT
...

Sheet PLAN D'ACTION
B2: PLAN D'ACTION & BUDGET FORMATION
B3: ⚠️ Cet onglet est 100% automatisé depuis l'onglet SAISIE — Ne rien modifier ici
B5: A. BUDGET FORMATIONS EXTERNES PLANIFIÉES
B6: Formation | C6: Collaborateur | D6: Durée (h) | E6: Coût HT € | F6: Organisme | G6: Domaine | H6: Type | I6: Comble déficit
B7: =IF(SAISIE!B77="","",SAISIE!B77) -> IA dans l'exercice professionnel | C7: =IF(SAISIE!B77="","",SAISIE!C77) -> Lambert | D7: =IF(SAISIE!B77="","",SAISIE!D77) -> 14 | E7: =IF(SAISIE!B77="","",SAISIE!E77) -> 890 | F7: =IF(SAISIE!B77="","",SAISIE!F77) -> CFPC (catalogue 2026) | G7: =IF(SAISIE!B77="","",SAISIE!G77) -> IA | H7: =IF(SAISIE!B77="","",SAISIE!H77) -> Productivité | I7: IA (Lambert -2.0)
B8: =IF(SAISIE!B78="","",SAISIE!B78) -> Cybersécurité des cabinets | C8: =IF(SAISIE!B78="","",SAISIE!C78) -> Lambert | D8: =IF(SAISIE!B78="","",SAISIE!D78) -> 7 | E8: =IF(SAISIE!B78="","",SAISIE!E78) -> 650 | F8: =IF(SAISIE!B78="","",SAISIE!F78) -> ANSSI / Cybermalveillance | G8: =IF(SAISIE!B78="","",SAISIE!G78) -> Cyber | H8: =IF(SAISIE!B78="","",SAISIE!H78) -> Prévention | I8: Cybersécurité (Lambert -1.75)
B9: =IF(SAISIE!B79="","",SAISIE!B79) -> RGPD — Conformité cabinet EC | C9: =IF(SAISIE!B79="","",SAISIE!C79) -> Renaud | D9: =IF(SAISIE!B79="","",SAISIE!D79) -> 7 | E9: =IF(SAISIE!B79="","",SAISIE!E79) -> 1200 | F9: =IF(SAISIE!B79="","",SAISIE!F79) -> Impact RGPD | G9: =IF(SAISIE!B79="","",SAISIE!G79) -> RGPD | H9: =IF(SAISIE!B79="","",SAISIE!H79) -> Conformité | I9: RGPD (Renaud -1.75)
B10: E-facture 2026 — Réforme PA | C10: =IF(SAISIE!B80="","",SAISIE!C80) -> Dupré | D10: =IF(SAISIE!B80="","",SAISIE!D80) -> 14 | E10: =IF(SAISIE!B80="","",SAISIE!E80) -> 890 | F10: =IF(SAISIE!B80="","",SAISIE!F80) -> CFPC (catalogue 2026) | G10: =IF(SAISIE!B80="","",SAISIE!G80) -> E-facture | H10: =IF(SAISIE!B80="","",SAISIE!H80) -> Productivité | I10: E-facture (Dupré -1.75)
B11: =IF(SAISIE!B81="","",SAISIE!B81) -> LCB-FT vigilance annuelle | C11: =IF(SAISIE!B81="","",SAISIE!C81) -> Équipe | D11: =IF(SAISIE!B81="","",SAISIE!D81) -> 3.5 | E11: =IF(SAISIE!B81="","",SAISIE!E81) -> 600 | F11: =IF(SAISIE!B81="","",SAISIE!F81) -> CFPC / CSOEC | G11: =IF(SAISIE!B81="","",SAISIE!G81) -> LCB-FT | H11: =IF(SAISIE!B81="","",SAISIE!H81) -> Conformité | I11: LCB-FT (Équipe -1.5)
B12: =IF(SAISIE!B82="","",SAISIE!B82) -> Déontologie & normes 2026 | C12: =IF(SAISIE!B82="","",SAISIE!C82) -> Dupré | D12: =IF(SAISIE!B82="","",SAISIE!D82) -> 7 | E12: =IF(SAISIE!B82="","",SAISIE!E82) -> 350 | F12: =IF(SAISIE!B82="","",SAISIE!F82) -> CROEC Île-de-France | G12: =IF(SAISIE!B82="","",SAISIE!G82) -> Déontologie | H12: =IF(SAISIE!B82="","",SAISIE!H82) -> Conformité | I12: Déontologie (Dupré -0.75)
B13: =IF(SAISIE!B83="","",SAISIE!B83) -> Signature électronique avancée | C13: =IF(SAISIE!B83="","",SAISIE!C83) -> Renaud | D13: =IF(SAISIE!B83="","",SAISIE!D83) -> 7 | E13: =IF(SAISIE!B83="","",SAISIE!E83) -> 450 | F13: =IF(SAISIE!B83="","",SAISIE!F83) -> Organisme Qualiopi | G13: =IF(SAISIE!B83="","",SAISIE!G83) -> Signature | H13: =IF(SAISIE!B83="","",SAISIE!H83) -> Compétence | I13: Signature élec. (Renaud -1.25)
B14: =IF(SAISIE!B84="","",SAISIE!B84) -> GED & archivage probant | C14: =IF(SAISIE!B84="","",SAISIE!C84) -> Renaud | D14: =IF(SAISIE!B84="","",SAISIE!D84) -> 7 | E14: =IF(SAISIE!B84="","",SAISIE!E84) -> 550 | F14: =IF(SAISIE!B84="","",SAISIE!F84) -> Organisme Qualiopi | G14: =IF(SAISIE!B84="","",SAISIE!G84) -> GED | H14: =IF(SAISIE!B84="","",SAISIE!H84) -> Compétence | I14: GED (Renaud -0.75)
B15: =IF(SAISIE!B85="","",SAISIE!B85) -> Comptabilité avancée — Arrêté et consolidation | C15: =IF(SAISIE!B85="","",SAISIE!C85) -> Renaud | D15: =IF(SAISIE!B85="","",SAISIE!D85) -> 14 | E15: =IF(SAISIE!B85="","",SAISIE!E85) -> 890 | F15: =IF(SAISIE!B85="","",SAISIE!F85) -> CFPC (catalogue 2026) | G15: =IF(SAISIE!B85="","",SAISIE!G85) -> Comptabilité | H15: =IF(SAISIE!B85="","",SAISIE!H85) -> Compétence | I15: Comptabilité (Renaud -1.25)
B16: =IF(SAISIE!B86="","",SAISIE!B86) -> Outils SaaS avancés — Automatisation flux | C16: =IF(SAISIE!B86="","",SAISIE!C86) -> Renaud | D16: =IF(SAISIE!B86="","",SAISIE!D86) -> 7 | E16: =IF(SAISIE!B86="","",SAISIE!E86) -> 0 | F16: =IF(SAISIE!B86="","",SAISIE!F86) -> campusAtlas (100% pris en charge) | G16: =IF(SAISIE!B86="","",SAISIE!G86) -> SaaS | H16: =IF(SAISIE!B86="","",SAISIE!H86) -> Productivité | I16: SaaS (Renaud -0.25)
B17: =IF(SAISIE!B87="","",SAISIE!B87) -> Communication digitale — Relation client | C17: =IF(SAISIE!B87="","",SAISIE!C87) -> Renaud | D17: =IF(SAISIE!B87="","",SAISIE!D87) -> 7 | E17: =IF(SAISIE!B87="","",SAISIE!E87) -> 0 | F17: =IF(SAISIE!B87="","",SAISIE!F87) -> microlearningAtlas | G17: =IF(SAISIE!B87="","",SAISIE!G87) -> Communication | H17: =IF(SAISIE!B87="","",SAISIE!H87) -> Compétence | I17: Communication (Renaud -0.75)
B18: =IF(SAISIE!B88="","",SAISIE!B88) -> Veille réglementaire IA — AI Act application | C18: =IF(SAISIE!B88="","",SAISIE!C88) -> Dupré | D18: =IF(SAISIE!B88="","",SAISIE!D88) -> 7 | E18: =IF(SAISIE!B88="","",SAISIE!E88) -> 0 | F18: =IF(SAISIE!B88="","",SAISIE!F88) -> Webinaire CNOEC (gratuit inscrit) | G18: =IF(SAISIE!B88="","",SAISIE!G88) -> IA | H18: =IF(SAISIE!B88="","",SAISIE!H88) -> Conformité | I18: IA / AI Act (Dupré -2.0)
B19: =IF(SAISIE!B89="","",SAISIE!B89) -> PIX I Atlas — Évaluation compétences numériques | C19: =IF(SAISIE!B89="","",SAISIE!C89) -> Renaud | D19: =IF(SAISIE!B89="","",SAISIE!D89) -> 3.5 | E19: =IF(SAISIE!B89="","",SAISIE!E89) -> 0 | F19: =IF(SAISIE!B89="","",SAISIE!F89) -> PIX I Atlas (100% gratuit, toutes tailles) | G19: =IF(SAISIE!B89="","",SAISIE!G89) -> SaaS | H19: =IF(SAISIE!B89="","",SAISIE!H89) -> Compétence | I19: SaaS / Numérique (Renaud -0.25)
B20: SOUS-TOTAL FORMATIONS EXTERNES | D20: =SUM(D7:D19) -> 105 | E20: =SUM(E7:E19) -> 6470
B22: B. FINANCEMENT OPCO ATLAS (CCN 3020 — Cabinets EC)
B23: Source : opco-atlas.fr/criteres-financement — Critères 2026
B24: Poste | C24: Montant € | E24: Note / Source
B25: Budget formations HT | C25: =E20 -> 6470 | E25: Somme coûts catalogue planifiés
B26: Plafond PDC Atlas (< 11 sal.) | C26: =SAISIE!C13 -> 2800 | E26: opco-atlas.fr — Critères 2026
B27: Plafond DEC/CAC supplémentaire | C27: =SAISIE!C14 -> 1000 | E27: 1 000€/sal/an — 1 salarié en stage DEC (L. Martin)
B28: TOTAL prise en charge OPCO | C28: =C26+C27 -> 3800
B29: Coût net cabinet (HT) | C29: =C25-C28 -> 2670 | E29: Budget – OPCO
B31: C. ÉCONOMIES FORMATIONS INTERNES (AFEST — 7 sessions rationalisées)
B32: AFEST finançable par Atlas : 20€ HT/h dans plafond PDC (Art. L6313-2 CT)
B33: Binôme | C33: Domaine | D33: Durée | E33: Heures compt. | F33: Éco. externe €
B34: =IF(SAISIE!B95="","",SAISIE!B95) -> Martin | C34: =IF(SAISIE!B95="","",SAISIE!C95) -> Lambert | D34: =IF(SAISIE!B95="","",SAISIE!D95) -> IA & Prompting SaaS — Mentorat inversé | E34: =IF(SAISIE!B95="","",SAISIE!E95) -> 14 | F34: =IF(SAISIE!B95="","",SAISIE!F95) -> 890
B35: =IF(SAISIE!B96="","",SAISIE!B96) -> Lambert | C35: =IF(SAISIE!B96="","",SAISIE!C96) -> Martin | D35: =IF(SAISIE!B96="","",SAISIE!D96) -> Révision comptable — Tutorat | E35: =IF(SAISIE!B96="","",SAISIE!E96) -> 14 | F35: =IF(SAISIE!B96="","",SAISIE!F96) -> 980
B36: =IF(SAISIE!B97="","",SAISIE!B97) -> Lambert | C36: =IF(SAISIE!B97="","",SAISIE!C97) -> Renaud | D36: =IF(SAISIE!B97="","",SAISIE!D97) -> Fiscalité appliquée — Cas pratiques | E36: =IF(SAISIE!B97="","",SAISIE!E97) -> 7 | F36: =IF(SAISIE!B97="","",SAISIE!F97) -> 450
B37: =IF(SAISIE!B98="","",SAISIE!B98) -> Lambert | C37: =IF(SAISIE!B98="","",SAISIE!C98) -> Renaud | D37: =IF(SAISIE!B98="","",SAISIE!D98) -> IA appliquée — Prompts comptabilité | E37: =IF(SAISIE!B98="","",SAISIE!E98) -> 7 | F37: =IF(SAISIE!B98="","",SAISIE!F98) -> 890
B38: =IF(SAISIE!B99="","",SAISIE!B99) -> Lambert | C38: =IF(SAISIE!B99="","",SAISIE!C99) -> Dupré | D38: =IF(SAISIE!B99="","",SAISIE!D99) -> Cybersécurité — Bonnes pratiques cabinet | E38: =IF(SAISIE!B99="","",SAISIE!E99) -> 3.5 | F38: =IF(SAISIE!B99="","",SAISIE!F99) -> 325
B39: =IF(SAISIE!B100="","",SAISIE!B100) -> Lambert | C39: =IF(SAISIE!B100="","",SAISIE!C100) -> Martin | D39: =IF(SAISIE!B100="","",SAISIE!D100) -> Cybersécurité — Bonnes pratiques cabinet | E39: =IF(SAISIE!B100="","",SAISIE!E100) -> 3.5 | F39: =IF(SAISIE!B100="","",SAISIE!F100) -> 0
B40: =IF(SAISIE!B101="","",SAISIE!B101) -> Lambert | C40: =IF(SAISIE!B101="","",SAISIE!C101) -> Renaud | D40: =IF(SAISIE!B101="","",SAISIE!D101) -> Cybersécurité — Bonnes pratiques cabinet | E40: =IF(SAISIE!B101="","",SAISIE!E101) -> 3.5 | F40: =IF(SAISIE!B101="","",SAISIE!F101) -> 0
B41: =IF(SAISIE!B102="","",SAISIE!B102) -> Dupré | C41: =IF(SAISIE!B102="","",SAISIE!C102) -> Martin | D41: =IF(SAISIE!B102="","",SAISIE!D102) -> E-facture PA — Cascade post-formation | E41: =IF(SAISIE!B102="","",SAISIE!E102) -> 3.5 | F41: =IF(SAISIE!B102="","",SAISIE!F102) -> 225
B42: =IF(SAISIE!B103="","",SAISIE!B103) -> Dupré | C42: =IF(SAISIE!B103="","",SAISIE!C103) -> Lambert | D42: =IF(SAISIE!B103="","",SAISIE!D103) -> E-facture PA — Cascade post-formation | E42: =IF(SAISIE!B103="","",SAISIE!E103) -> 3.5 | F42: =IF(SAISIE!B103="","",SAISIE!F103) -> 0
B43: =IF(SAISIE!B104="","",SAISIE!B104) -> Dupré | C43: =IF(SAISIE!B104="","",SAISIE!C104) -> Renaud | D43: =IF(SAISIE!B104="","",SAISIE!D104) -> E-facture PA — Cascade post-formation | E43: =IF(SAISIE!B104="","",SAISIE!E104) -> 3.5 | F43: =IF(SAISIE!B104="","",SAISIE!F104) -> 0
B44: =IF(SAISIE!B105="","",SAISIE!B105) -> Dupré | C44: =IF(SAISIE!B105="","",SAISIE!C105) -> Martin | D44: =IF(SAISIE!B105="","",SAISIE!D105) -> Déontologie — Actualités normes 2026 | E44: =IF(SAISIE!B105="","",SAISIE!E105) -> 3.5 | F44: =IF(SAISIE!B105="","",SAISIE!F105) -> 175
...

Sheet FICHE QUALITÉ
B2: FICHE QUALITÉ — FORMATION CONTINUE
B3: Art. 22 Code de déontologie • NPMQ 2025 §21-25 & §44 • À imprimer pour le dossier qualité annuel
B4: ⚠️ 100% automatisé — Ne rien modifier
B6: IDENTIFICATION DU CABINET
B7: Raison sociale | D7: =SAISIE!C8 -> Cabinet X
B8: N° OEC | D8: =SAISIE!C9 -> IDF-XXXXX
B9: Expert-comptable titulaire | D9: =SAISIE!C10 -> M. Dupré
B10: Effectif ETP | D10: =SAISIE!E16 -> 3.8
B11: OPCO de branche | D11: =SAISIE!C12&" (CCN 3020)" -> OPCO Atlas (CCN 3020)
B12: Date de synthèse | D12: =TODAY() -> 46077
B14: CONFORMITÉ FORMATION CONTINUE
B15: Collaborateur | D15: Heures 3 ans | E15: Objectif | F15: Écart | G15: Statut
B16: =DIAGNOSTIC!B13 -> M. Dupré | D16: =IF(DIAGNOSTIC!B13="","",DIAGNOSTIC!D13) -> 86.5 | E16: =IF(DIAGNOSTIC!B13="","",DIAGNOSTIC!E13) -> 120 | F16: =IF(DIAGNOSTIC!B13="","",DIAGNOSTIC!F13) -> -33.5 | G16: =IF(DIAGNOSTIC!B13="","",DIAGNOSTIC!G13) -> 🔴 Non conforme
B17: =DIAGNOSTIC!B14 -> L. Martin | D17: =IF(DIAGNOSTIC!B14="","",DIAGNOSTIC!D14) -> 17.5 | E17: =IF(DIAGNOSTIC!B14="","",DIAGNOSTIC!E14) -> 40 | F17: =IF(DIAGNOSTIC!B14="","",DIAGNOSTIC!F14) -> -22.5 | G17: =IF(DIAGNOSTIC!B14="","",DIAGNOSTIC!G14) -> 🔴 Non conforme
B18: =DIAGNOSTIC!B15 -> M. Lambert | D18: =IF(DIAGNOSTIC!B15="","",DIAGNOSTIC!D15) -> 77 | E18: =IF(DIAGNOSTIC!B15="","",DIAGNOSTIC!E15) -> 120 | F18: =IF(DIAGNOSTIC!B15="","",DIAGNOSTIC!F15) -> -43 | G18: =IF(DIAGNOSTIC!B15="","",DIAGNOSTIC!G15) -> 🔴 Non conforme
B19: =DIAGNOSTIC!B16 -> T. Renaud | D19: =IF(DIAGNOSTIC!B16="","",DIAGNOSTIC!D16) -> 49 | E19: =IF(DIAGNOSTIC!B16="","",DIAGNOSTIC!E16) -> 120 | F19: =IF(DIAGNOSTIC!B16="","",DIAGNOSTIC!F16) -> -71 | G19: =IF(DIAGNOSTIC!B16="","",DIAGNOSTIC!G16) -> 🔴 Non conforme
B20: =DIAGNOSTIC!B17 | D20: =IF(DIAGNOSTIC!B17="","",DIAGNOSTIC!D17) | E20: =IF(DIAGNOSTIC!B17="","",DIAGNOSTIC!E17) | F20: =IF(DIAGNOSTIC!B17="","",DIAGNOSTIC!F17) | G20: =IF(DIAGNOSTIC!B17="","",DIAGNOSTIC!G17)
B21: =DIAGNOSTIC!B18 | D21: =IF(DIAGNOSTIC!B18="","",DIAGNOSTIC!D18) | E21: =IF(DIAGNOSTIC!B18="","",DIAGNOSTIC!E18) | F21: =IF(DIAGNOSTIC!B18="","",DIAGNOSTIC!F18) | G21: =IF(DIAGNOSTIC!B18="","",DIAGNOSTIC!G18)
B22: =DIAGNOSTIC!B19 | D22: =IF(DIAGNOSTIC!B19="","",DIAGNOSTIC!D19) | E22: =IF(DIAGNOSTIC!B19="","",DIAGNOSTIC!E19) | F22: =IF(DIAGNOSTIC!B19="","",DIAGNOSTIC!F19) | G22: =IF(DIAGNOSTIC!B19="","",DIAGNOSTIC!G19)
B23: =DIAGNOSTIC!B20 | D23: =IF(DIAGNOSTIC!B20="","",DIAGNOSTIC!D20) | E23: =IF(DIAGNOSTIC!B20="","",DIAGNOSTIC!E20) | F23: =IF(DIAGNOSTIC!B20="","",DIAGNOSTIC!F20) | G23: =IF(DIAGNOSTIC!B20="","",DIAGNOSTIC!G20)
B24: =DIAGNOSTIC!B21 | D24: =IF(DIAGNOSTIC!B21="","",DIAGNOSTIC!D21) | E24: =IF(DIAGNOSTIC!B21="","",DIAGNOSTIC!E21) | F24: =IF(DIAGNOSTIC!B21="","",DIAGNOSTIC!F21) | G24: =IF(DIAGNOSTIC!B21="","",DIAGNOSTIC!G21)
B25: =DIAGNOSTIC!B22 | D25: =IF(DIAGNOSTIC!B22="","",DIAGNOSTIC!D22) | E25: =IF(DIAGNOSTIC!B22="","",DIAGNOSTIC!E22) | F25: =IF(DIAGNOSTIC!B22="","",DIAGNOSTIC!F22) | G25: =IF(DIAGNOSTIC!B22="","",DIAGNOSTIC!G22)
B27: Taux conformité actuel | D27: =COUNTIF(DIAGNOSTIC!G13:G22,"✅*")&" / "&COUNTIF(DIAGNOSTIC!B13:B22,"?*") -> 0 / 4
B28: Taux conformité après plan d'action | D28: =COUNTIF('PLAN D''ACTION'!H64:H73,"✅*")&" / "&COUNTIF('PLAN D''ACTION'!B64:B73,"?*") -> 4 / 4
B30: BUDGET FORMATION
B31: Budget formations externes HT | D31: ='PLAN D''ACTION'!D47 -> 6470
B32: Prise en charge OPCO Atlas | D32: ='PLAN D''ACTION'!D48 -> -3800
B33: Coût net formations | D33: ='PLAN D''ACTION'!D49 -> 2670
B34: Économies formations internes (AFEST) | D34: ='PLAN D''ACTION'!D50 -> -3935
B35: INVESTISSEMENT NET | D35: ='PLAN D''ACTION'!D51 -> -1265
B38: PIÈCES JUSTIFICATIVES (Checklist contrôle qualité)
B39: ☐ | C39: Attestations de formation (GED cabinet) | F39: Obligatoire — NPMQ §23
B40: ☐ | C40: Émargements formations internes (AFEST) | F40: Obligatoire — Art. L6313-2 CT
B41: ☐ | C41: Justificatifs OPCO Atlas (accords PDC) | F41: Recommandé
B42: ☐ | C42: Planning formations N+1 | F42: Obligatoire — NPMQ §24
B43: ☐ | C43: Attestation LCB-FT annuelle | F43: Obligatoire — Art. L561-32 CMF
B44: ☐ | C44: Procédure formation continue | F44: NPMQ 2025 §21-25
B45: ☐ | C45: Grilles évaluation compétences | F45: Art. 148 Code de déontologie
B46: ☐ | C46: Entretiens professionnels biennaux | F46: Art. L6315-1 Code du travail
B47: ☐ | C47: Sensibilisation AI literacy (art. 4 Règl. UE 2024/1689) | F47: Obligatoire depuis fév. 2025 — Règl. (UE) 2024/1689
...

Sheet _REF
A1: MÉTHODOLOGIE — Documentation technique Annexe 22 (Février 2026)
A3: 1. FONDEMENT RÉGLEMENTAIRE
A4: Art. 22 Code de déontologie (Décret 2012-432 modifié par Décret 2023-388)
A5: Édition janvier 2026 du Code de déontologie (CNOEC)
A6: Obligation : formation continue ≈ 120h/3 ans glissants (≈ 40h/an)
A7: dont ≥ 60h structurées homologuées par les CROEC
A8: NPMQ 2025 §21-25 : compétences collaborateurs, plan de formation, évaluation
A9: Art. 148 Code de déontologie : responsabilité de l'EC sur la compétence de l'équipe
A10: Art. L561-32 CMF : formation LCB-FT annuelle obligatoire
A11: Règl. (UE) 2024/1689 art. 4 : AI literacy — obligation applicable depuis fév. 2025
A13: Prorata pour les collaborateurs en cours de cycle :
A14: Pour un collaborateur entré en cours de période triennale, l'objectif est proratisé.
... A243: ⚠️ Après test, rétablir les valeurs d'origine du Cabinet X (données fictives).
