Workbook

Sheet 0-Saisie
B2: OUTIL 4 — Pilotage de création (saisie unique)
B3: ⚠️ Saisissez UNIQUEMENT dans les cellules JAUNES. Les autres sont calculées automatiquement.
H4: Synthèse (auto)
H5: Tâches terminées | I5: =COUNTIF(D46:D69,"Terminé")
H6: Avancement | I6: =IFERROR(ROUND(COUNTIF(D46:D69,"Terminé")/COUNTA(A46:A69)*100,0)&"%","0%")
H7: Tâches bloquantes | I7: =COUNTIFS(D46:D69,"<>Terminé")
B9: 1) Profil du projet
B10: Paramètre | D10: Valeur (à saisir) | F10: Unité | H10: Commentaire / aide
B11: Nom du porteur de projet | D11: Monsieur X | H11: Repris dans '2-Mon Projet'
B12: Nom du cabinet (NON intégré au mémoire) | D12: Cabinet X Expertise | H12: ⚠️ Interdit sur la page de garde du mémoire
B13: Région d’implantation | D13: Ile-de-France
B14: Type de création | D14: Creation ex-nihilo | H14: Ex-nihilo / Reprise / Association / Fusion
B15: Forme juridique | D15: SASU | H15: SASU, SARL, SELARL…
B16: Capital social prévu | D16: 5000 | F16: EUR
B17: Date création société (M0) | D17: 01/07/2025 | F17: JJ/MM/AAAA
B18: Date début réflexion (M-6) | D18: 01/01/2025 | F18: JJ/MM/AAAA
B19: Date cible 1er client | D19: 01/08/2025 | F19: JJ/MM/AAAA
B20: Niveau numérique cible | D20: Avance (100% numerique) | H20: Basique / Intermédiaire / Avancé
B21: Votre expérience outils | D21: Confirme | H21: Débutant / Confirmé / Expert
B22: Logiciel comptable cible | D22: Pennylane
B24: 2) Ressources humaines & objectifs commerciaux
B25: Paramètre | D25: Valeur (à saisir) | F25: Unité | H25: Commentaire / aide
B26: Objectif collaborateurs à 12 mois | D26: 1 | H26: 0 = mode solo
B27: Mois démarrage recrutement (M+) | D27: 6 | H27: Ex : 6 = M+6
B28: Profil recherché | D28: Collaborateur junior
B29: Budget recrutement (marque employeur) | D29: 800 | F29: EUR | H29: LinkedIn / jobboards / cabinet de chasse
B30: Objectif clients M+3 | D30: 3
B31: Objectif clients M+6 | D31: 8
B32: Objectif clients M+12 | D32: 15
B33: Honoraire moyen cible (€/an) | D33: 3000 | F33: EUR/an
B34: Spécialisation | D34: Startups / TPE innovantes
B36: 3) Budget & financement
B37: Paramètre | D37: Valeur (à saisir) | F37: Unité | H37: Commentaire / aide
B38: Apport personnel | D38: 30000 | F38: EUR
B39: Emprunt prévu | D39: 20000 | F39: EUR
B40: Charges fixes mensuelles | D40: 3000 | F40: EUR/mois | H40: Loyer, assurances, outils…
B41: Trésorerie de sécurité (mois) | D41: 6 | F41: mois | H41: Minimum recommandé : 6
B44: 4) Suivi — statut des tâches (saisie = colonne Statut)
B45: ID | C45: Tâche | E45: Statut | H45: Commentaire
B46: 0.1 | C46: Autodiagnostic maturité | E46: A faire
...

Sheet 1-Mode emploi
B2: ANNEXE 4 - DIAGRAMME DE GANTT INTERACTIF
B3: Outil de pilotage strategique pour la creation d'un cabinet d'expertise comptable 100% numerique
B5: 1. OBJECTIF DE CET OUTIL
B7: Cet outil n'est PAS un simple planning. C'est un OUTIL D'ARBITRAGE du dirigeant-expert-comptable qui permet de :
B9: PILOTER : Visualiser ou vous en etes dans votre projet de creation
B10: DECIDER : Savoir quoi faire MAINTENANT et quoi EVITER
B11: SECURISER : Identifier les risques majeurs par periode
B12: ARBITRER : Conditionner les decisions RH/SI aux seuils financiers
B14: Le Gantt est pilote par l'economie : le passage d'une periode a l'autre depend de criteres financiers, pas de dates.
B16: 2. COMMENT UTILISER CET OUTIL (5 ETAPES)
B18: ETAPE 1 : Remplissez l'onglet '2-Mon Projet' avec VOS donnees personnelles
B19: -> Toutes les cellules JAUNES doivent etre completees
... B52: Ce fichier utilise une palette de couleurs standardisée :
C54: Jaune vif | D54: → SAISIE UTILISATEUR : Cellules à remplir manuellement
C55: Bleu clair | D55: → CALCULS AUTOMATIQUES : Ne pas modifier
C56: Vert clair | D56: → CONDITIONS / VALIDATIONS : Points de passage
C57: Gris clair | D57: → STRUCTURE : Lignes de phase et en-têtes
C58: Bleu foncé | D58: → TITRES PRINCIPAUX : En-têtes de colonnes
C59: Rouge clair | D59: → ALERTES : Points d'attention majeurs
C60: Jaune pâle | D60: → STATUT EN ATTENTE : Tâches à réaliser
C61: Rouge vif | D61: → CHEMIN CRITIQUE : Aucun retard toléré
B64: 5. COULEURS DES PHASES (Gantt)
C66: Phase 0 | D66: Préparation
C67: Phase 1 | D67: Administratif
C68: Phase 2 | D68: SI & Conformité
C69: Phase 3 | D69: Lancement
C70: Phase 4 | D70: Industrialisation
C71: Phase 5 | D71: Structuration
C72: Phase 6 | D72: Conformité continue
B80: Cybersecurite : Sauvegardes, antivirus, MFA (obligation de moyens)
B81: Facturation élec. : 01/09/2026 réception obligatoire (toutes entreprises) ; 01/09/2026 émission GE/ETI ; 01/09/2027 émission PME/micro
B82: Assurance RCP : Obligatoire pour exercer
B83: AI Act (UE 2024/1689): AI literacy applicable 02/02/2025 ; applicabilité générale 02/08/2026 (selon calendrier UE)
B84: CONCLUSION
B85: Le diagramme de Gantt n'est pas un planning fige mais un OUTIL DE PILOTAGE STRATEGIQUE,
B86: permettant d'arbitrer les decisions de creation du cabinet en fonction des periodes
B87: et des contraintes financieres, organisationnelles et humaines.

Sheet 2-Mon Projet
B2: MON PROJET DE CREATION DE CABINET
B3: Remplissez TOUTES les cellules JAUNES. Ces donnees pilotent l'ensemble de l'outil.
B4: ⚠️ Saisie uniquement dans l’onglet '0-Saisie' (cellules jaunes).
B5: 1. IDENTITE DU PROJET
B6: Nom du porteur de projet | D6: ='0-Saisie'!D11
B7: Nom du cabinet | D7: ='0-Saisie'!D12
B8: Region d'implantation | D8: ='0-Saisie'!D13
B10: 2. TYPE DE CREATION
B11: Type de creation | D11: ='0-Saisie'!D14 | G11: Impact: duree projet
B12: Forme juridique | D12: ='0-Saisie'!D15
B13: Capital social prevu | D13: ='0-Saisie'!D16
B15: 3. CALENDRIER
B16: Date creation societe (M0) | D16: ='0-Saisie'!D17
B17: Date debut reflexion (M-6) | D17: ='0-Saisie'!D18
B18: Date cible 1er client | D18: ='0-Saisie'!D19
B20: 4. AMBITION NUMERIQUE
B21: Niveau numerique cible | D21: ='0-Saisie'!D20 | G21: Impact: duree Phase SI
B22: Votre experience outils | D22: ='0-Saisie'!D21 | G22: Impact: toutes durees
B23: Logiciel comptable cible | D23: ='0-Saisie'!D22
B25: 5. RESSOURCES HUMAINES
B26: Objectif collaborateurs 12 mois | D26: ='0-Saisie'!D26 | G26: 0 = Mode solo
B27: Mois demarrage recrutement | D27: ='0-Saisie'!D27 | G27: Ex: 6 = M+6
B28: Profil recherche | D28: ='0-Saisie'!D28
B29: Budget Recrutement (Marque Employeur) | D29: ='0-Saisie'!D29 | E29: EUR | G29: Prévoir LinkedIn / jobboards
B30: 6. OBJECTIFS COMMERCIAUX
B31: Objectif clients M+3 | D31: ='0-Saisie'!D30
B32: Objectif clients M+6 | D32: ='0-Saisie'!D31
B33: Objectif clients M+12 | D33: ='0-Saisie'!D32
B34: Honoraire moyen cible (EUR/an) | D34: ='0-Saisie'!D33
B35: Specialisation | D35: ='0-Saisie'!D34
B37: 7. BUDGET & FINANCEMENT
B38: Apport personnel | D38: ='0-Saisie'!D38
B39: Emprunt prevu | D39: ='0-Saisie'!D39
B40: Charges fixes mensuelles | D40: ='0-Saisie'!D40 | G40: Loyer, assurances, outils...
B41: Tresorerie securite (mois) | D41: ='0-Saisie'!D41 | G41: Minimum recommande: 6 mois
B42: Coût réel collaborateur DCG/an (minima 2026) | D42: =ROUND(26548*1.45,0) | E42: EUR | F42: Accord n°48 (15/12/2025) : +2,9% → Salaire min. 26 548 € | G42: À intégrer dans trésorerie de sécurité | H42: Source: Accord n°48 IDCC 787 (15/12/2025), +2,9%
B43: 8. PARAMETRES CALCULES (automatique)
B44: Coef. duree (type creation) | D44: =IF(D11="Creation ex-nihilo",1,IF(D11="Reprise cabinet",0.7,0.85)) | G44: ex-nihilo=1 / reprise=0.7
B45: Coef. duree (experience) | D45: =IF(D22="Debutant",1.3,IF(D22="Intermediaire",1.15,IF(D22="Confirme",1,0.9))) | G45: debutant=1.3 / expert=0.9
B46: Coef. SI (niveau numerique) | D46: =IF(D21="Basique",0.7,IF(D21="Intermediaire",1,1.3)) | G46: basique=0.7 / avance=1.3
...

Sheet 3-Periodes
A1: PÉRIODES DE DÉCISION — Jalons et Conditions de Passage
A2: Chaque période a ses objectifs et ses conditions de passage. Le non-respect d'une condition bloque le passage à la période suivante.
A4: 🔵 PÉRIODE 1 : AVANT M0 — Préparation
A5: Statut | B5: =IF(COUNTIF('0-Saisie'!D46:D50,"Terminé")=5,"✅ GO","⏳ EN COURS")
A6: Objectif principal | B6: Valider la faisabilité du projet et préparer tous les pré-requis
A7: CA cible | B7: 0 € (pas d'activité)
A8: Trésorerie mini | B8: ='2-Mon Projet'!D49&" € ("&'2-Mon Projet'!D41&" mois de charges)"
A9: Charge dominante | B9: Réflexion stratégique (80%) + Administratif (20%)
A10: Décision RH | B10: ❌ INTERDIT — Aucun recrutement avant l'inscription à l'Ordre
A11: Risque majeur | B11: Sous-estimation des délais administratifs (Ordre = 6 semaines)
A12: Erreur à éviter | B12: Commander les outils avant validation de l'architecture SI
A13: Action prioritaire | B13: Valider architecture SI + Déposer dossier Ordre
A14: Condition passage M0 | B14: Inscription Ordre OBTENUE + Assurance RCP active + RGPD OK
A16: 🟢 PÉRIODE 2 : M0 → M+3 — Lancement
A17: Statut | B17: =IF('0-Saisie'!D60="Terminé","✅ GO","⏳ EN COURS")
A18: Objectif principal | B18: ='2-Mon Projet'!D31&" premiers clients + process onboarding stabilisé"
A19: CA cible mensuel | B19: Faible / instable (construction portefeuille)
A20: Trésorerie mini | B20: ≥ 3 mois de charges fixes
A21: Charge dominante | B21: Production (40%) + Commercial (40%) + Onboarding (20%)
A22: Décision RH | B22: ❌ INTERDIT — Recruter = absorber le stress au détriment de la qualité
A23: Risque majeur | B23: Surcharge dirigeant → qualité dégradée
A24: Erreur à éviter | B24: Recruter trop tôt / Accepter n'importe quel client
A25: Action prioritaire | B25: Standardiser process onboarding + qualifier les prospects
A26: Condition passage M+3 | B26: Clients signés + Trésorerie OK + Process onboarding opérationnel + PA connectée
A28: 🟠 PÉRIODE 3 : M+3 → M+6 — Industrialisation
A29: Statut | B29: =IF('2-Mon Projet'!D26=0,"✅ GO (solo)","⏳ À ÉVALUER")
A30: Objectif principal | B30: ='2-Mon Projet'!D32&" clients + industrialisation production"
A31: CA cible mensuel | B31: Stabilisation (régularité des entrées)
A32: Trésorerie mini | B32: ≥ 4 mois de charges fixes
A33: Charge dominante | B33: Production (60%) + Développement (30%) + Admin (10%)
A34: Décision RH | B34: =IF('2-Mon Projet'!D26=0,"Non applicable (solo)","⚠️ Préparer si objectif > 0")
A35: Risque majeur | B35: Désorganisation / Qualité si croissance trop rapide
A36: Erreur à éviter | B36: Changer d'outil en pleine montée en charge
A37: Action prioritaire | B37: Industrialiser la production (process, templates, contrôles)
A38: Condition passage M+6 | B38: Marge positive + PA (ex-PDP) connectée et opérationnelle + Tests réception factures OK
A40: 🟣 PÉRIODE 4 : M+6 → M+12 — Structuration
A41: Statut | B41: =IF('2-Mon Projet'!D26=0,"✅ Solo pérenne","⏳ À ÉVALUER")
A42: Objectif principal | B42: ='2-Mon Projet'!D33&" clients + structuration (RH si applicable)"
A43: CA cible mensuel | B43: =ROUND('2-Mon Projet'!D50/12,0)&" €/mois"
A44: Trésorerie mini | B44: ≥ 6 mois de charges (incluant salaire si recrutement)
...

Sheet 4-Gantt
A1: DIAGRAMME DE GANTT - Planning interactif
A2: Type: | B2: ='2-Mon Projet'!D11 | D2: Duree: | E2: ='2-Mon Projet'!D51&" mois" | G2: RH: | H2: ='2-Mon Projet'!D47
A4: ID | B4: Phase | C4: Tache | D4: Sem. | E4: Deb | F4: Fin | G4: Crit | H4: M-6 | I4: M-5 | J4: M-4 | K4: M-3 | L4: M-2 | M4: M-1 | N4: M0 | O4: M+1 | P4: M+2 | Q4: M+3 | R4: M+4 | S4: M+5 | T4: M+6 | U4: M+7 | V4: M+8 | W4: M+9 | X4: M+10 | Y4: M+11 | Z4: M+12
B5: PHASE 0 | C5: PREPARATION
A6: 0.1 | B6: Phase 0 | C6: Autodiagnostic | D6: =ROUND(2*'2-Mon Projet'!$D$45,0) | E6: -6 | F6: =IF(OR($D6="-",$D6=""),"",$E6+ROUND($D6/4,0)) | G6: OUI | H6: =IF(OR($D6="-",$D6=""),"",IF(AND(-6>=$E6,-6<=$F6),1,"")) | I6: =IF(OR($D6="-",$D6=""),"",IF(AND(-5>=$E6,-5<=$F6),1,"")) | J6: =IF(OR($D6="-",$D6=""),"",IF(AND(-4>=$E6,-4<=$F6),1,"")) | K6: =IF(OR($D6="-",$D6=""),"",IF(AND(-3>=$E6,-3<=$F6),1,"")) | L6: =IF(OR($D6="-",$D6=""),"",IF(AND(-2>=$E6,-2<=$F6),1,"")) | M6: =IF(OR($D6="-",$D6=""),"",IF(AND(-1>=$E6,-1<=$F6),1,"")) | N6: =IF(OR($D6="-",$D6=""),"",IF(AND(0>=$E6,0<=$F6),1,"")) | O6: =IF(OR($D6="-",$D6=""),"",IF(AND(1>=$E6,1<=$F6),1,"")) | P6: =IF(OR($D6="-",$D6=""),"",IF(AND(2>=$E6,2<=$F6),1,"")) | Q6: =IF(OR($D6="-",$D6=""),"",IF(AND(3>=$E6,3<=$F6),1,"")) | R6: =IF(OR($D6="-",$D6=""),"",IF(AND(4>=$E6,4<=$F6),1,"")) | S6: =IF(OR($D6="-",$D6=""),"",IF(AND(5>=$E6,5<=$F6),1,"")) | T6: =IF(OR($D6="-",$D6=""),"",IF(AND(6>=$E6,6<=$F6),1,"")) | U6: =IF(OR($D6="-",$D6=""),"",IF(AND(7>=$E6,7<=$F6),1,"")) | V6: =IF(OR($D6="-",$D6=""),"",IF(AND(8>=$E6,8<=$F6),1,"")) | W6: =IF(OR($D6="-",$D6=""),"",IF(AND(9>=$E6,9<=$F6),1,"")) | X6: =IF(OR($D6="-",$D6=""),"",IF(AND(10>=$E6,10<=$F6),1,"")) | Y6: =IF(OR($D6="-",$D6=""),"",IF(AND(11>=$E6,11<=$F6),1,"")) | Z6: =IF(OR($D6="-",$D6=""),"",IF(AND(12>=$E6,12<=$F6),1,""))
A7: 0.2 | B7: Phase 0 | C7: Etude marché | D7: =ROUND(3*'2-Mon Projet'!$D$44*'2-Mon Projet'!$D$45,0) | E7: -5 | F7: =IF(OR($D7="-",$D7=""),"",$E7+ROUND($D7/4,0)) | G7: Non | H7: =IF(OR($D7="-",$D7=""),"",IF(AND(-6>=$E7,-6<=$F7),1,"")) | I7: =IF(OR($D7="-",$D7=""),"",IF(AND(-5>=$E7,-5<=$F7),1,"")) | J7: =IF(OR($D7="-",$D7=""),"",IF(AND(-4>=$E7,-4<=$F7),1,"")) | K7: =IF(OR($D7="-",$D7=""),"",IF(AND(-3>=$E7,-3<=$F7),1,"")) | L7: =IF(OR($D7="-",$D7=""),"",IF(AND(-2>=$E7,-2<=$F7),1,"")) | M7: =IF(OR($D7="-",$D7=""),"",IF(AND(-1>=$E7,-1<=$F7),1,"")) | N7: =IF(OR($D7="-",$D7=""),"",IF(AND(0>=$E7,0<=$F7),1,"")) | O7: =IF(OR($D7="-",$D7=""),"",IF(AND(1>=$E7,1<=$F7),1,"")) | P7: =IF(OR($D7="-",$D7=""),"",IF(AND(2>=$E7,2<=$F7),1,"")) | Q7: =IF(OR($D7="-",$D7=""),"",IF(AND(3>=$E7,3<=$F7),1,"")) | R7: =IF(OR($D7="-",$D7=""),"",IF(AND(4>=$E7,4<=$F7),1,"")) | S7: =IF(OR($D7="-",$D7=""),"",IF(AND(5>=$E7,5<=$F7),1,"")) | T7: =IF(OR($D7="-",$D7=""),"",IF(AND(6>=$E7,6<=$F7),1,"")) | U7: =IF(OR($D7="-",$D7=""),"",IF(AND(7>=$E7,7<=$F7),1,"")) | V7: =IF(OR($D7="-",$D7=""),"",IF(AND(8>=$E7,8<=$F7),1,"")) | W7: =IF(OR($D7="-",$D7=""),"",IF(AND(9>=$E7,9<=$F7),1,"")) | X7: =IF(OR($D7="-",$D7=""),"",IF(AND(10>=$E7,10<=$F7),1,"")) | Y7: =IF(OR($D7="-",$D7=""),"",IF(AND(11>=$E7,11<=$F7),1,"")) | Z7: =IF(OR($D7="-",$D7=""),"",IF(AND(12>=$E7,12<=$F7),1,""))
A8: 0.3 | B8: Phase 0 | C8: SWOT+BMC | D8: =ROUND(4*'2-Mon Projet'!$D$45,0) | E8: -4 | F8: =IF(OR($D8="-",$D8=""),"",$E8+ROUND($D8/4,0)) | G8: Non | H8: =IF(OR($D8="-",$D8=""),"",IF(AND(-6>=$E8,-6<=$F8),1,"")) | I8: =IF(OR($D8="-",$D8=""),"",IF(AND(-5>=$E8,-5<=$F8),1,"")) | J8: =IF(OR($D8="-",$D8=""),"",IF(AND(-4>=$E8,-4<=$F8),1,"")) | K8: =IF(OR($D8="-",$D8=""),"",IF(AND(-3>=$E8,-3<=$F8),1,"")) | L8: =IF(OR($D8="-",$D8=""),"",IF(AND(-2>=$E8,-2<=$F8),1,"")) | M8: =IF(OR($D8="-",$D8=""),"",IF(AND(-1>=$E8,-1<=$F8),1,"")) | N8: =IF(OR($D8="-",$D8=""),"",IF(AND(0>=$E8,0<=$F8),1,"")) | O8: =IF(OR($D8="-",$D8=""),"",IF(AND(1>=$E8,1<=$F8),1,"")) | P8: =IF(OR($D8="-",$D8=""),"",IF(AND(2>=$E8,2<=$F8),1,"")) | Q8: =IF(OR($D8="-",$D8=""),"",IF(AND(3>=$E8,3<=$F8),1,"")) | R8: =IF(OR($D8="-",$D8=""),"",IF(AND(4>=$E8,4<=$F8),1,"")) | S8: =IF(OR($D8="-",$D8=""),"",IF(AND(5>=$E8,5<=$F8),1,"")) | T8: =IF(OR($D8="-",$D8=""),"",IF(AND(6>=$E8,6<=$F8),1,"")) | U8: =IF(OR($D8="-",$D8=""),"",IF(AND(7>=$E8,7<=$F8),1,"")) | V8: =IF(OR($D8="-",$D8=""),"",IF(AND(8>=$E8,8<=$F8),1,"")) | W8: =IF(OR($D8="-",$D8=""),"",IF(AND(9>=$E8,9<=$F8),1,"")) | X8: =IF(OR($D8="-",$D8=""),"",IF(AND(10>=$E8,10<=$F8),1,"")) | Y8: =IF(OR($D8="-",$D8=""),"",IF(AND(11>=$E8,11<=$F8),1,"")) | Z8: =IF(OR($D8="-",$D8=""),"",IF(AND(12>=$E8,12<=$F8),1,""))
A9: 0.4 | B9: Phase 0 | C9: Prévisionnel | D9: =ROUND(3*'2-Mon Projet'!$D$45,0) | E9: -3 | F9: =IF(OR($D9="-",$D9=""),"",$E9+ROUND($D9/4,0)) | G9: Non | H9: =IF(OR($D9="-",$D9=""),"",IF(AND(-6>=$E9,-6<=$F9),1,"")) | I9: =IF(OR($D9="-",$D9=""),"",IF(AND(-5>=$E9,-5<=$F9),1,"")) | J9: =IF(OR($D9="-",$D9=""),"",IF(AND(-4>=$E9,-4<=$F9),1,"")) | K9: =IF(OR($D9="-",$D9=""),"",IF(AND(-3>=$E9,-3<=$F9),1,"")) | L9: =IF(OR($D9="-",$D9=""),"",IF(AND(-2>=$E9,-2<=$F9),1,"")) | M9: =IF(OR($D9="-",$D9=""),"",IF(AND(-1>=$E9,-1<=$F9),1,"")) | N9: =IF(OR($D9="-",$D9=""),"",IF(AND(0>=$E9,0<=$F9),1,"")) | O9: =IF(OR($D9="-",$D9=""),"",IF(AND(1>=$E9,1<=$F9),1,"")) | P9: =IF(OR($D9="-",$D9=""),"",IF(AND(2>=$E9,2<=$F9),1,"")) | Q9: =IF(OR($D9="-",$D9=""),"",IF(AND(3>=$E9,3<=$F9),1,"")) | R9: =IF(OR($D9="-",$D9=""),"",IF(AND(4>=$E9,4<=$F9),1,"")) | S9: =IF(OR($D9="-",$D9=""),"",IF(AND(5>=$E9,5<=$F9),1,"")) | T9: =IF(OR($D9="-",$D9=""),"",IF(AND(6>=$E9,6<=$F9),1,"")) | U9: =IF(OR($D9="-",$D9=""),"",IF(AND(7>=$E9,7<=$F9),1,"")) | V9: =IF(OR($D9="-",$D9=""),"",IF(AND(8>=$E9,8<=$F9),1,"")) | W9: =IF(OR($D9="-",$D9=""),"",IF(AND(9>=$E9,9<=$F9),1,"")) | X9: =IF(OR($D9="-",$D9=""),"",IF(AND(10>=$E9,10<=$F9),1,"")) | Y9: =IF(OR($D9="-",$D9=""),"",IF(AND(11>=$E9,11<=$F9),1,"")) | Z9: =IF(OR($D9="-",$D9=""),"",IF(AND(12>=$E9,12<=$F9),1,""))
A10: 0.5 | B10: Phase 0 | C10: Archi SI | D10: =ROUND(2*'2-Mon Projet'!$D$46,0) | E10: -3 | F10: =IF(OR($D10="-",$D10=""),"",$E10+ROUND($D10/4,0)) | G10: Non | H10: =IF(OR($D10="-",$D10=""),"",IF(AND(-6>=$E10,-6<=$F10),1,"")) | I10: =IF(OR($D10="-",$D10=""),"",IF(AND(-5>=$E10,-5<=$F10),1,"")) | J10: =IF(OR($D10="-",$D10=""),"",IF(AND(-4>=$E10,-4<=$F10),1,"")) | K10: =IF(OR($D10="-",$D10=""),"",IF(AND(-3>=$E10,-3<=$F10),1,"")) | L10: =IF(OR($D10="-",$D10=""),"",IF(AND(-2>=$E10,-2<=$F10),1,"")) | M10: =IF(OR($D10="-",$D10=""),"",IF(AND(-1>=$E10,-1<=$F10),1,"")) | N10: =IF(OR($D10="-",$D10=""),"",IF(AND(0>=$E10,0<=$F10),1,"")) | O10: =IF(OR($D10="-",$D10=""),"",IF(AND(1>=$E10,1<=$F10),1,"")) | P10: =IF(OR($D10="-",$D10=""),"",IF(AND(2>=$E10,2<=$F10),1,"")) | Q10: =IF(OR($D10="-",$D10=""),"",IF(AND(3>=$E10,3<=$F10),1,"")) | R10: =IF(OR($D10="-",$D10=""),"",IF(AND(4>=$E10,4<=$F10),1,"")) | S10: =IF(OR($D10="-",$D10=""),"",IF(AND(5>=$E10,5<=$F10),1,"")) | T10: =IF(OR($D10="-",$D10=""),"",IF(AND(6>=$E10,6<=$F10),1,"")) | U10: =IF(OR($D10="-",$D10=""),"",IF(AND(7>=$E10,7<=$F10),1,"")) | V10: =IF(OR($D10="-",$D10=""),"",IF(AND(8>=$E10,8<=$F10),1,"")) | W10: =IF(OR($D10="-",$D10=""),"",IF(AND(9>=$E10,9<=$F10),1,"")) | X10: =IF(OR($D10="-",$D10=""),"",IF(AND(10>=$E10,10<=$F10),1,"")) | Y10: =IF(OR($D10="-",$D10=""),"",IF(AND(11>=$E10,11<=$F10),1,"")) | Z10: =IF(OR($D10="-",$D10=""),"",IF(AND(12>=$E10,12<=$F10),1,""))
A11: 0.6 | B11: Phase 0 | C11: Formation IA & Data | D11: =2 | E11: -4 | F11: =IF(OR($D11="-",$D11=""),"",$E11+ROUND($D11/4,0)) | G11: OUI | H11: =IF(OR($D11="-",$D11=""),"",IF(AND(-6>=$E11,-6<=$F11),1,"")) | I11: =IF(OR($D11="-",$D11=""),"",IF(AND(-5>=$E11,-5<=$F11),1,"")) | J11: =IF(OR($D11="-",$D11=""),"",IF(AND(-4>=$E11,-4<=$F11),1,"")) | K11: =IF(OR($D11="-",$D11=""),"",IF(AND(-3>=$E11,-3<=$F11),1,"")) | L11: =IF(OR($D11="-",$D11=""),"",IF(AND(-2>=$E11,-2<=$F11),1,"")) | M11: =IF(OR($D11="-",$D11=""),"",IF(AND(-1>=$E11,-1<=$F11),1,"")) | N11: =IF(OR($D11="-",$D11=""),"",IF(AND(0>=$E11,0<=$F11),1,"")) | O11: =IF(OR($D11="-",$D11=""),"",IF(AND(1>=$E11,1<=$F11),1,"")) | P11: =IF(OR($D11="-",$D11=""),"",IF(AND(2>=$E11,2<=$F11),1,"")) | Q11: =IF(OR($D11="-",$D11=""),"",IF(AND(3>=$E11,3<=$F11),1,"")) | R11: =IF(OR($D11="-",$D11=""),"",IF(AND(4>=$E11,4<=$F11),1,"")) | S11: =IF(OR($D11="-",$D11=""),"",IF(AND(5>=$E11,5<=$F11),1,"")) | T11: =IF(OR($D11="-",$D11=""),"",IF(AND(6>=$E11,6<=$F11),1,"")) | U11: =IF(OR($D11="-",$D11=""),"",IF(AND(7>=$E11,7<=$F11),1,"")) | V11: =IF(OR($D11="-",$D11=""),"",IF(AND(8>=$E11,8<=$F11),1,"")) | W11: =IF(OR($D11="-",$D11=""),"",IF(AND(9>=$E11,9<=$F11),1,"")) | X11: =IF(OR($D11="-",$D11=""),"",IF(AND(10>=$E11,10<=$F11),1,"")) | Y11: =IF(OR($D11="-",$D11=""),"",IF(AND(11>=$E11,11<=$F11),1,"")) | Z11: =IF(OR($D11="-",$D11=""),"",IF(AND(12>=$E11,12<=$F11),1,""))
B12: PHASE 1 | C12: ADMINISTRATIF
A13: 1.1 | B13: Phase 1 | C13: Statuts+Immat | D13: =ROUND(4*'2-Mon Projet'!$D$44,0) | E13: -2 | F13: =IF(OR($D13="-",$D13=""),"",$E13+ROUND($D13/4,0)) | G13: OUI | H13: =IF(OR($D13="-",$D13=""),"",IF(AND(-6>=$E13,-6<=$F13),1,"")) | I13: =IF(OR($D13="-",$D13=""),"",IF(AND(-5>=$E13,-5<=$F13),1,"")) | J13: =IF(OR($D13="-",$D13=""),"",IF(AND(-4>=$E13,-4<=$F13),1,"")) | K13: =IF(OR($D13="-",$D13=""),"",IF(AND(-3>=$E13,-3<=$F13),1,"")) | L13: =IF(OR($D13="-",$D13=""),"",IF(AND(-2>=$E13,-2<=$F13),1,"")) | M13: =IF(OR($D13="-",$D13=""),"",IF(AND(-1>=$E13,-1<=$F13),1,"")) | N13: =IF(OR($D13="-",$D13=""),"",IF(AND(0>=$E13,0<=$F13),1,"")) | O13: =IF(OR($D13="-",$D13=""),"",IF(AND(1>=$E13,1<=$F13),1,"")) | P13: =IF(OR($D13="-",$D13=""),"",IF(AND(2>=$E13,2<=$F13),1,"")) | Q13: =IF(OR($D13="-",$D13=""),"",IF(AND(3>=$E13,3<=$F13),1,"")) | R13: =IF(OR($D13="-",$D13=""),"",IF(AND(4>=$E13,4<=$F13),1,"")) | S13: =IF(OR($D13="-",$D13=""),"",IF(AND(5>=$E13,5<=$F13),1,"")) | T13: =IF(OR($D13="-",$D13=""),"",IF(AND(6>=$E13,6<=$F13),1,"")) | U13: =IF(OR($D13="-",$D13=""),"",IF(AND(7>=$E13,7<=$F13),1,"")) | V13: =IF(OR($D13="-",$D13=""),"",IF(AND(8>=$E13,8<=$F13),1,"")) | W13: =IF(OR($D13="-",$D13=""),"",IF(AND(9>=$E13,9<=$F13),1,"")) | X13: =IF(OR($D13="-",$D13=""),"",IF(AND(10>=$E13,10<=$F13),1,"")) | Y13: =IF(OR($D13="-",$D13=""),"",IF(AND(11>=$E13,11<=$F13),1,"")) | Z13: =IF(OR($D13="-",$D13=""),"",IF(AND(12>=$E13,12<=$F13),1,""))
A14: 1.2 | B14: Phase 1 | C14: Inscription Ordre | D14: =ROUND(6*'2-Mon Projet'!$D$44,0) | E14: -1 | F14: =IF(OR($D14="-",$D14=""),"",$E14+ROUND($D14/4,0)) | G14: OUI | H14: =IF(OR($D14="-",$D14=""),"",IF(AND(-6>=$E14,-6<=$F14),1,"")) | I14: =IF(OR($D14="-",$D14=""),"",IF(AND(-5>=$E14,-5<=$F14),1,"")) | J14: =IF(OR($D14="-",$D14=""),"",IF(AND(-4>=$E14,-4<=$F14),1,"")) | K14: =IF(OR($D14="-",$D14=""),"",IF(AND(-3>=$E14,-3<=$F14),1,"")) | L14: =IF(OR($D14="-",$D14=""),"",IF(AND(-2>=$E14,-2<=$F14),1,"")) | M14: =IF(OR($D14="-",$D14=""),"",IF(AND(-1>=$E14,-1<=$F14),1,"")) | N14: =IF(OR($D14="-",$D14=""),"",IF(AND(0>=$E14,0<=$F14),1,"")) | O14: =IF(OR($D14="-",$D14=""),"",IF(AND(1>=$E14,1<=$F14),1,"")) | P14: =IF(OR($D14="-",$D14=""),"",IF(AND(2>=$E14,2<=$F14),1,"")) | Q14: =IF(OR($D14="-",$D14=""),"",IF(AND(3>=$E14,3<=$F14),1,"")) | R14: =IF(OR($D14="-",$D14=""),"",IF(AND(4>=$E14,4<=$F14),1,"")) | S14: =IF(OR($D14="-",$D14=""),"",IF(AND(5>=$E14,5<=$F14),1,"")) | T14: =IF(OR($D14="-",$D14=""),"",IF(AND(6>=$E14,6<=$F14),1,"")) | U14: =IF(OR($D14="-",$D14=""),"",IF(AND(7>=$E14,7<=$F14),1,"")) | V14: =IF(OR($D14="-",$D14=""),"",IF(AND(8>=$E14,8<=$F14),1,"")) | W14: =IF(OR($D14="-",$D14=""),"",IF(AND(9>=$E14,9<=$F14),1,"")) | X14: =IF(OR($D14="-",$D14=""),"",IF(AND(10>=$E14,10<=$F14),1,"")) | Y14: =IF(OR($D14="-",$D14=""),"",IF(AND(11>=$E14,11<=$F14),1,"")) | Z14: =IF(OR($D14="-",$D14=""),"",IF(AND(12>=$E14,12<=$F14),1,""))
A15: 1.3 | B15: Phase 1 | C15: Assurance RCP | D15: =2 | E15: -1 | F15: =IF(OR($D15="-",$D15=""),"",$E15+ROUND($D15/4,0)) | G15: OUI | H15: =IF(OR($D15="-",$D15=""),"",IF(AND(-6>=$E15,-6<=$F15),1,"")) | I15: =IF(OR($D15="-",$D15=""),"",IF(AND(-5>=$E15,-5<=$F15),1,"")) | J15: =IF(OR($D15="-",$D15=""),"",IF(AND(-4>=$E15,-4<=$F15),1,"")) | K15: =IF(OR($D15="-",$D15=""),"",IF(AND(-3>=$E15,-3<=$F15),1,"")) | L15: =IF(OR($D15="-",$D15=""),"",IF(AND(-2>=$E15,-2<=$F15),1,"")) | M15: =IF(OR($D15="-",$D15=""),"",IF(AND(-1>=$E15,-1<=$F15),1,"")) | N15: =IF(OR($D15="-",$D15=""),"",IF(AND(0>=$E15,0<=$F15),1,"")) | O15: =IF(OR($D15="-",$D15=""),"",IF(AND(1>=$E15,1<=$F15),1,"")) | P15: =IF(OR($D15="-",$D15=""),"",IF(AND(2>=$E15,2<=$F15),1,"")) | Q15: =IF(OR($D15="-",$D15=""),"",IF(AND(3>=$E15,3<=$F15),1,"")) | R15: =IF(OR($D15="-",$D15=""),"",IF(AND(4>=$E15,4<=$F15),1,"")) | S15: =IF(OR($D15="-",$D15=""),"",IF(AND(5>=$E15,5<=$F15),1,"")) | T15: =IF(OR($D15="-",$D15=""),"",IF(AND(6>=$E15,6<=$F15),1,"")) | U15: =IF(OR($D15="-",$D15=""),"",IF(AND(7>=$E15,7<=$F15),1,"")) | V15: =IF(OR($D15="-",$D15=""),"",IF(AND(8>=$E15,8<=$F15),1,"")) | W15: =IF(OR($D15="-",$D15=""),"",IF(AND(9>=$E15,9<=$F15),1,"")) | X15: =IF(OR($D15="-",$D15=""),"",IF(AND(10>=$E15,10<=$F15),1,"")) | Y15: =IF(OR($D15="-",$D15=""),"",IF(AND(11>=$E15,11<=$F15),1,"")) | Z15: =IF(OR($D15="-",$D15=""),"",IF(AND(12>=$E15,12<=$F15),1,""))
B16: PHASE 2 | C16: SI & CONFORMITÉ
A17: 2.1 | B17: Phase 2 | C17: Logiciel prod | D17: =ROUND(4*'2-Mon Projet'!$D$44*'2-Mon Projet'!$D$46,0) | E17: -2 | F17: =IF(OR($D17="-",$D17=""),"",$E17+ROUND($D17/4,0)) | G17: Non | H17: =IF(OR($D17="-",$D17=""),"",IF(AND(-6>=$E17,-6<=$F17),1,"")) | I17: =IF(OR($D17="-",$D17=""),"",IF(AND(-5>=$E17,-5<=$F17),1,"")) | J17: =IF(OR($D17="-",$D17=""),"",IF(AND(-4>=$E17,-4<=$F17),1,"")) | K17: =IF(OR($D17="-",$D17=""),"",IF(AND(-3>=$E17,-3<=$F17),1,"")) | L17: =IF(OR($D17="-",$D17=""),"",IF(AND(-2>=$E17,-2<=$F17),1,"")) | M17: =IF(OR($D17="-",$D17=""),"",IF(AND(-1>=$E17,-1<=$F17),1,"")) | N17: =IF(OR($D17="-",$D17=""),"",IF(AND(0>=$E17,0<=$F17),1,"")) | O17: =IF(OR($D17="-",$D17=""),"",IF(AND(1>=$E17,1<=$F17),1,"")) | P17: =IF(OR($D17="-",$D17=""),"",IF(AND(2>=$E17,2<=$F17),1,"")) | Q17: =IF(OR($D17="-",$D17=""),"",IF(AND(3>=$E17,3<=$F17),1,"")) | R17: =IF(OR($D17="-",$D17=""),"",IF(AND(4>=$E17,4<=$F17),1,"")) | S17: =IF(OR($D17="-",$D17=""),"",IF(AND(5>=$E17,5<=$F17),1,"")) | T17: =IF(OR($D17="-",$D17=""),"",IF(AND(6>=$E17,6<=$F17),1,"")) | U17: =IF(OR($D17="-",$D17=""),"",IF(AND(7>=$E17,7<=$F17),1,"")) | V17: =IF(OR($D17="-",$D17=""),"",IF(AND(8>=$E17,8<=$F17),1,"")) | W17: =IF(OR($D17="-",$D17=""),"",IF(AND(9>=$E17,9<=$F17),1,"")) | X17: =IF(OR($D17="-",$D17=""),"",IF(AND(10>=$E17,10<=$F17),1,"")) | Y17: =IF(OR($D17="-",$D17=""),"",IF(AND(11>=$E17,11<=$F17),1,"")) | Z17: =IF(OR($D17="-",$D17=""),"",IF(AND(12>=$E17,12<=$F17),1,""))
A18: 2.2 | B18: Phase 2 | C18: RGPD | D18: =ROUND(3*'2-Mon Projet'!$D$46,0) | E18: -1 | F18: =IF(OR($D18="-",$D18=""),"",$E18+ROUND($D18/4,0)) | G18: OUI | H18: =IF(OR($D18="-",$D18=""),"",IF(AND(-6>=$E18,-6<=$F18),1,"")) | I18: =IF(OR($D18="-",$D18=""),"",IF(AND(-5>=$E18,-5<=$F18),1,"")) | J18: =IF(OR($D18="-",$D18=""),"",IF(AND(-4>=$E18,-4<=$F18),1,"")) | K18: =IF(OR($D18="-",$D18=""),"",IF(AND(-3>=$E18,-3<=$F18),1,"")) | L18: =IF(OR($D18="-",$D18=""),"",IF(AND(-2>=$E18,-2<=$F18),1,"")) | M18: =IF(OR($D18="-",$D18=""),"",IF(AND(-1>=$E18,-1<=$F18),1,"")) | N18: =IF(OR($D18="-",$D18=""),"",IF(AND(0>=$E18,0<=$F18),1,"")) | O18: =IF(OR($D18="-",$D18=""),"",IF(AND(1>=$E18,1<=$F18),1,"")) | P18: =IF(OR($D18="-",$D18=""),"",IF(AND(2>=$E18,2<=$F18),1,"")) | Q18: =IF(OR($D18="-",$D18=""),"",IF(AND(3>=$E18,3<=$F18),1,"")) | R18: =IF(OR($D18="-",$D18=""),"",IF(AND(4>=$E18,4<=$F18),1,"")) | S18: =IF(OR($D18="-",$D18=""),"",IF(AND(5>=$E18,5<=$F18),1,"")) | T18: =IF(OR($D18="-",$D18=""),"",IF(AND(6>=$E18,6<=$F18),1,"")) | U18: =IF(OR($D18="-",$D18=""),"",IF(AND(7>=$E18,7<=$F18),1,"")) | V18: =IF(OR($D18="-",$D18=""),"",IF(AND(8>=$E18,8<=$F18),1,"")) | W18: =IF(OR($D18="-",$D18=""),"",IF(AND(9>=$E18,9<=$F18),1,"")) | X18: =IF(OR($D18="-",$D18=""),"",IF(AND(10>=$E18,10<=$F18),1,"")) | Y18: =IF(OR($D18="-",$D18=""),"",IF(AND(11>=$E18,11<=$F18),1,"")) | Z18: =IF(OR($D18="-",$D18=""),"",IF(AND(12>=$E18,12<=$F18),1,""))
A19: 2.3 | B19: Phase 2 | C19: Cybersécurité | D19: =ROUND(2*'2-Mon Projet'!$D$46,0) | E19: -1 | F19: =IF(OR($D19="-",$D19=""),"",$E19+ROUND($D19/4,0)) | G19: Non | H19: =IF(OR($D19="-",$D19=""),"",IF(AND(-6>=$E19,-6<=$F19),1,"")) | I19: =IF(OR($D19="-",$D19=""),"",IF(AND(-5>=$E19,-5<=$F19),1,"")) | J19: =IF(OR($D19="-",$D19=""),"",IF(AND(-4>=$E19,-4<=$F19),1,"")) | K19: =IF(OR($D19="-",$D19=""),"",IF(AND(-3>=$E19,-3<=$F19),1,"")) | L19: =IF(OR($D19="-",$D19=""),"",IF(AND(-2>=$E19,-2<=$F19),1,"")) | M19: =IF(OR($D19="-",$D19=""),"",IF(AND(-1>=$E19,-1<=$F19),1,"")) | N19: =IF(OR($D19="-",$D19=""),"",IF(AND(0>=$E19,0<=$F19),1,"")) | O19: =IF(OR($D19="-",$D19=""),"",IF(AND(1>=$E19,1<=$F19),1,"")) | P19: =IF(OR($D19="-",$D19=""),"",IF(AND(2>=$E19,2<=$F19),1,"")) | Q19: =IF(OR($D19="-",$D19=""),"",IF(AND(3>=$E19,3<=$F19),1,"")) | R19: =IF(OR($D19="-",$D19=""),"",IF(AND(4>=$E19,4<=$F19),1,"")) | S19: =IF(OR($D19="-",$D19=""),"",IF(AND(5>=$E19,5<=$F19),1,"")) | T19: =IF(OR($D19="-",$D19=""),"",IF(AND(6>=$E19,6<=$F19),1,"")) | U19: =IF(OR($D19="-",$D19=""),"",IF(AND(7>=$E19,7<=$F19),1,"")) | V19: =IF(OR($D19="-",$D19=""),"",IF(AND(8>=$E19,8<=$F19),1,"")) | W19: =IF(OR($D19="-",$D19=""),"",IF(AND(9>=$E19,9<=$F19),1,"")) | X19: =IF(OR($D19="-",$D19=""),"",IF(AND(10>=$E19,10<=$F19),1,"")) | Y19: =IF(OR($D19="-",$D19=""),"",IF(AND(11>=$E19,11<=$F19),1,"")) | Z19: =IF(OR($D19="-",$D19=""),"",IF(AND(12>=$E19,12<=$F19),1,""))
A20: 2.4 | B20: Phase 2 | C20: Choix PA (ex-PDP) / portail e-facture / PA | D20: =ROUND(4*'2-Mon Projet'!$D$46,0) | E20: 0 | F20: =IF(OR($D20="-",$D20=""),"",$E20+ROUND($D20/4,0)) | G20: OUI | H20: =IF(OR($D20="-",$D20=""),"",IF(AND(-6>=$E20,-6<=$F20),1,"")) | I20: =IF(OR($D20="-",$D20=""),"",IF(AND(-5>=$E20,-5<=$F20),1,"")) | J20: =IF(OR($D20="-",$D20=""),"",IF(AND(-4>=$E20,-4<=$F20),1,"")) | K20: =IF(OR($D20="-",$D20=""),"",IF(AND(-3>=$E20,-3<=$F20),1,"")) | L20: =IF(OR($D20="-",$D20=""),"",IF(AND(-2>=$E20,-2<=$F20),1,"")) | M20: =IF(OR($D20="-",$D20=""),"",IF(AND(-1>=$E20,-1<=$F20),1,"")) | N20: =IF(OR($D20="-",$D20=""),"",IF(AND(0>=$E20,0<=$F20),1,"")) | O20: =IF(OR($D20="-",$D20=""),"",IF(AND(1>=$E20,1<=$F20),1,"")) | P20: =IF(OR($D20="-",$D20=""),"",IF(AND(2>=$E20,2<=$F20),1,"")) | Q20: =IF(OR($D20="-",$D20=""),"",IF(AND(3>=$E20,3<=$F20),1,"")) | R20: =IF(OR($D20="-",$D20=""),"",IF(AND(4>=$E20,4<=$F20),1,"")) | S20: =IF(OR($D20="-",$D20=""),"",IF(AND(5>=$E20,5<=$F20),1,"")) | T20: =IF(OR($D20="-",$D20=""),"",IF(AND(6>=$E20,6<=$F20),1,"")) | U20: =IF(OR($D20="-",$D20=""),"",IF(AND(7>=$E20,7<=$F20),1,"")) | V20: =IF(OR($D20="-",$D20=""),"",IF(AND(8>=$E20,8<=$F20),1,"")) | W20: =IF(OR($D20="-",$D20=""),"",IF(AND(9>=$E20,9<=$F20),1,"")) | X20: =IF(OR($D20="-",$D20=""),"",IF(AND(10>=$E20,10<=$F20),1,"")) | Y20: =IF(OR($D20="-",$D20=""),"",IF(AND(11>=$E20,11<=$F20),1,"")) | Z20: =IF(OR($D20="-",$D20=""),"",IF(AND(12>=$E20,12<=$F20),1,""))
B21: PHASE 3 | C21: LANCEMENT M0-M+3
A22: 3.1 | B22: Phase 3 | C22: Site web | D22: =4 | E22: 0 | F22: =IF(OR($D22="-",$D22=""),"",$E22+ROUND($D22/4,0)) | G22: Non | H22: =IF(OR($D22="-",$D22=""),"",IF(AND(-6>=$E22,-6<=$F22),1,"")) | I22: =IF(OR($D22="-",$D22=""),"",IF(AND(-5>=$E22,-5<=$F22),1,"")) | J22: =IF(OR($D22="-",$D22=""),"",IF(AND(-4>=$E22,-4<=$F22),1,"")) | K22: =IF(OR($D22="-",$D22=""),"",IF(AND(-3>=$E22,-3<=$F22),1,"")) | L22: =IF(OR($D22="-",$D22=""),"",IF(AND(-2>=$E22,-2<=$F22),1,"")) | M22: =IF(OR($D22="-",$D22=""),"",IF(AND(-1>=$E22,-1<=$F22),1,"")) | N22: =IF(OR($D22="-",$D22=""),"",IF(AND(0>=$E22,0<=$F22),1,"")) | O22: =IF(OR($D22="-",$D22=""),"",IF(AND(1>=$E22,1<=$F22),1,"")) | P22: =IF(OR($D22="-",$D22=""),"",IF(AND(2>=$E22,2<=$F22),1,"")) | Q22: =IF(OR($D22="-",$D22=""),"",IF(AND(3>=$E22,3<=$F22),1,"")) | R22: =IF(OR($D22="-",$D22=""),"",IF(AND(4>=$E22,4<=$F22),1,"")) | S22: =IF(OR($D22="-",$D22=""),"",IF(AND(5>=$E22,5<=$F22),1,"")) | T22: =IF(OR($D22="-",$D22=""),"",IF(AND(6>=$E22,6<=$F22),1,"")) | U22: =IF(OR($D22="-",$D22=""),"",IF(AND(7>=$E22,7<=$F22),1,"")) | V22: =IF(OR($D22="-",$D22=""),"",IF(AND(8>=$E22,8<=$F22),1,"")) | W22: =IF(OR($D22="-",$D22=""),"",IF(AND(9>=$E22,9<=$F22),1,"")) | X22: =IF(OR($D22="-",$D22=""),"",IF(AND(10>=$E22,10<=$F22),1,"")) | Y22: =IF(OR($D22="-",$D22=""),"",IF(AND(11>=$E22,11<=$F22),1,"")) | Z22: =IF(OR($D22="-",$D22=""),"",IF(AND(12>=$E22,12<=$F22),1,""))
A23: 3.2 | B23: Phase 3 | C23: Onboarding | D23: =8 | E23: 1 | F23: =IF(OR($D23="-",$D23=""),"",$E23+ROUND($D23/4,0)) | G23: Non | H23: =IF(OR($D23="-",$D23=""),"",IF(AND(-6>=$E23,-6<=$F23),1,"")) | I23: =IF(OR($D23="-",$D23=""),"",IF(AND(-5>=$E23,-5<=$F23),1,"")) | J23: =IF(OR($D23="-",$D23=""),"",IF(AND(-4>=$E23,-4<=$F23),1,"")) | K23: =IF(OR($D23="-",$D23=""),"",IF(AND(-3>=$E23,-3<=$F23),1,"")) | L23: =IF(OR($D23="-",$D23=""),"",IF(AND(-2>=$E23,-2<=$F23),1,"")) | M23: =IF(OR($D23="-",$D23=""),"",IF(AND(-1>=$E23,-1<=$F23),1,"")) | N23: =IF(OR($D23="-",$D23=""),"",IF(AND(0>=$E23,0<=$F23),1,"")) | O23: =IF(OR($D23="-",$D23=""),"",IF(AND(1>=$E23,1<=$F23),1,"")) | P23: =IF(OR($D23="-",$D23=""),"",IF(AND(2>=$E23,2<=$F23),1,"")) | Q23: =IF(OR($D23="-",$D23=""),"",IF(AND(3>=$E23,3<=$F23),1,"")) | R23: =IF(OR($D23="-",$D23=""),"",IF(AND(4>=$E23,4<=$F23),1,"")) | S23: =IF(OR($D23="-",$D23=""),"",IF(AND(5>=$E23,5<=$F23),1,"")) | T23: =IF(OR($D23="-",$D23=""),"",IF(AND(6>=$E23,6<=$F23),1,"")) | U23: =IF(OR($D23="-",$D23=""),"",IF(AND(7>=$E23,7<=$F23),1,"")) | V23: =IF(OR($D23="-",$D23=""),"",IF(AND(8>=$E23,8<=$F23),1,"")) | W23: =IF(OR($D23="-",$D23=""),"",IF(AND(9>=$E23,9<=$F23),1,"")) | X23: =IF(OR($D23="-",$D23=""),"",IF(AND(10>=$E23,10<=$F23),1,"")) | Y23: =IF(OR($D23="-",$D23=""),"",IF(AND(11>=$E23,11<=$F23),1,"")) | Z23: =IF(OR($D23="-",$D23=""),"",IF(AND(12>=$E23,12<=$F23),1,""))
A24: 3.3 | B24: Phase 3 | C24: Process std | D24: =4 | E24: 3 | F24: =IF(OR($D24="-",$D24=""),"",$E24+ROUND($D24/4,0)) | G24: Non | H24: =IF(OR($D24="-",$D24=""),"",IF(AND(-6>=$E24,-6<=$F24),1,"")) | I24: =IF(OR($D24="-",$D24=""),"",IF(AND(-5>=$E24,-5<=$F24),1,"")) | J24: =IF(OR($D24="-",$D24=""),"",IF(AND(-4>=$E24,-4<=$F24),1,"")) | K24: =IF(OR($D24="-",$D24=""),"",IF(AND(-3>=$E24,-3<=$F24),1,"")) | L24: =IF(OR($D24="-",$D24=""),"",IF(AND(-2>=$E24,-2<=$F24),1,"")) | M24: =IF(OR($D24="-",$D24=""),"",IF(AND(-1>=$E24,-1<=$F24),1,"")) | N24: =IF(OR($D24="-",$D24=""),"",IF(AND(0>=$E24,0<=$F24),1,"")) | O24: =IF(OR($D24="-",$D24=""),"",IF(AND(1>=$E24,1<=$F24),1,"")) | P24: =IF(OR($D24="-",$D24=""),"",IF(AND(2>=$E24,2<=$F24),1,"")) | Q24: =IF(OR($D24="-",$D24=""),"",IF(AND(3>=$E24,3<=$F24),1,"")) | R24: =IF(OR($D24="-",$D24=""),"",IF(AND(4>=$E24,4<=$F24),1,"")) | S24: =IF(OR($D24="-",$D24=""),"",IF(AND(5>=$E24,5<=$F24),1,"")) | T24: =IF(OR($D24="-",$D24=""),"",IF(AND(6>=$E24,6<=$F24),1,"")) | U24: =IF(OR($D24="-",$D24=""),"",IF(AND(7>=$E24,7<=$F24),1,"")) | V24: =IF(OR($D24="-",$D24=""),"",IF(AND(8>=$E24,8<=$F24),1,"")) | W24: =IF(OR($D24="-",$D24=""),"",IF(AND(9>=$E24,9<=$F24),1,"")) | X24: =IF(OR($D24="-",$D24=""),"",IF(AND(10>=$E24,10<=$F24),1,"")) | Y24: =IF(OR($D24="-",$D24=""),"",IF(AND(11>=$E24,11<=$F24),1,"")) | Z24: =IF(OR($D24="-",$D24=""),"",IF(AND(12>=$E24,12<=$F24),1,""))
B25: PHASE 4 | C25: INDUSTRIALISATION M+3-M+6
A26: 4.1 | B26: Phase 4 | C26: Dev clients | D26: =ROUND(12*'2-Mon Projet'!$D$44,0) | E26: 3 | F26: =IF(OR($D26="-",$D26=""),"",$E26+ROUND($D26/4,0)) | G26: OUI | H26: =IF(OR($D26="-",$D26=""),"",IF(AND(-6>=$E26,-6<=$F26),1,"")) | I26: =IF(OR($D26="-",$D26=""),"",IF(AND(-5>=$E26,-5<=$F26),1,"")) | J26: =IF(OR($D26="-",$D26=""),"",IF(AND(-4>=$E26,-4<=$F26),1,"")) | K26: =IF(OR($D26="-",$D26=""),"",IF(AND(-3>=$E26,-3<=$F26),1,"")) | L26: =IF(OR($D26="-",$D26=""),"",IF(AND(-2>=$E26,-2<=$F26),1,"")) | M26: =IF(OR($D26="-",$D26=""),"",IF(AND(-1>=$E26,-1<=$F26),1,"")) | N26: =IF(OR($D26="-",$D26=""),"",IF(AND(0>=$E26,0<=$F26),1,"")) | O26: =IF(OR($D26="-",$D26=""),"",IF(AND(1>=$E26,1<=$F26),1,"")) | P26: =IF(OR($D26="-",$D26=""),"",IF(AND(2>=$E26,2<=$F26),1,"")) | Q26: =IF(OR($D26="-",$D26=""),"",IF(AND(3>=$E26,3<=$F26),1,"")) | R26: =IF(OR($D26="-",$D26=""),"",IF(AND(4>=$E26,4<=$F26),1,"")) | S26: =IF(OR($D26="-",$D26=""),"",IF(AND(5>=$E26,5<=$F26),1,"")) | T26: =IF(OR($D26="-",$D26=""),"",IF(AND(6>=$E26,6<=$F26),1,"")) | U26: =IF(OR($D26="-",$D26=""),"",IF(AND(7>=$E26,7<=$F26),1,"")) | V26: =IF(OR($D26="-",$D26=""),"",IF(AND(8>=$E26,8<=$F26),1,"")) | W26: =IF(OR($D26="-",$D26=""),"",IF(AND(9>=$E26,9<=$F26),1,"")) | X26: =IF(OR($D26="-",$D26=""),"",IF(AND(10>=$E26,10<=$F26),1,"")) | Y26: =IF(OR($D26="-",$D26=""),"",IF(AND(11>=$E26,11<=$F26),1,"")) | Z26: =IF(OR($D26="-",$D26=""),"",IF(AND(12>=$E26,12<=$F26),1,""))
A27: 4.2 | B27: Phase 4 | C27: Automatisations | D27: =ROUND(4*'2-Mon Projet'!$D$46,0) | E27: 4 | F27: =IF(OR($D27="-",$D27=""),"",$E27+ROUND($D27/4,0)) | G27: Non | H27: =IF(OR($D27="-",$D27=""),"",IF(AND(-6>=$E27,-6<=$F27),1,"")) | I27: =IF(OR($D27="-",$D27=""),"",IF(AND(-5>=$E27,-5<=$F27),1,"")) | J27: =IF(OR($D27="-",$D27=""),"",IF(AND(-4>=$E27,-4<=$F27),1,"")) | K27: =IF(OR($D27="-",$D27=""),"",IF(AND(-3>=$E27,-3<=$F27),1,"")) | L27: =IF(OR($D27="-",$D27=""),"",IF(AND(-2>=$E27,-2<=$F27),1,"")) | M27: =IF(OR($D27="-",$D27=""),"",IF(AND(-1>=$E27,-1<=$F27),1,"")) | N27: =IF(OR($D27="-",$D27=""),"",IF(AND(0>=$E27,0<=$F27),1,"")) | O27: =IF(OR($D27="-",$D27=""),"",IF(AND(1>=$E27,1<=$F27),1,"")) | P27: =IF(OR($D27="-",$D27=""),"",IF(AND(2>=$E27,2<=$F27),1,"")) | Q27: =IF(OR($D27="-",$D27=""),"",IF(AND(3>=$E27,3<=$F27),1,"")) | R27: =IF(OR($D27="-",$D27=""),"",IF(AND(4>=$E27,4<=$F27),1,"")) | S27: =IF(OR($D27="-",$D27=""),"",IF(AND(5>=$E27,5<=$F27),1,"")) | T27: =IF(OR($D27="-",$D27=""),"",IF(AND(6>=$E27,6<=$F27),1,"")) | U27: =IF(OR($D27="-",$D27=""),"",IF(AND(7>=$E27,7<=$F27),1,"")) | V27: =IF(OR($D27="-",$D27=""),"",IF(AND(8>=$E27,8<=$F27),1,"")) | W27: =IF(OR($D27="-",$D27=""),"",IF(AND(9>=$E27,9<=$F27),1,"")) | X27: =IF(OR($D27="-",$D27=""),"",IF(AND(10>=$E27,10<=$F27),1,"")) | Y27: =IF(OR($D27="-",$D27=""),"",IF(AND(11>=$E27,11<=$F27),1,"")) | Z27: =IF(OR($D27="-",$D27=""),"",IF(AND(12>=$E27,12<=$F27),1,""))
A28: 4.3 | B28: Phase 4 | C28: Audit Cyber | D28: =2 | E28: 4 | F28: =IF(OR($D28="-",$D28=""),"",$E28+ROUND($D28/4,0)) | G28: Non | H28: =IF(OR($D28="-",$D28=""),"",IF(AND(-6>=$E28,-6<=$F28),1,"")) | I28: =IF(OR($D28="-",$D28=""),"",IF(AND(-5>=$E28,-5<=$F28),1,"")) | J28: =IF(OR($D28="-",$D28=""),"",IF(AND(-4>=$E28,-4<=$F28),1,"")) | K28: =IF(OR($D28="-",$D28=""),"",IF(AND(-3>=$E28,-3<=$F28),1,"")) | L28: =IF(OR($D28="-",$D28=""),"",IF(AND(-2>=$E28,-2<=$F28),1,"")) | M28: =IF(OR($D28="-",$D28=""),"",IF(AND(-1>=$E28,-1<=$F28),1,"")) | N28: =IF(OR($D28="-",$D28=""),"",IF(AND(0>=$E28,0<=$F28),1,"")) | O28: =IF(OR($D28="-",$D28=""),"",IF(AND(1>=$E28,1<=$F28),1,"")) | P28: =IF(OR($D28="-",$D28=""),"",IF(AND(2>=$E28,2<=$F28),1,"")) | Q28: =IF(OR($D28="-",$D28=""),"",IF(AND(3>=$E28,3<=$F28),1,"")) | R28: =IF(OR($D28="-",$D28=""),"",IF(AND(4>=$E28,4<=$F28),1,"")) | S28: =IF(OR($D28="-",$D28=""),"",IF(AND(5>=$E28,5<=$F28),1,"")) | T28: =IF(OR($D28="-",$D28=""),"",IF(AND(6>=$E28,6<=$F28),1,"")) | U28: =IF(OR($D28="-",$D28=""),"",IF(AND(7>=$E28,7<=$F28),1,"")) | V28: =IF(OR($D28="-",$D28=""),"",IF(AND(8>=$E28,8<=$F28),1,"")) | W28: =IF(OR($D28="-",$D28=""),"",IF(AND(9>=$E28,9<=$F28),1,"")) | X28: =IF(OR($D28="-",$D28=""),"",IF(AND(10>=$E28,10<=$F28),1,"")) | Y28: =IF(OR($D28="-",$D28=""),"",IF(AND(11>=$E28,11<=$F28),1,"")) | Z28: =IF(OR($D28="-",$D28=""),"",IF(AND(12>=$E28,12<=$F28),1,""))
A29: 4.4 | B29: Phase 4 | C29: Offre Conseil e-facture | D29: =8 | E29: 4 | F29: =IF(OR($D29="-",$D29=""),"",$E29+ROUND($D29/4,0)) | G29: Non | H29: =IF(OR($D29="-",$D29=""),"",IF(AND(-6>=$E29,-6<=$F29),1,"")) | I29: =IF(OR($D29="-",$D29=""),"",IF(AND(-5>=$E29,-5<=$F29),1,"")) | J29: =IF(OR($D29="-",$D29=""),"",IF(AND(-4>=$E29,-4<=$F29),1,"")) | K29: =IF(OR($D29="-",$D29=""),"",IF(AND(-3>=$E29,-3<=$F29),1,"")) | L29: =IF(OR($D29="-",$D29=""),"",IF(AND(-2>=$E29,-2<=$F29),1,"")) | M29: =IF(OR($D29="-",$D29=""),"",IF(AND(-1>=$E29,-1<=$F29),1,"")) | N29: =IF(OR($D29="-",$D29=""),"",IF(AND(0>=$E29,0<=$F29),1,"")) | O29: =IF(OR($D29="-",$D29=""),"",IF(AND(1>=$E29,1<=$F29),1,"")) | P29: =IF(OR($D29="-",$D29=""),"",IF(AND(2>=$E29,2<=$F29),1,"")) | Q29: =IF(OR($D29="-",$D29=""),"",IF(AND(3>=$E29,3<=$F29),1,"")) | R29: =IF(OR($D29="-",$D29=""),"",IF(AND(4>=$E29,4<=$F29),1,"")) | S29: =IF(OR($D29="-",$D29=""),"",IF(AND(5>=$E29,5<=$F29),1,"")) | T29: =IF(OR($D29="-",$D29=""),"",IF(AND(6>=$E29,6<=$F29),1,"")) | U29: =IF(OR($D29="-",$D29=""),"",IF(AND(7>=$E29,7<=$F29),1,"")) | V29: =IF(OR($D29="-",$D29=""),"",IF(AND(8>=$E29,8<=$F29),1,"")) | W29: =IF(OR($D29="-",$D29=""),"",IF(AND(9>=$E29,9<=$F29),1,"")) | X29: =IF(OR($D29="-",$D29=""),"",IF(AND(10>=$E29,10<=$F29),1,"")) | Y29: =IF(OR($D29="-",$D29=""),"",IF(AND(11>=$E29,11<=$F29),1,"")) | Z29: =IF(OR($D29="-",$D29=""),"",IF(AND(12>=$E29,12<=$F29),1,""))
B30: PHASE 5 | C30: STRUCTURATION M+6-M+12
A31: 5.1 | B31: Phase 5 | C31: Recrutement | D31: =IF('2-Mon Projet'!$D$26=0,"-",10) | E31: 6 | F31: =IF(OR($D31="-",$D31=""),"",$E31+ROUND($D31/4,0)) | G31: OUI | H31: =IF(OR($D31="-",$D31=""),"",IF(AND(-6>=$E31,-6<=$F31),1,"")) | I31: =IF(OR($D31="-",$D31=""),"",IF(AND(-5>=$E31,-5<=$F31),1,"")) | J31: =IF(OR($D31="-",$D31=""),"",IF(AND(-4>=$E31,-4<=$F31),1,"")) | K31: =IF(OR($D31="-",$D31=""),"",IF(AND(-3>=$E31,-3<=$F31),1,"")) | L31: =IF(OR($D31="-",$D31=""),"",IF(AND(-2>=$E31,-2<=$F31),1,"")) | M31: =IF(OR($D31="-",$D31=""),"",IF(AND(-1>=$E31,-1<=$F31),1,"")) | N31: =IF(OR($D31="-",$D31=""),"",IF(AND(0>=$E31,0<=$F31),1,"")) | O31: =IF(OR($D31="-",$D31=""),"",IF(AND(1>=$E31,1<=$F31),1,"")) | P31: =IF(OR($D31="-",$D31=""),"",IF(AND(2>=$E31,2<=$F31),1,"")) | Q31: =IF(OR($D31="-",$D31=""),"",IF(AND(3>=$E31,3<=$F31),1,"")) | R31: =IF(OR($D31="-",$D31=""),"",IF(AND(4>=$E31,4<=$F31),1,"")) | S31: =IF(OR($D31="-",$D31=""),"",IF(AND(5>=$E31,5<=$F31),1,"")) | T31: =IF(OR($D31="-",$D31=""),"",IF(AND(6>=$E31,6<=$F31),1,"")) | U31: =IF(OR($D31="-",$D31=""),"",IF(AND(7>=$E31,7<=$F31),1,"")) | V31: =IF(OR($D31="-",$D31=""),"",IF(AND(8>=$E31,8<=$F31),1,"")) | W31: =IF(OR($D31="-",$D31=""),"",IF(AND(9>=$E31,9<=$F31),1,"")) | X31: =IF(OR($D31="-",$D31=""),"",IF(AND(10>=$E31,10<=$F31),1,"")) | Y31: =IF(OR($D31="-",$D31=""),"",IF(AND(11>=$E31,11<=$F31),1,"")) | Z31: =IF(OR($D31="-",$D31=""),"",IF(AND(12>=$E31,12<=$F31),1,""))
A32: 5.2 | B32: Phase 5 | C32: Integration | D32: =IF('2-Mon Projet'!$D$26=0,"-",4) | E32: 8 | F32: =IF(OR($D32="-",$D32=""),"",$E32+ROUND($D32/4,0)) | G32: Non | H32: =IF(OR($D32="-",$D32=""),"",IF(AND(-6>=$E32,-6<=$F32),1,"")) | I32: =IF(OR($D32="-",$D32=""),"",IF(AND(-5>=$E32,-5<=$F32),1,"")) | J32: =IF(OR($D32="-",$D32=""),"",IF(AND(-4>=$E32,-4<=$F32),1,"")) | K32: =IF(OR($D32="-",$D32=""),"",IF(AND(-3>=$E32,-3<=$F32),1,"")) | L32: =IF(OR($D32="-",$D32=""),"",IF(AND(-2>=$E32,-2<=$F32),1,"")) | M32: =IF(OR($D32="-",$D32=""),"",IF(AND(-1>=$E32,-1<=$F32),1,"")) | N32: =IF(OR($D32="-",$D32=""),"",IF(AND(0>=$E32,0<=$F32),1,"")) | O32: =IF(OR($D32="-",$D32=""),"",IF(AND(1>=$E32,1<=$F32),1,"")) | P32: =IF(OR($D32="-",$D32=""),"",IF(AND(2>=$E32,2<=$F32),1,"")) | Q32: =IF(OR($D32="-",$D32=""),"",IF(AND(3>=$E32,3<=$F32),1,"")) | R32: =IF(OR($D32="-",$D32=""),"",IF(AND(4>=$E32,4<=$F32),1,"")) | S32: =IF(OR($D32="-",$D32=""),"",IF(AND(5>=$E32,5<=$F32),1,"")) | T32: =IF(OR($D32="-",$D32=""),"",IF(AND(6>=$E32,6<=$F32),1,"")) | U32: =IF(OR($D32="-",$D32=""),"",IF(AND(7>=$E32,7<=$F32),1,"")) | V32: =IF(OR($D32="-",$D32=""),"",IF(AND(8>=$E32,8<=$F32),1,"")) | W32: =IF(OR($D32="-",$D32=""),"",IF(AND(9>=$E32,9<=$F32),1,"")) | X32: =IF(OR($D32="-",$D32=""),"",IF(AND(10>=$E32,10<=$F32),1,"")) | Y32: =IF(OR($D32="-",$D32=""),"",IF(AND(11>=$E32,11<=$F32),1,"")) | Z32: =IF(OR($D32="-",$D32=""),"",IF(AND(12>=$E32,12<=$F32),1,""))
A33: 5.3 | B33: Phase 5 | C33: Bilan annuel | D33: =2 | E33: 11 | F33: =IF(OR($D33="-",$D33=""),"",$E33+ROUND($D33/4,0)) | G33: OUI | H33: =IF(OR($D33="-",$D33=""),"",IF(AND(-6>=$E33,-6<=$F33),1,"")) | I33: =IF(OR($D33="-",$D33=""),"",IF(AND(-5>=$E33,-5<=$F33),1,"")) | J33: =IF(OR($D33="-",$D33=""),"",IF(AND(-4>=$E33,-4<=$F33),1,"")) | K33: =IF(OR($D33="-",$D33=""),"",IF(AND(-3>=$E33,-3<=$F33),1,"")) | L33: =IF(OR($D33="-",$D33=""),"",IF(AND(-2>=$E33,-2<=$F33),1,"")) | M33: =IF(OR($D33="-",$D33=""),"",IF(AND(-1>=$E33,-1<=$F33),1,"")) | N33: =IF(OR($D33="-",$D33=""),"",IF(AND(0>=$E33,0<=$F33),1,"")) | O33: =IF(OR($D33="-",$D33=""),"",IF(AND(1>=$E33,1<=$F33),1,"")) | P33: =IF(OR($D33="-",$D33=""),"",IF(AND(2>=$E33,2<=$F33),1,"")) | Q33: =IF(OR($D33="-",$D33=""),"",IF(AND(3>=$E33,3<=$F33),1,"")) | R33: =IF(OR($D33="-",$D33=""),"",IF(AND(4>=$E33,4<=$F33),1,"")) | S33: =IF(OR($D33="-",$D33=""),"",IF(AND(5>=$E33,5<=$F33),1,"")) | T33: =IF(OR($D33="-",$D33=""),"",IF(AND(6>=$E33,6<=$F33),1,"")) | U33: =IF(OR($D33="-",$D33=""),"",IF(AND(7>=$E33,7<=$F33),1,"")) | V33: =IF(OR($D33="-",$D33=""),"",IF(AND(8>=$E33,8<=$F33),1,"")) | W33: =IF(OR($D33="-",$D33=""),"",IF(AND(9>=$E33,9<=$F33),1,"")) | X33: =IF(OR($D33="-",$D33=""),"",IF(AND(10>=$E33,10<=$F33),1,"")) | Y33: =IF(OR($D33="-",$D33=""),"",IF(AND(11>=$E33,11<=$F33),1,"")) | Z33: =IF(OR($D33="-",$D33=""),"",IF(AND(12>=$E33,12<=$F33),1,""))
B34: PHASE 6 | C34: CONFORMITÉ CONTINUE
A35: 6.1 | B35: Phase 6 | C35: Formation continue | D35: =48 | E35: 0 | F35: =IF(OR($D35="-",$D35=""),"",$E35+ROUND($D35/4,0)) | G35: Non | H35: =IF(OR($D35="-",$D35=""),"",IF(AND(-6>=$E35,-6<=$F35),1,"")) | I35: =IF(OR($D35="-",$D35=""),"",IF(AND(-5>=$E35,-5<=$F35),1,"")) | J35: =IF(OR($D35="-",$D35=""),"",IF(AND(-4>=$E35,-4<=$F35),1,"")) | K35: =IF(OR($D35="-",$D35=""),"",IF(AND(-3>=$E35,-3<=$F35),1,"")) | L35: =IF(OR($D35="-",$D35=""),"",IF(AND(-2>=$E35,-2<=$F35),1,"")) | M35: =IF(OR($D35="-",$D35=""),"",IF(AND(-1>=$E35,-1<=$F35),1,"")) | N35: =IF(OR($D35="-",$D35=""),"",IF(AND(0>=$E35,0<=$F35),1,"")) | O35: =IF(OR($D35="-",$D35=""),"",IF(AND(1>=$E35,1<=$F35),1,"")) | P35: =IF(OR($D35="-",$D35=""),"",IF(AND(2>=$E35,2<=$F35),1,"")) | Q35: =IF(OR($D35="-",$D35=""),"",IF(AND(3>=$E35,3<=$F35),1,"")) | R35: =IF(OR($D35="-",$D35=""),"",IF(AND(4>=$E35,4<=$F35),1,"")) | S35: =IF(OR($D35="-",$D35=""),"",IF(AND(5>=$E35,5<=$F35),1,"")) | T35: =IF(OR($D35="-",$D35=""),"",IF(AND(6>=$E35,6<=$F35),1,"")) | U35: =IF(OR($D35="-",$D35=""),"",IF(AND(7>=$E35,7<=$F35),1,"")) | V35: =IF(OR($D35="-",$D35=""),"",IF(AND(8>=$E35,8<=$F35),1,"")) | W35: =IF(OR($D35="-",$D35=""),"",IF(AND(9>=$E35,9<=$F35),1,"")) | X35: =IF(OR($D35="-",$D35=""),"",IF(AND(10>=$E35,10<=$F35),1,"")) | Y35: =IF(OR($D35="-",$D35=""),"",IF(AND(11>=$E35,11<=$F35),1,"")) | Z35: =IF(OR($D35="-",$D35=""),"",IF(AND(12>=$E35,12<=$F35),1,""))
A38: LÉGENDE DES PHASES
B39: Phase 0 - Préparation | C39: Avant M0 : Diagnostic, SWOT, prévisionnel
B40: Phase 1 - Administratif | C40: Avant M0 : Statuts, Ordre, RCP
B41: Phase 2 - SI & Conformité | C41: M0 : Logiciels, RGPD, PA (ex-PDP)
B42: Phase 3 - Lancement | C42: M0→M+3 : Site, onboarding, process
B43: Phase 4 - Industrialisation | C43: M+3→M+6 : Clients, automatisations
...

Sheet 5-PERT Suivi
A1: PERT - SUIVI OPERATIONNEL DU PROJET
A2: Diagramme PERT adapte en outil de pilotage reel avec chemin critique et dependances
A3: ID | B3: Tâche | C3: Période | D3: Durée | E3: Annexe | F3: Statut | G3: Commentaire | H3: Livrable
A4: 0.1 | B4: Autodiagnostic maturité (Annexe 2 – 6 dimensions) | C4: Avant M0 | D4: 2 sem | E4: Annexe 2 | F4: =IFERROR(VLOOKUP($A4,'0-Saisie'!$B$46:$E$69,4,FALSE),"A faire") | G4: Critères RGPD/sécurité BLOQUANTS | H4: Diagnostic complété + plan d’actions
A5: 0.2 | B5: Étude marché | C5: Avant M0 | D5: 3 sem | E5: Annexe 1 | F5: =IFERROR(VLOOKUP($A5,'0-Saisie'!$B$46:$E$69,4,FALSE),"A faire") | G5: Données marché 2025-2026 | H5: Synthèse marché + hypothèses
A6: 0.3 | B6: SWOT + BMC | C6: Avant M0 | D6: 4 sem | E6: Annexe 3 + 8 | F6: =IFERROR(VLOOKUP($A6,'0-Saisie'!$B$46:$E$69,4,FALSE),"A faire") | G6: Utiliser Annexe 3 AVANT BMC | H6: SWOT + BMC validés
A7: 0.4 | B7: Prévisionnel financier | C7: Avant M0 | D7: 3 sem | E7: Annexe 7 | F7: =IFERROR(VLOOKUP($A7,'0-Saisie'!$B$46:$E$69,4,FALSE),"A faire") | G7: Scénario prudent + trésorerie sécurité | H7: Prévisionnel + plan financement
A8: 0.5 | B8: Architecture SI | C8: Avant M0 | D8: 2 sem | E8: Annexe 6 | F8: =IFERROR(VLOOKUP($A8,'0-Saisie'!$B$46:$E$69,4,FALSE),"A faire") | G8: Ne pas commander avant architecture validée | H8: Schéma SI + choix outils
A9: 0.6 | B9: Formation IA & Data (AI Act) | C9: Avant M0 | D9: 2 sem | E9: Annexe 1 | F9: =IFERROR(VLOOKUP($A9,'0-Saisie'!$B$46:$E$69,4,FALSE),"A faire") | G9: AI literacy (art. 4) + règles internes d’usage | H9: Attestation / plan de formation IA
A10: 1.1 | B10: Statuts + immatriculation | C10: Avant M0 | D10: 4 sem | E10: - | F10: =IFERROR(VLOOKUP($A10,'0-Saisie'!$B$46:$E$69,4,FALSE),"A faire") | G10: Anticiper délais greffe | H10: KBis / immatriculation
A11: 1.2 | B11: Inscription Ordre | C11: Avant M0 | D11: 6 sem | E11: Annexe 5 | F11: =IFERROR(VLOOKUP($A11,'0-Saisie'!$B$46:$E$69,4,FALSE),"A faire") | G11: CRITIQUE — délai incompressible | H11: Inscription obtenue
A12: 1.3 | B12: Assurance RCP | C12: M0 | D12: 2 sem | E12: - | F12: =IFERROR(VLOOKUP($A12,'0-Saisie'!$B$46:$E$69,4,FALSE),"A faire") | G12: RCP obligatoire avant exercice | H12: Attestation RCP
A13: 2.1 | B13: Déploiement logiciel | C13: M0 | D13: 4-6 sem | E13: Annexe 10 | F13: =IFERROR(VLOOKUP($A13,'0-Saisie'!$B$46:$E$69,4,FALSE),"A faire") | G13: Paramétrage prod + tests | H13: Production opérationnelle
A14: 2.2 | B14: RGPD | C14: M0 | D14: 3 sem | E14: - | F14: =IFERROR(VLOOKUP($A14,'0-Saisie'!$B$46:$E$69,4,FALSE),"A faire") | G14: AVANT 1er client (bloquant) | H14: Registre + procédures
A15: 2.3 | B15: Cybersécurité | C15: M0 | D15: 2 sem | E15: - | F15: =IFERROR(VLOOKUP($A15,'0-Saisie'!$B$46:$E$69,4,FALSE),"A faire") | G15: MFA + sauvegardes + PRA | H15: Mesures en place
... A27: 6.1 | B27: Formation continue | C27: M0-M+12 | D27: Récurrent | E27: Annexe 1 | F27: =IFERROR(VLOOKUP($A27,'0-Saisie'!$B$46:$E$69,4,FALSE),"A faire") | G27: 40h/an dont 20h homologuées + LCB-FT + IA | H27: Plan formation annuel
A30: AVANCEMENT GLOBAL: | B30: =COUNTIF(F4:F27,"Terminé")&"/"&ROWS(A4:A27)&" tâches terminées"
B31: =ROUND(COUNTIF(F4:F27,"Terminé")/ROWS(A4:A27)*100,0)&"% complété"

Sheet 6-Alertes
A1: ALERTES PERSONNALISEES - Selon vos parametres
A3: VOS ALERTES SPÉCIFIQUES
A5: Type projet: | B5: =IF('2-Mon Projet'!D11="Creation ex-nihilo","Création ex-nihilo : durée standard, attention à la trésorerie.","Autre mode : ajuster les délais et rôles.")
A6: Ressources humaines: | B6: =IF('2-Mon Projet'!D26=0,"MODE SOLO : pas de recrutement prévu.","RH ACTIVE :"&CHAR(10)&"- Grille 2026 : collaborateur DCG min 26 548€ brut + 45% ≈ 38 500€ coût/an"&CHAR(10)&"- Recrutement : tensions élevées (~85%) ⇒ prévoir 10–12 sem"&CHAR(10)&"- AI Act : clause/parcours formation IA (AI literacy 02/02/2025)")
A7: Automatisation (ROI): | B7: ROI (Annexe 1) : 1) Rappr. bancaire 60–80% 2) OCR 30–50% 3) Reporting 50–70%
A8: E-facture (PA (ex-PDP)): | B8: =IFERROR(VLOOKUP("2.4",'0-Saisie'!$B$46:$E$69,4,FALSE),"A faire")&" — Choisir une PA (ex-PDP)/portail avant 01/09/2026 (réception obligatoire)."
A9: Budget: | B9: =IF('2-Mon Projet'!D48<'2-Mon Projet'!D49,"ALERTE : trésorerie de sécurité insuffisante (viser ≥ "&'2-Mon Projet'!D41&" mois).","OK : trésorerie de sécurité couverte.")
A11: ALERTES CRITIQUES — RÉGLEMENTATION (dates clés)
A13: 02/02/2025 | B13: AI Act : AI literacy (formation/compétence IA) — obligations applicables
A14: 02/08/2026 | B14: AI Act : applicabilité générale de l’AI Act (sauf exceptions/transition)
A15: 01/09/2026 | B15: Facture électronique : RÉCEPTION obligatoire (toutes entreprises assujetties TVA) + ÉMISSION GE/ETI
A16: 01/09/2027 | B16: Facture électronique : ÉMISSION obligatoire PME / micro
A19: ERREURS CLASSIQUES À ÉVITER
A21: Avant M0 | B21: Ne pas faire le diagnostic Annexe 2 (RGPD/sécurité bloquants)
A22: Avant M0 | B22: Commander des outils avant architecture SI / choix PA (ex-PDP) validés
A23: M0–M+3 | B23: Négliger la sécurité du portail client (bloquant)
A24: M0–M+3 | B24: Sous-estimer RGPD : conformité avant 1er client
A25: M+3–M+6 | B25: Sous-estimer paramétrage APIs et OCR
A26: M+6–M+12 | B26: Recruter sans budget marque employeur (tensions marché)
A29: RAPPELS OBLIGATOIRES
A31: Inscription Ordre | B31: Délai incompressible : anticiper avant M0.
A32: Assurance RCP | B32: Obligatoire avant exercice.
A33: RGPD | B33: Conformité obligatoire AVANT le premier client.
A34: Facturation électronique | B34: 01/09/2026: réception via PA obligatoire (le PPF = annuaire uniquement). 01/09/2027: émission.
A35: Référentiel salarial 2026 | B35: Accord n°48 (15/12/2025) : +2,9%. Salaire min. collaborateur : 26 548 € brut/an.
A36: Secret professionnel | B36: Dès le premier contact client.
A39: Conclusion : | B39: Le Gantt n’est pas un planning figé : le passage de période dépend de conditions financières + réglementaires.
